Workbook
Name Closed: execute!$O$2:$O$100000
Name DOL: execute!$I$2:$I$100000
Name Filter1: execute!$T$2:$T$100000
Name IncLim: execute!$K$2:$K$100000
Name IncYr_yn: execute!$A$32
Name indType: execute!$N$2:$N$100000
Name Lit: execute!$Q$2:$Q$100000
Name Months: execute!$U$2:$U$100000
Name months1: execute!$D$32
Name months2: execute!$D$33
Name months3: execute!$D$34
Name months4: execute!$D$35
Name months5: execute!$D$36
Name osLim: execute!$M$2:$M$100000
Name pdLim: execute!$L$2:$L$100000
Name PY: execute!$J$2:$J$100000
Name PY1_: execute!$A$26
Name PY1_ret: 'Total Scorecards'!$N$5
Name PY1_ult: 'Total Scorecards'!$O$5
Name PY1_ultCt: 'Total Scorecards'!$P$5
Name PY2_: execute!$A$25
Name PY2_ret: 'Total Scorecards'!$N$6
Name PY2_ult: 'Total Scorecards'!$O$6
Name PY2_ultCt: 'Total Scorecards'!$P$6
Name PY3_: execute!$A$24
Name PY3_ret: 'Total Scorecards'!$N$7
Name PY3_ult: 'Total Scorecards'!$O$7
Name PY3_ultCt: 'Total Scorecards'!$P$7
Name PY4_: execute!$A$23
Name PY4_ret: 'Total Scorecards'!$N$8
Name PY4_ult: 'Total Scorecards'!$O$8
Name PY4_ultCt: 'Total Scorecards'!$P$8
Name PY5_: execute!$A$22
Name PY5_ret: 'Total Scorecards'!$N$9
Name PY5_ult: 'Total Scorecards'!$O$9
Name PY5_ultCt: 'Total Scorecards'!$P$9
Name PY6_: execute!$A$21
Name PY6_ret: 'Total Scorecards'!$N$10
Name PY6_ult: 'Total Scorecards'!$O$10
Name PY6_ultCt: 'Total Scorecards'!$P$10
Name PY7_: execute!$A$20
Name PY7_ult: 'Total Scorecards'!$O$11
Name PY7_ultCT: 'Total Scorecards'!$P$11
Name PY8_: execute!$A$19
Name PY8_ult: 'Total Scorecards'!$O$12
Name PY8_ultCt: 'Total Scorecards'!$P$12
Name Source1: execute!$B$9
Name Source2: execute!$B$10
Name Source3: execute!$B$11
Name Val_current: execute!$A$5
Name Valuation: execute!$S$2:$S$100000

Sheet Instructions
A2: Change Records
B4: Version 3.1 | C4: 43773 | D4: Changed Month formula
D5: Reversed scorecard trend titles from "18 vs 17" format to "17 vs 18" format
D6: Moved Compay ultimates table from Execute to Total Scorecards sheet
D7: Created Indemnity Rate, Ultmiate Severity, and Litigation Analysis sheets
A16: NEED TO REVALIDATE INSTRUCTIONS
A17: Steps:
B18: 1 | C18: Enter data on 'execute' page; see details below on pages
B19: 2 | C19: If filtering scorecards, complete exposures on filtered scorecards 1-3
B20: 3 | C20: Make sure notes on Total Scorecard page are accurate and comprehensive; they are fed to the other scorecard pages
A25: Pages:
B26: Execute
C27: Info on this page feeds the scorecard pages
C28: Enter metrics in tables
C29: Enter three valuations of loss run data in columns J+; Use month end valuations such as 4/30/19, 4/30/18, 4/30/17
C30: Dollar fields must be limited to retention
C31: Claim Status and Litigated must be on 0/1 format
D32: Claim Type should equal 1 if indemnity incurred is greater than $0;
D33: Claim Status should equal 1 if TPA claim status = Closed at time of valuation
D34: Litigated should equal 1 if TPA representation date or litigation date is ON OR BEFORE the valuation date; litigation flags (Y/N) are not sufficient to use since they are not usually valued as of the valuation dates
C35: Use the Filter field if scorecards are needed broken down, such as by state
B37: Total Scorecard
C38: Represents all data results
B40: Filtered Scorecards 1-3
C41: Are filtered to the values entered on Scorecard Names on the execute page; names must match the values in column U (Filters) on the execute page
C42: Complete the exposures table on each filtered scorecard
B44: Data
C45: Data sheet is not required, but is a place you can store all loss run data
B47: Validation table
C48: Refresh results
C49: Used to summarize results and to validate the report creator is accurate

Sheet execute
A1: PY TREND REPORT CREATOR | H1: Claim Number | I1: Date of Loss | J1: Policy Inception | K1: Incurred Limited | L1: Paid Limited | M1: Outstanding Reserves | N1: Indemnity Incurred | O1: Claim Status C=1 | P1: Litigation Date | Q1: Litigated =1 | R1: Days to Litigation | S1: Valuation | T1: Filter | U1: Months | V1: Incurred Buckets | W1: Date Closed | X1: Duration | Y1: Duration Buckets
I2: 44197 | J2: =IFERROR(VLOOKUP(I2,$A$19:$B$29,2,TRUE),"") -> 44197 | M2: =IF(K2<>"",K2-L2,"") | Q2: =IF(AND(P2<>"",P2<=S2),P2=I2,"") | S2: 44255 | U2: =(12*(YEAR(S2)-YEAR(J2)))+((MONTH(S2)-MONTH(J2))+1) -> 2 | V2: =VLOOKUP(K2,execute!$D$19:$E$27,2,TRUE) -> a. 0 | X2: =IF(W2<>"",W2-I2,"") | Y2: =IF(X2<>"",IF(X2<365,"< 1 year",IF(X2<730,"1-2",IF(X2<1095,"2-3",IF(X2<1460,"3-4",IF(X2<1825,"4-5","5+"))))),"")
I3: 43586 | J3: =IFERROR(VLOOKUP(I3,$A$19:$B$29,2,TRUE),"") -> 43466 | M3: =IF(K3<>"",K3-L3,"") | Q3: =IF(AND(P3<>"",P3<=S3),P3=I3,"") | V3: =VLOOKUP(K3,execute!$D$19:$E$27,2,TRUE) -> a. 0 | X3: =IF(W3<>"",W3-I3,"") | Y3: =IF(X3<>"",IF(X3<365,"< 1 year",IF(X3<730,"1-2",IF(X3<1095,"2-3",IF(X3<1460,"3-4",IF(X3<1825,"4-5","5+"))))),"")
A4: Current Valuation | D4: to-do | I4: 44105 | J4: =IFERROR(VLOOKUP(I4,$A$19:$B$29,2,TRUE),"") -> 43831 | M4: =IF(K4<>"",K4-L4,"") | Q4: =IF(AND(P4<>"",P4<=S4),P4=I4,"") | V4: =VLOOKUP(K4,execute!$D$19:$E$27,2,TRUE) -> a. 0 | X4: =IF(W4<>"",W4-I4,"") | Y4: =IF(X4<>"",IF(X4<365,"< 1 year",IF(X4<730,"1-2",IF(X4<1095,"2-3",IF(X4<1460,"3-4",IF(X4<1825,"4-5","5+"))))),"")
A5: {=MAX(Valuation)} -> 44255 | D5: need iferror on more scorecard cells | J5: =IFERROR(VLOOKUP(I5,$A$19:$B$29,2,TRUE),"") | M5: =IF(K5<>"",K5-L5,"") | Q5: =IF(AND(P5<>"",P5<=S5),P5=I5,"") | V5: =VLOOKUP(K5,execute!$D$19:$E$27,2,TRUE) -> a. 0 | X5: =IF(W5<>"",W5-I5,"") | Y5: =IF(X5<>"",IF(X5<365,"< 1 year",IF(X5<730,"1-2",IF(X5<1095,"2-3",IF(X5<1460,"3-4",IF(X5<1825,"4-5","5+"))))),"")
J6: =IFERROR(VLOOKUP(I6,$A$19:$B$29,2,TRUE),"") | M6: =IF(K6<>"",K6-L6,"") | Q6: =IF(AND(P6<>"",P6<=S6),P6=I6,"") | V6: =VLOOKUP(K6,execute!$D$19:$E$27,2,TRUE) -> a. 0 | X6: =IF(W6<>"",W6-I6,"") | Y6: =IF(X6<>"",IF(X6<365,"< 1 year",IF(X6<730,"1-2",IF(X6<1095,"2-3",IF(X6<1460,"3-4",IF(X6<1825,"4-5","5+"))))),"")
A7: Scorecard Names | J7: =IFERROR(VLOOKUP(I7,$A$19:$B$29,2,TRUE),"") | M7: =IF(K7<>"",K7-L7,"") | Q7: =IF(AND(P7<>"",P7<=S7),P7=I7,"") | V7: =VLOOKUP(K7,execute!$D$19:$E$27,2,TRUE) -> a. 0 | X7: =IF(W7<>"",W7-I7,"") | Y7: =IF(X7<>"",IF(X7<365,"< 1 year",IF(X7<730,"1-2",IF(X7<1095,"2-3",IF(X7<1460,"3-4",IF(X7<1825,"4-5","5+"))))),"")
A8: Total Scorecard | B8: Company Total | J8: =IFERROR(VLOOKUP(I8,$A$19:$B$29,2,TRUE),"") | M8: =IF(K8<>"",K8-L8,"") | Q8: =IF(AND(P8<>"",P8<=S8),P8=I8,"") | V8: =VLOOKUP(K8,execute!$D$19:$E$27,2,TRUE) -> a. 0 | X8: =IF(W8<>"",W8-I8,"") | Y8: =IF(X8<>"",IF(X8<365,"< 1 year",IF(X8<730,"1-2",IF(X8<1095,"2-3",IF(X8<1460,"3-4",IF(X8<1825,"4-5","5+"))))),"")
A9: Filtered Scorecard 1 | B9: California | J9: =IFERROR(VLOOKUP(I9,$A$19:$B$29,2,TRUE),"") | M9: =IF(K9<>"",K9-L9,"") | Q9: =IF(AND(P9<>"",P9<=S9),P9=I9,"") | V9: =VLOOKUP(K9,execute!$D$19:$E$27,2,TRUE) -> a. 0 | X9: =IF(W9<>"",W9-I9,"") | Y9: =IF(X9<>"",IF(X9<365,"< 1 year",IF(X9<730,"1-2",IF(X9<1095,"2-3",IF(X9<1460,"3-4",IF(X9<1825,"4-5","5+"))))),"")
A10: Filtered Scorecard 2 | J10: =IFERROR(VLOOKUP(I10,$A$19:$B$29,2,TRUE),"") | M10: =IF(K10<>"",K10-L10,"") | Q10: =IF(AND(P10<>"",P10<=S10),P10=I10,"") | V10: =VLOOKUP(K10,execute!$D$19:$E$27,2,TRUE) -> a. 0 | X10: =IF(W10<>"",W10-I10,"") | Y10: =IF(X10<>"",IF(X10<365,"< 1 year",IF(X10<730,"1-2",IF(X10<1095,"2-3",IF(X10<1460,"3-4",IF(X10<1825,"4-5","5+"))))),"")
A11: Filtered Scorecard 3 | J11: =IFERROR(VLOOKUP(I11,$A$19:$B$29,2,TRUE),"") | M11: =IF(K11<>"",K11-L11,"") | Q11: =IF(AND(P11<>"",P11<=S11),P11=I11,"") | V11: =VLOOKUP(K11,execute!$D$19:$E$27,2,TRUE) -> a. 0 | X11: =IF(W11<>"",W11-I11,"") | Y11: =IF(X11<>"",IF(X11<365,"< 1 year",IF(X11<730,"1-2",IF(X11<1095,"2-3",IF(X11<1460,"3-4",IF(X11<1825,"4-5","5+"))))),"")
J12: =IFERROR(VLOOKUP(I12,$A$19:$B$29,2,TRUE),"") | M12: =IF(K12<>"",K12-L12,"") | Q12: =IF(AND(P12<>"",P12<=S12),P12=I12,"") | V12: =VLOOKUP(K12,execute!$D$19:$E$27,2,TRUE) -> a. 0 | X12: =IF(W12<>"",W12-I12,"") | Y12: =IF(X12<>"",IF(X12<365,"< 1 year",IF(X12<730,"1-2",IF(X12<1095,"2-3",IF(X12<1460,"3-4",IF(X12<1825,"4-5","5+"))))),"")
J13: =IFERROR(VLOOKUP(I13,$A$19:$B$29,2,TRUE),"") | M13: =IF(K13<>"",K13-L13,"") | Q13: =IF(AND(P13<>"",P13<=S13),P13=I13,"") | V13: =VLOOKUP(K13,execute!$D$19:$E$27,2,TRUE) -> a. 0 | X13: =IF(W13<>"",W13-I13,"") | Y13: =IF(X13<>"",IF(X13<365,"< 1 year",IF(X13<730,"1-2",IF(X13<1095,"2-3",IF(X13<1460,"3-4",IF(X13<1825,"4-5","5+"))))),"")
J14: =IFERROR(VLOOKUP(I14,$A$19:$B$29,2,TRUE),"") | M14: =IF(K14<>"",K14-L14,"") | Q14: =IF(AND(P14<>"",P14<=S14),P14=I14,"") | V14: =VLOOKUP(K14,execute!$D$19:$E$27,2,TRUE) -> a. 0 | X14: =IF(W14<>"",W14-I14,"") | Y14: =IF(X14<>"",IF(X14<365,"< 1 year",IF(X14<730,"1-2",IF(X14<1095,"2-3",IF(X14<1460,"3-4",IF(X14<1825,"4-5","5+"))))),"")
J15: =IFERROR(VLOOKUP(I15,$A$19:$B$29,2,TRUE),"") | M15: =IF(K15<>"",K15-L15,"") | Q15: =IF(AND(P15<>"",P15<=S15),P15=I15,"") | V15: =VLOOKUP(K15,execute!$D$19:$E$27,2,TRUE) -> a. 0 | X15: =IF(W15<>"",W15-I15,"") | Y15: =IF(X15<>"",IF(X15<365,"< 1 year",IF(X15<730,"1-2",IF(X15<1095,"2-3",IF(X15<1460,"3-4",IF(X15<1825,"4-5","5+"))))),"")
J16: =IFERROR(VLOOKUP(I16,$A$19:$B$29,2,TRUE),"") | M16: =IF(K16<>"",K16-L16,"") | Q16: =IF(AND(P16<>"",P16<=S16),P16=I16,"") | V16: =VLOOKUP(K16,execute!$D$19:$E$27,2,TRUE) -> a. 0 | X16: =IF(W16<>"",W16-I16,"") | Y16: =IF(X16<>"",IF(X16<365,"< 1 year",IF(X16<730,"1-2",IF(X16<1095,"2-3",IF(X16<1460,"3-4",IF(X16<1825,"4-5","5+"))))),"")
A17: Used as a vlookup in Policy Inception column to recode older years | D17: Used to recode | J17: =IFERROR(VLOOKUP(I17,$A$19:$B$29,2,TRUE),"") | M17: =IF(K17<>"",K17-L17,"") | Q17: =IF(AND(P17<>"",P17<=S17),P17=I17,"") | V17: =VLOOKUP(K17,execute!$D$19:$E$27,2,TRUE) -> a. 0 | X17: =IF(W17<>"",W17-I17,"") | Y17: =IF(X17<>"",IF(X17<365,"< 1 year",IF(X17<730,"1-2",IF(X17<1095,"2-3",IF(X17<1460,"3-4",IF(X17<1825,"4-5","5+"))))),"")
A18: Policy Year Inception | B18: Policy Inception | D18: $ | E18: Bin | J18: =IFERROR(VLOOKUP(I18,$A$19:$B$29,2,TRUE),"") | M18: =IF(K18<>"",K18-L18,"") | Q18: =IF(AND(P18<>"",P18<=S18),P18=I18,"") | V18: =VLOOKUP(K18,execute!$D$19:$E$27,2,TRUE) -> a. 0 | X18: =IF(W18<>"",W18-I18,"") | Y18: =IF(X18<>"",IF(X18<365,"< 1 year",IF(X18<730,"1-2",IF(X18<1095,"2-3",IF(X18<1460,"3-4",IF(X18<1825,"4-5","5+"))))),"")
A19: 1 | B19: Older | D19: 0 | E19: a. 0 | J19: =IFERROR(VLOOKUP(I19,$A$19:$B$29,2,TRUE),"") | M19: =IF(K19<>"",K19-L19,"") | Q19: =IF(AND(P19<>"",P19<=S19),P19=I19,"") | V19: =VLOOKUP(K19,execute!$D$19:$E$27,2,TRUE) -> a. 0 | X19: =IF(W19<>"",W19-I19,"") | Y19: =IF(X19<>"",IF(X19<365,"< 1 year",IF(X19<730,"1-2",IF(X19<1095,"2-3",IF(X19<1460,"3-4",IF(X19<1825,"4-5","5+"))))),"")
A20: 42005 | B20: =A20 -> 42005 | D20: 1 | E20: b. 1-100 | J20: =IFERROR(VLOOKUP(I20,$A$19:$B$29,2,TRUE),"") | M20: =IF(K20<>"",K20-L20,"") | Q20: =IF(AND(P20<>"",P20<=S20),P20=I20,"") | V20: =VLOOKUP(K20,execute!$D$19:$E$27,2,TRUE) -> a. 0 | X20: =IF(W20<>"",W20-I20,"") | Y20: =IF(X20<>"",IF(X20<365,"< 1 year",IF(X20<730,"1-2",IF(X20<1095,"2-3",IF(X20<1460,"3-4",IF(X20<1825,"4-5","5+"))))),"")
A21: 42370 | B21: =A21 -> 42370 | D21: 100 | E21: c. 100-10k | J21: =IFERROR(VLOOKUP(I21,$A$19:$B$29,2,TRUE),"") | M21: =IF(K21<>"",K21-L21,"") | Q21: =IF(AND(P21<>"",P21<=S21),P21=I21,"") | V21: =VLOOKUP(K21,execute!$D$19:$E$27,2,TRUE) -> a. 0 | X21: =IF(W21<>"",W21-I21,"") | Y21: =IF(X21<>"",IF(X21<365,"< 1 year",IF(X21<730,"1-2",IF(X21<1095,"2-3",IF(X21<1460,"3-4",IF(X21<1825,"4-5","5+"))))),"")
A22: 39083 | B22: =A22 -> 39083 | D22: 10000 | E22: d. 10k-25k | J22: =IFERROR(VLOOKUP(I22,$A$19:$B$29,2,TRUE),"") | M22: =IF(K22<>"",K22-L22,"") | Q22: =IF(AND(P22<>"",P22<=S22),P22=I22,"") | V22: =VLOOKUP(K22,execute!$D$19:$E$27,2,TRUE) -> a. 0 | X22: =IF(W22<>"",W22-I22,"") | Y22: =IF(X22<>"",IF(X22<365,"< 1 year",IF(X22<730,"1-2",IF(X22<1095,"2-3",IF(X22<1460,"3-4",IF(X22<1825,"4-5","5+"))))),"")
A23: 43101 | B23: =A23 -> 43101 | D23: 25000 | E23: d. 25k-50k | J23: =IFERROR(VLOOKUP(I23,$A$19:$B$29,2,TRUE),"") | M23: =IF(K23<>"",K23-L23,"") | Q23: =IF(AND(P23<>"",P23<=S23),P23=I23,"") | V23: =VLOOKUP(K23,execute!$D$19:$E$27,2,TRUE) -> a. 0 | X23: =IF(W23<>"",W23-I23,"") | Y23: =IF(X23<>"",IF(X23<365,"< 1 year",IF(X23<730,"1-2",IF(X23<1095,"2-3",IF(X23<1460,"3-4",IF(X23<1825,"4-5","5+"))))),"")
A24: 43466 | B24: =A24 -> 43466 | D24: 50000 | E24: e. 50k-75k | J24: =IFERROR(VLOOKUP(I24,$A$19:$B$29,2,TRUE),"") | M24: =IF(K24<>"",K24-L24,"") | Q24: =IF(AND(P24<>"",P24<=S24),P24=I24,"") | V24: =VLOOKUP(K24,execute!$D$19:$E$27,2,TRUE) -> a. 0 | X24: =IF(W24<>"",W24-I24,"") | Y24: =IF(X24<>"",IF(X24<365,"< 1 year",IF(X24<730,"1-2",IF(X24<1095,"2-3",IF(X24<1460,"3-4",IF(X24<1825,"4-5","5+"))))),"")
A25: 43831 | B25: =A25 -> 43831 | D25: 75000 | E25: f. 75k-100k | J25: =IFERROR(VLOOKUP(I25,$A$19:$B$29,2,TRUE),"") | M25: =IF(K25<>"",K25-L25,"") | Q25: =IF(AND(P25<>"",P25<=S25),P25=I25,"") | V25: =VLOOKUP(K25,execute!$D$19:$E$27,2,TRUE) -> a. 0 | X25: =IF(W25<>"",W25-I25,"") | Y25: =IF(X25<>"",IF(X25<365,"< 1 year",IF(X25<730,"1-2",IF(X25<1095,"2-3",IF(X25<1460,"3-4",IF(X25<1825,"4-5","5+"))))),"")
A26: 44197 | B26: =A26 -> 44197 | D26: 100000 | E26: g. 100k-200k | X26: =IF(W26<>"",W26-I26,"") | Y26: =IF(X26<>"",IF(X26<365,"< 1 year",IF(X26<730,"1-2",IF(X26<1095,"2-3",IF(X26<1460,"3-4",IF(X26<1825,"4-5","5+"))))),"")
D27: 200000 | E27: h. 200k+ | X27: =IF(W27<>"",W27-I27,"") | Y27: =IF(X27<>"",IF(X27<365,"< 1 year",IF(X27<730,"1-2",IF(X27<1095,"2-3",IF(X27<1460,"3-4",IF(X27<1825,"4-5","5+"))))),"")
X28: =IF(W28<>"",W28-I28,"") | Y28: =IF(X28<>"",IF(X28<365,"< 1 year",IF(X28<730,"1-2",IF(X28<1095,"2-3",IF(X28<1460,"3-4",IF(X28<1825,"4-5","5+"))))),"")
X29: =IF(W29<>"",W29-I29,"") | Y29: =IF(X29<>"",IF(X29<365,"< 1 year",IF(X29<730,"1-2",IF(X29<1095,"2-3",IF(X29<1460,"3-4",IF(X29<1825,"4-5","5+"))))),"")
X30: =IF(W30<>"",W30-I30,"") | Y30: =IF(X30<>"",IF(X30<365,"< 1 year",IF(X30<730,"1-2",IF(X30<1095,"2-3",IF(X30<1460,"3-4",IF(X30<1825,"4-5","5+"))))),"")
A31: Policy Year same as inception year? Y/N | B31: Policy Inception | D31: Months | X31: =IF(W31<>"",W31-I31,"") | Y31: =IF(X31<>"",IF(X31<365,"< 1 year",IF(X31<730,"1-2",IF(X31<1095,"2-3",IF(X31<1460,"3-4",IF(X31<1825,"4-5","5+"))))),"")
A32: Y | D32: =MIN(U:U) -> 2 | X32: =IF(W32<>"",W32-I32,"") | Y32: =IF(X32<>"",IF(X32<365,"< 1 year",IF(X32<730,"1-2",IF(X32<1095,"2-3",IF(X32<1460,"3-4",IF(X32<1825,"4-5","5+"))))),"")
D33: =months1+12 -> 14 | X33: =IF(W33<>"",W33-I33,"") | Y33: =IF(X33<>"",IF(X33<365,"< 1 year",IF(X33<730,"1-2",IF(X33<1095,"2-3",IF(X33<1460,"3-4",IF(X33<1825,"4-5","5+"))))),"")
D34: =months2+12 -> 26 | X34: =IF(W34<>"",W34-I34,"") | Y34: =IF(X34<>"",IF(X34<365,"< 1 year",IF(X34<730,"1-2",IF(X34<1095,"2-3",IF(X34<1460,"3-4",IF(X34<1825,"4-5","5+"))))),"")
D35: =months3+12 -> 38 | X35: =IF(W35<>"",W35-I35,"") | Y35: =IF(X35<>"",IF(X35<365,"< 1 year",IF(X35<730,"1-2",IF(X35<1095,"2-3",IF(X35<1460,"3-4",IF(X35<1825,"4-5","5+"))))),"")
D36: =D35+12 -> 50 | X36: =IF(W36<>"",W36-I36,"") | Y36: =IF(X36<>"",IF(X36<365,"< 1 year",IF(X36<730,"1-2",IF(X36<1095,"2-3",IF(X36<1460,"3-4",IF(X36<1825,"4-5","5+"))))),"")
D37: =D36+12 -> 62 | X37: =IF(W37<>"",W37-I37,"") | Y37: =IF(X37<>"",IF(X37<365,"< 1 year",IF(X37<730,"1-2",IF(X37<1095,"2-3",IF(X37<1460,"3-4",IF(X37<1825,"4-5","5+"))))),"")
X38: =IF(W38<>"",W38-I38,"") | Y38: =IF(X38<>"",IF(X38<365,"< 1 year",IF(X38<730,"1-2",IF(X38<1095,"2-3",IF(X38<1460,"3-4",IF(X38<1825,"4-5","5+"))))),"")
X39: =IF(W39<>"",W39-I39,"") | Y39: =IF(X39<>"",IF(X39<365,"< 1 year",IF(X39<730,"1-2",IF(X39<1095,"2-3",IF(X39<1460,"3-4",IF(X39<1825,"4-5","5+"))))),"")
X40: =IF(W40<>"",W40-I40,"") | Y40: =IF(X40<>"",IF(X40<365,"< 1 year",IF(X40<730,"1-2",IF(X40<1095,"2-3",IF(X40<1460,"3-4",IF(X40<1825,"4-5","5+"))))),"")
...

Sheet Total Scorecards
A1: =execute!B8 -> Company Total
A2: =MIN(Months)&" Months" -> 2 Months | K2: Notes | M2: =A1&" Exposures" -> Company Total Exposures
K3: $0 incurred claims excluded
B4: PY1 | C4: =execute!$B$8 -> Company Total | K4: financials limited to retention | M4: Policy Year Inception | N4: Retention | O4: Ultimate Incurred | P4: Ultimate Claim Count | Q4: Payroll (actual) | R4: Severity
C5: ="PY"&RIGHT(YEAR($F$6),2)&" at "&execute!D32&" Months" -> PY21 at 2 Months | D5: Policy Year Inception Date | K5: indemnity status defined by indemnity incurred >$0 | M5: {=PY1_} -> 44197 | R5: =O5/P5 -> #DIV/0!
D6: {=PY3_} -> 43466 | E6: {=PY2_} -> 43831 | F6: {=PY1_} -> 44197 | K6: closure status defined by TPA | M6: {=PY2_} -> 43831 | R6: =O6/P6 -> #DIV/0!
D7: valued as of | E7: valued as of | F7: valued as of | K7: litigation defined as represented date before valuation | M7: =PY3_ -> 43466 | R7: =O7/P7 -> #DIV/0!
D8: {=MONTH(Val_current)&"/"&DAY(Val_current)&"/"&YEAR(Val_current)-2} -> 2/28/2019 | E8: {=MONTH(Val_current)&"/"&DAY(Val_current)&"/"&YEAR(Val_current)-1} -> 2/28/2020 | F8: {=Val_current} -> 44255 | G8: Trend | H8: {=IF(IncYr_yn="Y",RIGHT(YEAR($D$6),2)&" vs "&RIGHT(YEAR($F$6),2),RIGHT(YEAR($D$6),2)+1&" vs "&RIGHT(YEAR($F$6)+1,2))} -> 19 vs 21 | I8: {=IF(IncYr_yn="Y",RIGHT(YEAR($E$6),2)&" vs "&RIGHT(YEAR($F$6),2),RIGHT(YEAR($E$6),2)+1&" vs "&RIGHT(YEAR($F$6)+1,2))} -> 20 vs 21 | K8: Actuarial: Milliman as of 3/31/19 | M8: =PY4_ -> 43101 | R8: =O8/P8 -> #DIV/0!
K9: PY 7/1/18 ultimates are prorated from actuarial report | M9: =PY5_ -> 39083 | R9: =O9/P9 -> #DIV/0!
C10: Ultimates | D10: {=IFERROR(VLOOKUP(PY3_,$M$4:$R$13,3,FALSE),"-")} -> 0 | E10: =IFERROR(VLOOKUP(PY2_,$M$4:$R$13,3,FALSE),"-") -> 0 | F10: {=IFERROR(VLOOKUP(PY1_,$M$4:$R$13,3,FALSE),"-")} -> 0 | H10: =IFERROR((F10-D10)/D10,"-") -> - | I10: =IFERROR((F10-E10)/E10,"-") -> - | M10: =PY6_ -> 42370 | R10: =O10/P10 -> #DIV/0!
C11: Ultimate Claim Count | D11: =IFERROR(VLOOKUP(PY3_,'Total Scorecards'!$M$4:$P$11,4,FALSE),"-") -> 0 | E11: {=IFERROR(VLOOKUP(PY2_,'Total Scorecards'!$M$4:$P$11,4,FALSE),"-")} -> 0 | F11: {=IFERROR(VLOOKUP(PY1_,'Total Scorecards'!$M$4:$P$11,4,FALSE),"-")} -> 0 | H11: =IFERROR((F11-D11)/D11,"-") -> - | I11: =IFERROR((F11-E11)/E11,"-") -> - | M11: =PY7_ -> 42005 | R11: =O11/P11 -> #DIV/0!
R12: =O12/P12 -> #DIV/0!
C13: Total Incurred | D13: {=SUM((IncLim)*(Months=months1)*(PY=PY3_))} -> 0 | E13: {=SUM((IncLim)*(Months=months1)*(PY=PY2_))} -> 0 | F13: {=SUM((IncLim)*(Months=months1)*(PY=PY1_))} -> 0 | H13: =IFERROR((F13-D13)/D13,"-") -> - | I13: =IFERROR((F13-E13)/E13,"-") -> -
C14: Total Paid | D14: {=SUM((pdLim)*(Months=months1)*(PY=PY3_))} -> 0 | E14: {=SUM((pdLim)*(Months=months1)*(PY=PY2_))} -> 0 | F14: {=SUM((pdLim)*(Months=months1)*(PY=PY1_))} -> 0 | H14: =IFERROR((F14-D14)/D14,"-") -> - | I14: =IFERROR((F14-E14)/E14,"-") -> -
C15: Total Outstanding | D15: =D13-D14 -> 0 | E15: =E13-E14 -> 0 | F15: =F13-F14 -> 0 | H15: =IFERROR((F15-D15)/D15,"-") -> - | I15: =IFERROR((F15-E15)/E15,"-") -> -
C17: Total Claims >$0 | D17: {=SUM((IncLim>0)*(Months=months1)*(PY=PY3_))} -> 0 | E17: {=SUM((IncLim>0)*(Months=months1)*(PY=PY2_))} -> 0 | F17: {=SUM((IncLim>0)*(Months=months1)*(PY=PY1_))} -> 0 | H17: =IFERROR((F17-D17)/D17,"-") -> - | I17: =IFERROR((F17-E17)/E17,"-") -> -
C18: Average Cost per Claim | D18: =IFERROR(D13/D17,"-") -> - | E18: =IFERROR(E13/E17,"-") -> - | F18: =IFERROR(F13/F17,"-") -> - | H18: =IFERROR((F18-D18)/D18,"-") -> - | I18: =IFERROR((F18-E18)/E18,"-") -> -
C19: Median CPC | D19: {=IFERROR(MEDIAN(IF(IncLim>0, IF(Months=months1,IF(PY=PY3_, IncLim)))),"-")} -> - | E19: {=IFERROR(MEDIAN(IF(IncLim>0, IF(Months=months1,IF(PY=PY2_, IncLim)))),"-")} -> - | F19: {=IFERROR(MEDIAN(IF(IncLim>0, IF(Months=months1,IF(PY=PY1_, IncLim)))),"-")} -> - | H19: =IFERROR((F19-D19)/D19,"-") -> - | I19: =IFERROR((F19-E19)/E19,"-") -> -
C21: Payroll per $100 | D21: =IFERROR((VLOOKUP(PY3_,'Total Scorecards'!$M$4:$Q$10,5,FALSE)/100),"-") -> 0 | E21: =IFERROR((VLOOKUP(PY2_,'Total Scorecards'!$M$4:$Q$10,5,FALSE)/100),"-") -> 0 | F21: =IFERROR((VLOOKUP(PY1_,'Total Scorecards'!$M$4:$Q$10,5,FALSE)/100),"-") -> 0 | H21: =IFERROR((F21-D21)/D21,"-") -> - | I21: =IFERROR((F21-E21)/E21,"-") -> -
C22: Incurred Loss Rate | D22: =IFERROR(D13/D21,"-") -> - | E22: =IFERROR(E13/E21,"-") -> - | F22: =IFERROR(F13/F21,"-") -> - | H22: =IFERROR((F22-D22)/D22,"-") -> - | I22: =IFERROR((F22-E22)/E22,"-") -> -
C24: Indemnity Claims | D24: {=SUM((IncLim>0)*(indType>0)*(Months=months1)*(PY=PY3_))} -> 0 | E24: {=SUM((IncLim>0)*(indType>0)*(Months=months1)*(PY=PY2_))} -> 0 | F24: {=SUM((IncLim>0)*(indType>0)*(Months=months1)*(PY=PY1_))} -> 0 | H24: =IFERROR((F24-D24)/D24,"-") -> - | I24: =IFERROR((F24-E24)/E24,"-") -> -
C25: Indemnity Rate | D25: =IFERROR(D24/D17,"-") -> - | E25: =IFERROR(E24/E17,"-") -> - | F25: =IFERROR(F24/F17,"-") -> - | H25: =IFERROR(IF(((F25-D25)*100)>0,"+"&ROUND((F25-D25)*100,1),ROUND((F25-D25)*100,1)),"-") -> - | I25: =IFERROR(IF(((F25-E25)*100)>0,"+"&ROUND((F25-E25)*100,1),ROUND((F25-E25)*100,1)),"-") -> -
C26: Total Inc- Ind Claims | D26: {=SUM((IncLim)*(indType>0)*(Months=months1)*(PY=PY3_))} -> 0 | E26: {=SUM((IncLim)*(indType>0)*(Months=months1)*(PY=PY2_))} -> 0 | F26: {=SUM((IncLim)*(indType>0)*(Months=months1)*(PY=PY1_))} -> 0 | H26: =IFERROR((F26-D26)/D26,"-") -> - | I26: =IFERROR((F26-E26)/E26,"-") -> -
C27: ACPC- Ind Claims | D27: =IFERROR(D26/D24,"-") -> - | E27: =IFERROR(E26/E24,"-") -> - | F27: =IFERROR(F26/F24,"-") -> - | H27: =IFERROR((F27-D27)/D27,"-") -> - | I27: =IFERROR((F27-E27)/E27,"-") -> -
C28: Indemnity Closure Rate | D28: =IFERROR(1-(D29/D24),"-") -> - | E28: =IFERROR(1-(E29/E24),"-") -> - | F28: =IFERROR(1-(F29/F24),"-") -> - | H28: =IFERROR(IF(((F28-D28)*100)>0,"+"&ROUND((F28-D28)*100,1),ROUND((F28-D28)*100,1)),"-") -> - | I28: =IFERROR(IF(((F28-E28)*100)>0,"+"&ROUND((F28-E28)*100,1),ROUND((F28-E28)*100,1)),"-") -> -
C29: Open Indemnity Claims | D29: {=SUM((IncLim>0)*(indType>0)*(Closed=0)*(Months=months1)*(PY=PY3_))} -> 0 | E29: {=SUM((IncLim>0)*(indType>0)*(Closed=0)*(Months=months1)*(PY=PY2_))} -> 0 | F29: {=SUM((IncLim>0)*(indType>0)*(Closed=0)*(Months=months1)*(PY=PY1_))} -> 0 | H29: =IFERROR((F29-D29)/D29,"-") -> - | I29: =IFERROR((F29-E29)/E29,"-") -> -
C31: Ind Litigated Claims | D31: {=IFERROR(SUM((IncLim>0)*(Lit>0)*(indType>0)*(Months=months1)*(PY=PY3_)),"-")} -> 0 | E31: {=IFERROR(SUM((IncLim>0)*(Lit>0)*(indType>0)*(Months=months1)*(PY=PY2_)),"-")} -> 0 | F31: {=IFERROR(SUM((IncLim>0)*(Lit>0)*(indType>0)*(Months=months1)*(PY=PY1_)),"-")} -> 0 | H31: =IFERROR((F31-D31)/D31,"-") -> - | I31: =IFERROR((F31-E31)/E31,"-") -> -
C32: Ind Litigation Rate | D32: =IFERROR(D31/D24,"-") -> - | E32: =IFERROR(E31/E24,"-") -> - | F32: =IFERROR(F31/F24,"-") -> - | H32: =IFERROR(IF(((F32-D32)*100)>0,"+"&ROUND((F32-D32)*100,1),ROUND((F32-D32)*100,1)),"-") -> - | I32: =IFERROR(IF(((F32-E32)*100)>0,"+"&ROUND((F32-E32)*100,1),ROUND((F32-E32)*100,1)),"-") -> -
C33: Total Lit Ind Incurred | D33: {=SUM((IncLim)*(Lit>0)*(indType>0)*(Months=months1)*(PY=PY3_))} -> 0 | E33: {=SUM((IncLim)*(Lit>0)*(indType>0)*(Months=months1)*(PY=PY2_))} -> 0 | F33: {=SUM((IncLim)*(Lit>0)*(indType>0)*(Months=months1)*(PY=PY1_))} -> 0 | H33: =IFERROR((F33-D33)/D33,"-") -> - | I33: =IFERROR((F33-E33)/E33,"-") -> -
C34: Lit Ind Inc % of Tot Ind Inc | D34: =IFERROR(D33/D26,"-") -> - | E34: =IFERROR(E33/E26,"-") -> - | F34: =IFERROR(F33/F26,"-") -> - | H34: =IFERROR(IF(((F34-D34)*100)>0,"+"&ROUND((F34-D34)*100,1),ROUND((F34-D34)*100,1)),"-") -> - | I34: =IFERROR(IF(((F34-E34)*100)>0,"+"&ROUND((F34-E34)*100,1),ROUND((F34-E34)*100,1)),"-") -> -
C35: Total Litigated Claims | D35: {=SUM((IncLim>0)*(Lit>0)*(Months=months1)*(PY=PY3_))} -> 0 | E35: {=SUM((IncLim>0)*(Lit>0)*(Months=months1)*(PY=PY2_))} -> 0 | F35: {=SUM((IncLim>0)*(Lit>0)*(Months=months1)*(PY=PY1_))} -> 0 | H35: =IFERROR((F35-D35)/D35,"-") -> - | I35: =IFERROR((F35-E35)/E35,"-") -> -
C36: Total Litigated Incurred | D36: {=SUM((IncLim)*(Lit>0)*(Months=months1)*(PY=PY3_))} -> 0 | E36: {=SUM((IncLim)*(Lit>0)*(Months=months1)*(PY=PY2_))} -> 0 | F36: {=SUM((IncLim)*(Lit>0)*(Months=months1)*(PY=PY1_))} -> 0 | H36: =IFERROR((F36-D36)/D36,"-") -> - | I36: =IFERROR((F36-E36)/E36,"-") -> -
C37: Average Days to Litigation | H37: =IFERROR((F37-D37)/D37,"-") -> - | I37: =IFERROR((F37-E37)/E37,"-") -> -
C39: Top 5 Claims | D39: {=SUMPRODUCT(LARGE((Months=months1)*(PY=PY3_)*(IncLim),{1,2,3,4,5}))} -> 0 | E39: {=SUMPRODUCT(LARGE((Months=months1)*(PY=PY2_)*(IncLim),{1,2,3,4,5}))} -> 0 | F39: {=SUMPRODUCT(LARGE((Months=months1)*(PY=PY1_)*(IncLim),{1,2,3,4,5}))} -> 0 | H39: =IFERROR((F39-D39)/D39,"-") -> - | I39: =IFERROR((F39-E39)/E39,"-") -> -
C40: Top 5 as % of Incurred | D40: =IFERROR(D39/D13,"-") -> - | E40: =IFERROR(E39/E13,"-") -> - | F40: =IFERROR(F39/F13,"-") -> - | H40: =IFERROR(IF(((F40-D40)*100)>0,"+"&ROUND((F40-D40)*100,1),ROUND((F40-D40)*100,1)),"-") -> - | I40: =IFERROR(IF(((F40-E40)*100)>0,"+"&ROUND((F40-E40)*100,1),ROUND((F40-E40)*100,1)),"-") -> -
B44: PY2 | C44: =execute!$B$8 -> Company Total
C45: ="PY"&RIGHT(YEAR($F$46),2)&" at "&execute!D33&" Months" -> PY20 at 14 Months | D45: Policy Year Inception Date
D46: {=PY4_} -> 43101 | E46: {=PY3_} -> 43466 | F46: {=PY2_} -> 43831
D47: valued as of | E47: valued as of | F47: valued as of
D48: {=MONTH(Val_current)&"/"&DAY(Val_current)&"/"&YEAR(Val_current)-2} -> 2/28/2019 | E48: {=MONTH(Val_current)&"/"&DAY(Val_current)&"/"&YEAR(Val_current)-1} -> 2/28/2020 | F48: {=MONTH(Val_current)&"/"&DAY(Val_current)&"/"&YEAR(Val_current)} -> 2/28/2021 | G48: Trend | H48: {=(IF(IncYr_yn="Y",RIGHT(YEAR($D$46),2)&" vs "&RIGHT(YEAR($F$46),2),RIGHT(YEAR($D$46),2)+1&" vs "&RIGHT(YEAR($F$46),2)+1))} -> 18 vs 20 | I48: {=(IF(IncYr_yn="Y",RIGHT(YEAR($E$46),2)&" vs "&RIGHT(YEAR($F$46),2),RIGHT(YEAR($E$46),2)+1&" vs "&RIGHT(YEAR($F$46)+1,2)))} -> 19 vs 20
...

Sheet Filtered Scorecard 1
A1: =Source1 -> California
A2: =MIN(Months)&" Months" -> 2 Months | K2: =IF(ISBLANK('Total Scorecards'!K2),"-",'Total Scorecards'!K2) -> Notes | M2: =A1&" Exposures" -> California Exposures
K3: =IF(ISBLANK('Total Scorecards'!K3),"-",'Total Scorecards'!K3) -> $0 incurred claims excluded
B4: PY1 | C4: =Source1 -> California | K4: =IF(ISBLANK('Total Scorecards'!K4),"-",'Total Scorecards'!K4) -> financials limited to retention | M4: Policy Year Inception | N4: Retention | O4: Ultimate Incurred | P4: Ultimate Claim Count | Q4: Payroll (actual)
C5: ="PY"&RIGHT(YEAR($F$6),2)&" at "&execute!D32&" Months" -> PY21 at 2 Months | D5: Policy Year Inception Date | K5: =IF(ISBLANK('Total Scorecards'!K5),"-",'Total Scorecards'!K5) -> indemnity status defined by indemnity incurred >$0 | M5: {=PY1_} -> 44197 | N5: 1000000 | O5: 13800000 | P5: 755 | Q5: 401627000
D6: {=PY3_} -> 43466 | E6: {=PY2_} -> 43831 | F6: {=PY1_} -> 44197 | K6: =IF(ISBLANK('Total Scorecards'!K6),"-",'Total Scorecards'!K6) -> closure status defined by TPA | M6: {=PY2_} -> 43831 | N6: 1000000 | O6: 12000000 | P6: 717 | Q6: 366586000
D7: valued as of | E7: valued as of | F7: valued as of | K7: =IF(ISBLANK('Total Scorecards'!K7),"-",'Total Scorecards'!K7) -> litigation defined as represented date before valuation | M7: =PY3_ -> 43466 | N7: 1000000 | O7: 12830000 | P7: 690 | Q7: 372921000
D8: {=MONTH(Val_current)&"/"&DAY(Val_current)&"/"&YEAR(Val_current)-2} -> 2/28/2019 | E8: {=MONTH(Val_current)&"/"&DAY(Val_current)&"/"&YEAR(Val_current)-1} -> 2/28/2020 | F8: {=Val_current} -> 44255 | G8: Trend | H8: {=IF(IncYr_yn="Y",RIGHT(YEAR($D$6),2)&" vs "&RIGHT(YEAR($F$6),2),RIGHT(YEAR($D$6),2)+1&" vs "&RIGHT(YEAR($F$6)+1,2))} -> 19 vs 21 | I8: {=IF(IncYr_yn="Y",RIGHT(YEAR($E$6),2)&" vs "&RIGHT(YEAR($F$6),2),RIGHT(YEAR($E$6),2)+1&" vs "&RIGHT(YEAR($F$6)+1,2))} -> 20 vs 21 | K8: =IF(ISBLANK('Total Scorecards'!K8),"-",'Total Scorecards'!K8) -> Actuarial: Milliman as of 3/31/19 | M8: =PY4_ -> 43101 | N8: 1000000 | O8: 9020000 | P8: 645 | Q8: 359650000
K9: =IF(ISBLANK('Total Scorecards'!K9),"-",'Total Scorecards'!K9) -> PY 7/1/18 ultimates are prorated from actuarial report | M9: =PY5_ -> 39083 | N9: 1000000 | O9: 9030000 | P9: 697 | Q9: 376975000
C10: Ultimates | D10: {=IFERROR(VLOOKUP(PY3_,$M$4:$R$13,3,FALSE),"-")} -> 12830000 | E10: =IFERROR(VLOOKUP(PY2_,$M$4:$R$13,3,FALSE),"-") -> 12000000 | F10: {=IFERROR(VLOOKUP(PY1_,$M$4:$R$13,3,FALSE),"-")} -> 13800000 | H10: =IFERROR((F10-D10)/D10,"-") -> 0.075604053 | I10: =IFERROR((F10-E10)/E10,"-") -> 0.15 | M10: =PY6_ -> 42370 | N10: 1000000 | O10: 9820000 | P10: 712 | Q10: 379000000
C11: Ultimate Claim Count | D11: =IFERROR(VLOOKUP(PY3_,$M$4:$P$11,4,FALSE),"-") -> 690 | E11: =IFERROR(VLOOKUP(PY2_,$M$4:$P$11,4,FALSE),"-") -> 717 | F11: =IFERROR(VLOOKUP(PY1_,$M$4:$P$11,4,FALSE),"-") -> 755 | H11: =IFERROR((F11-D11)/D11,"-") -> 0.094202899 | I11: =IFERROR((F11-E11)/E11,"-") -> 0.052998605 | M11: =PY7_ -> 42005
C13: Total Incurred | D13: {=SUM((IncLim)*(Months=months1)*(PY=PY3_)*(Filter1=Source1))} -> 0 | E13: {=SUM((IncLim)*(Months=months1)*(PY=PY2_)*(Filter1=Source1))} -> 0 | F13: {=SUM((IncLim)*(Months=months1)*(PY=PY1_)*(Filter1=Source1)*(Filter1=Source1))} -> 0 | H13: =IFERROR((F13-D13)/D13,"-") -> - | I13: =IFERROR((F13-E13)/E13,"-") -> -
C14: Total Paid | D14: {=SUM((pdLim)*(Months=months1)*(PY=PY3_)*(Filter1=Source1))} -> 0 | E14: {=SUM((pdLim)*(Months=months1)*(PY=PY2_)*(Filter1=Source1))} -> 0 | F14: {=SUM((pdLim)*(Months=months1)*(PY=PY1_)*(Filter1=Source1))} -> 0 | H14: =IFERROR((F14-D14)/D14,"-") -> - | I14: =IFERROR((F14-E14)/E14,"-") -> -
C15: Total Outstanding | D15: =D13-D14 -> 0 | E15: =E13-E14 -> 0 | F15: =F13-F14 -> 0 | H15: =IFERROR((F15-D15)/D15,"-") -> - | I15: =IFERROR((F15-E15)/E15,"-") -> -
C17: Total Claims >$0 | D17: {=SUM((IncLim>0)*(Months=months1)*(PY=PY3_)*(Filter1=Source1))} -> 0 | E17: {=SUM((IncLim>0)*(Months=months1)*(PY=PY2_)*(Filter1=Source1))} -> 0 | F17: {=SUM((IncLim>0)*(Months=months1)*(PY=PY1_)*(Filter1=Source1))} -> 0 | H17: =IFERROR((F17-D17)/D17,"-") -> - | I17: =IFERROR((F17-E17)/E17,"-") -> -
C18: Average Cost per Claim | D18: =IFERROR(D13/D17,"-") -> - | E18: =IFERROR(E13/E17,"-") -> - | F18: =IFERROR(F13/F17,"-") -> - | H18: =IFERROR((F18-D18)/D18,"-") -> - | I18: =IFERROR((F18-E18)/E18,"-") -> -
C19: Median CPC | D19: {=IFERROR(MEDIAN(IF(IncLim>0, IF(Months=months1,IF(PY=PY3_, IF(Filter1=Source1, IncLim))))),"-")} -> - | E19: {=IFERROR(MEDIAN(IF(IncLim>0, IF(Months=months1,IF(PY=PY2_, IF(Filter1=Source1, IncLim))))),"-")} -> - | F19: {=IFERROR(MEDIAN(IF(IncLim>0, IF(Months=months1,IF(PY=PY1_, IF(Filter1=Source1,IncLim))))),"-")} -> - | H19: =IFERROR((F19-D19)/D19,"-") -> - | I19: =IFERROR((F19-E19)/E19,"-") -> -
C21: Payroll per $100 | D21: =IFERROR((VLOOKUP(PY3_,$M$4:$Q$10,5,FALSE)/100),"-") -> 3729210 | E21: =IFERROR((VLOOKUP(PY2_,$M$4:$Q$10,5,FALSE)/100),"-") -> 3665860 | F21: =IFERROR((VLOOKUP(PY1_,$M$4:$Q$10,5,FALSE)/100),"-") -> 4016270 | H21: =IFERROR((F21-D21)/D21,"-") -> 0.076976089 | I21: =IFERROR((F21-E21)/E21,"-") -> 0.095587393
C22: Incurred Loss Rate | D22: =IFERROR(D13/D21,"-") -> 0 | E22: =IFERROR(E13/E21,"-") -> 0 | F22: =IFERROR(F13/F21,"-") -> 0 | H22: =IFERROR((F22-D22)/D22,"-") -> - | I22: =IFERROR((F22-E22)/E22,"-") -> -
C24: Indemnity Claims | D24: {=SUM((IncLim>0)*(indType>0)*(Months=months1)*(PY=PY3_)*(Filter1=Source1))} -> 0 | E24: {=SUM((IncLim>0)*(indType>0)*(Months=months1)*(PY=PY2_)*(Filter1=Source1))} -> 0 | F24: {=SUM((IncLim>0)*(indType>0)*(Months=months1)*(PY=PY1_)*(Filter1=Source1))} -> 0 | H24: =IFERROR((F24-D24)/D24,"-") -> - | I24: =IFERROR((F24-E24)/E24,"-") -> -
C25: Indemnity Rate | D25: =IFERROR(D24/D17,"-") -> - | E25: =IFERROR(E24/E17,"-") -> - | F25: =IFERROR(F24/F17,"-") -> - | H25: =IFERROR(IF(((F25-D25)*100)>0,"+"&ROUND((F25-D25)*100,1),ROUND((F25-D25)*100,1)),"-") -> - | I25: =IFERROR(IF(((F25-E25)*100)>0,"+"&ROUND((F25-E25)*100,1),ROUND((F25-E25)*100,1)),"-") -> -
C26: Total Inc- Ind Claims | D26: {=SUM((IncLim)*(indType>0)*(Months=months1)*(PY=PY3_)*(Filter1=Source1))} -> 0 | E26: {=SUM((IncLim)*(indType>0)*(Months=months1)*(PY=PY2_)*(Filter1=Source1))} -> 0 | F26: {=SUM((IncLim)*(indType>0)*(Months=months1)*(PY=PY1_)*(Filter1=Source1))} -> 0 | H26: =IFERROR((F26-D26)/D26,"-") -> - | I26: =IFERROR((F26-E26)/E26,"-") -> -
C27: ACPC- Ind Claims | D27: =IFERROR(D26/D24,"-") -> - | E27: =IFERROR(E26/E24,"-") -> - | F27: =IFERROR(F26/F24,"-") -> - | H27: =IFERROR((F27-D27)/D27,"-") -> - | I27: =IFERROR((F27-E27)/E27,"-") -> -
C28: Indemnity Closure Rate | D28: =IFERROR(1-(D29/D24),"-") -> - | E28: =IFERROR(1-(E29/E24),"-") -> - | F28: =IFERROR(1-(F29/F24),"-") -> - | H28: =IFERROR(IF(((F28-D28)*100)>0,"+"&ROUND((F28-D28)*100,1),ROUND((F28-D28)*100,1)),"-") -> - | I28: =IFERROR(IF(((F28-E28)*100)>0,"+"&ROUND((F28-E28)*100,1),ROUND((F28-E28)*100,1)),"-") -> -
C29: Open Indemnity Claims | D29: {=D24-SUM((IncLim>0)*(indType>0)*(Closed>0)*(Months=months1)*(PY=PY3_)*(Filter1=Source1))} -> 0 | E29: {=E24-SUM((IncLim>0)*(indType>0)*(Closed>0)*(Months=months1)*(PY=PY2_)*(Filter1=Source1))} -> 0 | F29: {=F24-SUM((IncLim>0)*(indType>0)*(Closed>0)*(Months=months1)*(PY=PY1_)*(Filter1=Source1))} -> 0 | H29: =IFERROR((F29-D29)/D29,"-") -> - | I29: =IFERROR((F29-E29)/E29,"-") -> -
C31: Litigated Ind Claims | D31: {=SUM((IncLim>0)*(Lit>0)*(indType>0)*(Months=months1)*(PY=PY3_)*(Filter1=Source1))} -> 0 | E31: {=SUM((IncLim>0)*(Lit>0)*(indType>0)*(Months=months1)*(PY=PY2_)*(Filter1=Source1))} -> 0 | F31: {=SUM((IncLim>0)*(Lit>0)*(indType>0)*(Months=months1)*(PY=PY1_)*(Filter1=Source1))} -> 0 | H31: =IFERROR((F31-D31)/D31,"-") -> - | I31: =IFERROR((F31-E31)/E31,"-") -> -
C32: Ind Litigation Rate | D32: =IFERROR(D31/D24,"-") -> - | E32: =IFERROR(E31/E24,"-") -> - | F32: =IFERROR(F31/F24,"-") -> - | H32: =IFERROR(IF(((F32-D32)*100)>0,"+"&ROUND((F32-D32)*100,1),ROUND((F32-D32)*100,1)),"-") -> - | I32: =IFERROR(IF(((F32-E32)*100)>0,"+"&ROUND((F32-E32)*100,1),ROUND((F32-E32)*100,1)),"-") -> -
C33: Total Lit Ind Incurred | D33: {=SUM((IncLim)*(Lit>0)*(indType>0)*(Months=months1)*(PY=PY3_)*(Filter1=Source1))} -> 0 | E33: {=SUM((IncLim)*(Lit>0)*(indType>0)*(Months=months1)*(PY=PY2_)*(Filter1=Source1))} -> 0 | F33: {=SUM((IncLim)*(Lit>0)*(indType>0)*(Months=months1)*(PY=PY1_)*(Filter1=Source1))} -> 0 | H33: =IFERROR((F33-D33)/D33,"-") -> - | I33: =IFERROR((F33-E33)/E33,"-") -> -
C34: Lit Ind Inc % of Tot Ind Inc | D34: =IFERROR(D33/D26,"-") -> - | E34: =IFERROR(E33/E26,"-") -> - | F34: =IFERROR(F33/F26,"-") -> - | H34: =IFERROR(IF(((F34-D34)*100)>0,"+"&ROUND((F34-D34)*100,1),ROUND((F34-D34)*100,1)),"-") -> - | I34: =IFERROR(IF(((F34-E34)*100)>0,"+"&ROUND((F34-E34)*100,1),ROUND((F34-E34)*100,1)),"-") -> -
C35: Total Litigated Claims | D35: {=SUM((IncLim>0)*(Lit>0)*(Months=months1)*(PY=PY3_)*(Filter1=Source1))} -> 0 | E35: {=SUM((IncLim>0)*(Lit>0)*(Months=months1)*(PY=PY2_)*(Filter1=Source1))} -> 0 | F35: {=SUM((IncLim>0)*(Lit>0)*(Months=months1)*(PY=PY1_)*(Filter1=Source1))} -> 0 | H35: =IFERROR((F35-D35)/D35,"-") -> - | I35: =IFERROR((F35-E35)/E35,"-") -> -
C36: Total Litigated Incurred | D36: {=SUM((IncLim)*(Lit>0)*(Months=months1)*(PY=PY3_)*(Filter1=Source1))} -> 0 | E36: {=SUM((IncLim)*(Lit>0)*(Months=months1)*(PY=PY2_)*(Filter1=Source1))} -> 0 | F36: {=SUM((IncLim)*(Lit>0)*(Months=months1)*(PY=PY1_)*(Filter1=Source1))} -> 0 | H36: =IFERROR((F36-D36)/D36,"-") -> - | I36: =IFERROR((F36-E36)/E36,"-") -> -
C37: Average Days to Litigation | H37: =IFERROR((F37-D37)/D37,"-") -> - | I37: =IFERROR((F37-E37)/E37,"-") -> -
C39: Top 5 Claims | D39: =SUMPRODUCT(LARGE((Months=months1)*(PY=PY3_)*(IncLim)*(Filter1=Source1),{1,2,3,4,5})) -> 0 | E39: =SUMPRODUCT(LARGE((Months=months1)*(PY=PY2_)*(IncLim)*(Filter1=Source1),{1,2,3,4,5})) -> 0 | F39: =SUMPRODUCT(LARGE((Months=months1)*(PY=PY1_)*(IncLim)*(Filter1=Source1),{1,2,3,4,5})) -> 0 | H39: =IFERROR((F39-D39)/D39,"-") -> - | I39: =IFERROR((F39-E39)/E39,"-") -> -
C40: Top 5 as % of Incurred | D40: =IFERROR(D39/D13,"-") -> - | E40: =IFERROR(E39/E13,"-") -> - | F40: =IFERROR(F39/F13,"-") -> - | H40: =IFERROR(IF(((F40-D40)*100)>0,"+"&ROUND((F40-D40)*100,1),ROUND((F40-D40)*100,1)),"-") -> - | I40: =IFERROR(IF(((F40-E40)*100)>0,"+"&ROUND((F40-E40)*100,1),ROUND((F40-E40)*100,1)),"-") -> -
B44: PY2 | C44: =Source1 -> California
C45: ="PY"&RIGHT(YEAR($F$46),2)&" at "&execute!D33&" Months" -> PY20 at 14 Months | D45: Policy Year Inception Date
D46: {=PY4_} -> 43101 | E46: {=PY3_} -> 43466 | F46: {=PY2_} -> 43831
D47: valued as of | E47: valued as of | F47: valued as of
D48: {=MONTH(Val_current)&"/"&DAY(Val_current)&"/"&YEAR(Val_current)-2} -> 2/28/2019 | E48: {=MONTH(Val_current)&"/"&DAY(Val_current)&"/"&YEAR(Val_current)-1} -> 2/28/2020 | F48: {=MONTH(Val_current)&"/"&DAY(Val_current)&"/"&YEAR(Val_current)} -> 2/28/2021 | G48: Trend | H48: {=(IF(IncYr_yn="Y",RIGHT(YEAR($D$46),2)&" vs "&RIGHT(YEAR($F$46),2),RIGHT(YEAR($D$46),2)+1&" vs "&RIGHT(YEAR($F$46),2)+1))} -> 18 vs 20 | I48: {=(IF(IncYr_yn="Y",RIGHT(YEAR($E$46),2)&" vs "&RIGHT(YEAR($F$46),2),RIGHT(YEAR($E$46),2)+1&" vs "&RIGHT(YEAR($F$46)+1,2)))} -> 19 vs 20
C50: Ultimates | D50: {=IFERROR(VLOOKUP(PY4_,$M$4:$R$13,3,FALSE),"-")} -> 9020000 | E50: {=IFERROR(VLOOKUP(PY3_,$M$4:$R$13,3,FALSE),"-")} -> 12830000 | F50: {=IFERROR(VLOOKUP(PY2_,$M$4:$R$13,3,FALSE),"-")} -> 12000000 | H50: =IFERROR((F50-D50)/D50,"-") -> 0.33037694 | I50: =IFERROR((F50-E50)/E50,"-") -> -0.064692128
...

Sheet Filtered Scorecard 2
A1: =Source2 -> 0
A2: =MIN(Months)&" Months" -> 2 Months | K2: =IF(ISBLANK('Total Scorecards'!K2),"-",'Total Scorecards'!K2) -> Notes | M2: =A1&" Exposures" -> 0 Exposures
K3: =IF(ISBLANK('Total Scorecards'!K3),"-",'Total Scorecards'!K3) -> $0 incurred claims excluded
B4: PY1 | C4: =Source2 -> 0 | K4: =IF(ISBLANK('Total Scorecards'!K4),"-",'Total Scorecards'!K4) -> financials limited to retention | M4: Policy Year Inception | N4: Retention | O4: Ultimate Incurred | P4: Ultimate Claim Count | Q4: Payroll (actual)
C5: ="PY"&RIGHT(YEAR($F$6),2)&" at "&execute!D32&" Months" -> PY21 at 2 Months | D5: Policy Year Inception Date | K5: =IF(ISBLANK('Total Scorecards'!K5),"-",'Total Scorecards'!K5) -> indemnity status defined by indemnity incurred >$0 | M5: {=PY1_} -> 44197 | N5: 400000 | O5: 700000 | P5: 30 | Q5: 55341000
D6: {=PY3_} -> 43466 | E6: {=PY2_} -> 43831 | F6: {=PY1_} -> 44197 | K6: =IF(ISBLANK('Total Scorecards'!K6),"-",'Total Scorecards'!K6) -> closure status defined by TPA | M6: {=PY2_} -> 43831 | N6: 400000 | O6: 340000 | P6: 62 | Q6: 27862000
D7: valued as of | E7: valued as of | F7: valued as of | K7: =IF(ISBLANK('Total Scorecards'!K7),"-",'Total Scorecards'!K7) -> litigation defined as represented date before valuation | M7: =PY3_ -> 43466 | N7: 400000 | O7: 219000 | P7: 49 | Q7: 26720000
D8: {=MONTH(Val_current)&"/"&DAY(Val_current)&"/"&YEAR(Val_current)-2} -> 2/28/2019 | E8: {=MONTH(Val_current)&"/"&DAY(Val_current)&"/"&YEAR(Val_current)-1} -> 2/28/2020 | F8: {=Val_current} -> 44255 | G8: Trend | H8: {=IF(IncYr_yn="Y",RIGHT(YEAR($D$6),2)&" vs "&RIGHT(YEAR($F$6),2),RIGHT(YEAR($D$6),2)+1&" vs "&RIGHT(YEAR($F$6)+1,2))} -> 19 vs 21 | I8: {=IF(IncYr_yn="Y",RIGHT(YEAR($E$6),2)&" vs "&RIGHT(YEAR($F$6),2),RIGHT(YEAR($E$6),2)+1&" vs "&RIGHT(YEAR($F$6)+1,2))} -> 20 vs 21 | K8: =IF(ISBLANK('Total Scorecards'!K8),"-",'Total Scorecards'!K8) -> Actuarial: Milliman as of 3/31/19 | M8: =PY4_ -> 43101 | N8: 400000 | O8: 98000 | P8: 46 | Q8: 29312000
K9: =IF(ISBLANK('Total Scorecards'!K9),"-",'Total Scorecards'!K9) -> PY 7/1/18 ultimates are prorated from actuarial report | M9: =PY5_ -> 39083 | N9: 400000 | O9: 364000 | P9: 51 | Q9: 27408000
C10: Ultimates | D10: {=IFERROR(VLOOKUP(PY3_,$M$4:$R$13,3,FALSE),"-")} -> 219000 | E10: =IFERROR(VLOOKUP(PY2_,$M$4:$R$13,3,FALSE),"-") -> 340000 | F10: {=IFERROR(VLOOKUP(PY1_,$M$4:$R$13,3,FALSE),"-")} -> 700000 | H10: =IFERROR((F10-D10)/D10,"-") -> 2.196347 | I10: =IFERROR((F10-E10)/E10,"-") -> 1.0588235 | M10: =PY6_ -> 42370 | N10: 400000 | O10: 372000 | P10: 46 | Q10: 29300000
C11: Ultimate Claim Count | D11: =IFERROR(VLOOKUP(PY3_,$M$4:$P$11,4,FALSE),"-") -> 49 | E11: =IFERROR(VLOOKUP(PY2_,$M$4:$P$11,4,FALSE),"-") -> 62 | F11: =IFERROR(VLOOKUP(PY1_,$M$4:$P$11,4,FALSE),"-") -> 30 | H11: =IFERROR((F11-D11)/D11,"-") -> -0.3877551 | I11: =IFERROR((F11-E11)/E11,"-") -> -0.51612903 | M11: =PY7_ -> 42005
C13: Total Incurred | D13: {=SUM((IncLim)*(Months=months1)*(PY=PY3_)*(Filter1=Source2))} -> 0 | E13: {=SUM((IncLim)*(Months=months1)*(PY=PY2_)*(Filter1=Source2))} -> 0 | F13: {=SUM((IncLim)*(Months=months1)*(PY=PY1_)*(Filter1=Source2)*(Filter1=Source2))} -> 0 | H13: =IFERROR((F13-D13)/D13,"-") -> - | I13: =IFERROR((F13-E13)/E13,"-") -> -
C14: Total Paid | D14: {=SUM((pdLim)*(Months=months1)*(PY=PY3_)*(Filter1=Source2))} -> 0 | E14: {=SUM((pdLim)*(Months=months1)*(PY=PY2_)*(Filter1=Source2))} -> 0 | F14: =SUM((pdLim)*(Months=months1)*(PY=PY1_)*(Filter1=Source2)) -> 0 | H14: =IFERROR((F14-D14)/D14,"-") -> - | I14: =IFERROR((F14-E14)/E14,"-") -> -
C15: Total Outstanding | D15: =D13-D14 -> 0 | E15: =E13-E14 -> 0 | F15: =F13-F14 -> 0 | H15: =IFERROR((F15-D15)/D15,"-") -> - | I15: =IFERROR((F15-E15)/E15,"-") -> -
C17: Total Claims >$0 | D17: {=SUM((IncLim>0)*(Months=months1)*(PY=PY3_)*(Filter1=Source2))} -> 0 | E17: {=SUM((IncLim>0)*(Months=months1)*(PY=PY2_)*(Filter1=Source2))} -> 0 | F17: {=SUM((IncLim>0)*(Months=months1)*(PY=PY1_)*(Filter1=Source2))} -> 0 | H17: =IFERROR((F17-D17)/D17,"-") -> - | I17: =IFERROR((F17-E17)/E17,"-") -> -
C18: Average Cost per Claim | D18: =IFERROR(D13/D17,"-") -> - | E18: =IFERROR(E13/E17,"-") -> - | F18: =IFERROR(F13/F17,"-") -> - | H18: =IFERROR((F18-D18)/D18,"-") -> - | I18: =IFERROR((F18-E18)/E18,"-") -> -
C19: Median CPC | D19: {=IFERROR(MEDIAN(IF(IncLim>0, IF(Months=months1,IF(PY=PY3_, IF(Filter1=Source2, IncLim))))),"-")} -> - | E19: {=IFERROR(MEDIAN(IF(IncLim>0, IF(Months=months1,IF(PY=PY2_, IF(Filter1=Source2, IncLim))))),"-")} -> - | F19: {=IFERROR(MEDIAN(IF(IncLim>0, IF(Months=months1,IF(PY=PY1_, IF(Filter1=Source2,IncLim))))),"-")} -> - | H19: =IFERROR((F19-D19)/D19,"-") -> - | I19: =IFERROR((F19-E19)/E19,"-") -> -
C21: Payroll per $100 | D21: =IFERROR((VLOOKUP(PY3_,$M$4:$Q$10,5,FALSE)/100),"-") -> 267200 | E21: =IFERROR((VLOOKUP(PY2_,$M$4:$Q$10,5,FALSE)/100),"-") -> 278620 | F21: =IFERROR((VLOOKUP(PY1_,$M$4:$Q$10,5,FALSE)/100),"-") -> 553410 | H21: =IFERROR((F21-D21)/D21,"-") -> 1.0711452 | I21: =IFERROR((F21-E21)/E21,"-") -> 0.98625368
C22: Incurred Loss Rate | D22: =IFERROR(D13/D21,"-") -> 0 | E22: =IFERROR(E13/E21,"-") -> 0 | F22: =IFERROR(F13/F21,"-") -> 0 | H22: =IFERROR((F22-D22)/D22,"-") -> - | I22: =IFERROR((F22-E22)/E22,"-") -> -
C24: Indemnity Claims | D24: {=SUM((IncLim>0)*(indType>0)*(Months=months1)*(PY=PY3_)*(Filter1=Source2))} -> 0 | E24: {=SUM((IncLim>0)*(indType>0)*(Months=months1)*(PY=PY2_)*(Filter1=Source2))} -> 0 | F24: {=SUM((IncLim>0)*(indType>0)*(Months=months1)*(PY=PY1_)*(Filter1=Source2))} -> 0 | H24: =IFERROR((F24-D24)/D24,"-") -> - | I24: =IFERROR((F24-E24)/E24,"-") -> -
C25: Indemnity Rate | D25: =IFERROR(D24/D17,"-") -> - | E25: =IFERROR(E24/E17,"-") -> - | F25: =IFERROR(F24/F17,"-") -> - | H25: =IFERROR(IF(((F25-D25)*100)>0,"+"&ROUND((F25-D25)*100,1),ROUND((F25-D25)*100,1)),"-") -> - | I25: =IFERROR(IF(((F25-E25)*100)>0,"+"&ROUND((F25-E25)*100,1),ROUND((F25-E25)*100,1)),"-") -> -
C26: Total Inc- Ind Claims | D26: {=SUM((IncLim)*(indType>0)*(Months=months1)*(PY=PY3_)*(Filter1=Source2))} -> 0 | E26: {=SUM((IncLim)*(indType>0)*(Months=months1)*(PY=PY2_)*(Filter1=Source2))} -> 0 | F26: {=SUM((IncLim)*(indType>0)*(Months=months1)*(PY=PY1_)*(Filter1=Source2))} -> 0 | H26: =IFERROR((F26-D26)/D26,"-") -> - | I26: =IFERROR((F26-E26)/E26,"-") -> -
C27: ACPC- Ind Claims | D27: =IFERROR(D26/D24,"-") -> - | E27: =IFERROR(E26/E24,"-") -> - | F27: =IFERROR(F26/F24,"-") -> - | H27: =IFERROR((F27-D27)/D27,"-") -> - | I27: =IFERROR((F27-E27)/E27,"-") -> -
C28: Indemnity Closure Rate | D28: =IFERROR(1-(D29/D24),"-") -> - | E28: =IFERROR(1-(E29/E24),"-") -> - | F28: =IFERROR(1-(F29/F24),"-") -> - | H28: =IFERROR(IF(((F28-D28)*100)>0,"+"&ROUND((F28-D28)*100,1),ROUND((F28-D28)*100,1)),"-") -> - | I28: =IFERROR(IF(((F28-E28)*100)>0,"+"&ROUND((F28-E28)*100,1),ROUND((F28-E28)*100,1)),"-") -> -
C29: Open Indemnity Claims | D29: {=D24-SUM((IncLim>0)*(indType>0)*(Closed>0)*(Months=months1)*(PY=PY3_)*(Filter1=Source2))} -> 0 | E29: {=E24-SUM((IncLim>0)*(indType>0)*(Closed>0)*(Months=months1)*(PY=PY2_)*(Filter1=Source2))} -> 0 | F29: {=F24-SUM((IncLim>0)*(indType>0)*(Closed>0)*(Months=months1)*(PY=PY1_)*(Filter1=Source2))} -> 0 | H29: =IFERROR((F29-D29)/D29,"-") -> - | I29: =IFERROR((F29-E29)/E29,"-") -> -
C31: Litigated Ind Claims | D31: {=SUM((IncLim>0)*(Lit>0)*(indType>0)*(Months=months1)*(PY=PY3_)*(Filter1=Source2))} -> 0 | E31: {=SUM((IncLim>0)*(Lit>0)*(indType>0)*(Months=months1)*(PY=PY2_)*(Filter1=Source2))} -> 0 | F31: {=SUM((IncLim>0)*(Lit>0)*(indType>0)*(Months=months1)*(PY=PY1_)*(Filter1=Source2))} -> 0 | H31: =IFERROR((F31-D31)/D31,"-") -> - | I31: =IFERROR((F31-E31)/E31,"-") -> -
C32: Ind Litigation Rate | D32: =IFERROR(D31/D24,"-") -> - | E32: =IFERROR(E31/E24,"-") -> - | F32: =IFERROR(F31/F24,"-") -> - | H32: =IFERROR(IF(((F32-D32)*100)>0,"+"&ROUND((F32-D32)*100,1),ROUND((F32-D32)*100,1)),"-") -> - | I32: =IFERROR(IF(((F32-E32)*100)>0,"+"&ROUND((F32-E32)*100,1),ROUND((F32-E32)*100,1)),"-") -> -
C33: Total Lit Ind Incurred | D33: {=SUM((IncLim)*(Lit>0)*(indType>0)*(Months=months1)*(PY=PY3_)*(Filter1=Source2))} -> 0 | E33: {=SUM((IncLim)*(Lit>0)*(indType>0)*(Months=months1)*(PY=PY2_)*(Filter1=Source2))} -> 0 | F33: =SUM((IncLim)*(Lit>0)*(indType>0)*(Months=months1)*(PY=PY1_)*(Filter1=Source2)) -> 0 | H33: =IFERROR((F33-D33)/D33,"-") -> - | I33: =IFERROR((F33-E33)/E33,"-") -> -
C34: Lit Ind Inc % of Tot Ind Inc | D34: =IFERROR(D33/D26,"-") -> - | E34: =IFERROR(E33/E26,"-") -> - | F34: =IFERROR(F33/F26,"-") -> - | H34: =IFERROR(IF(((F34-D34)*100)>0,"+"&ROUND((F34-D34)*100,1),ROUND((F34-D34)*100,1)),"-") -> - | I34: =IFERROR(IF(((F34-E34)*100)>0,"+"&ROUND((F34-E34)*100,1),ROUND((F34-E34)*100,1)),"-") -> -
C35: Total Litigated Claims | D35: {=SUM((IncLim>0)*(Lit>0)*(Months=months1)*(PY=PY3_)*(Filter1=Source2))} -> 0 | E35: {=SUM((IncLim>0)*(Lit>0)*(Months=months1)*(PY=PY2_)*(Filter1=Source2))} -> 0 | F35: {=SUM((IncLim>0)*(Lit>0)*(Months=months1)*(PY=PY1_)*(Filter1=Source2))} -> 0 | H35: =IFERROR((F35-D35)/D35,"-") -> - | I35: =IFERROR((F35-E35)/E35,"-") -> -
C36: Total Litigated Incurred | D36: {=SUM((IncLim)*(Lit>0)*(Months=months1)*(PY=PY3_)*(Filter1=Source2))} -> 0 | E36: {=SUM((IncLim)*(Lit>0)*(Months=months1)*(PY=PY2_)*(Filter1=Source2))} -> 0 | F36: {=SUM((IncLim)*(Lit>0)*(Months=months1)*(PY=PY1_)*(Filter1=Source2))} -> 0 | H36: =IFERROR((F36-D36)/D36,"-") -> - | I36: =IFERROR((F36-E36)/E36,"-") -> -
C37: Average Days to Litigation | H37: =IFERROR((F37-D37)/D37,"-") -> - | I37: =IFERROR((F37-E37)/E37,"-") -> -
C39: Top 5 Claims | D39: =SUMPRODUCT(LARGE((Months=months1)*(PY=PY3_)*(IncLim)*(Filter1=Source2),{1,2,3,4,5})) -> 0 | E39: =SUMPRODUCT(LARGE((Months=months1)*(PY=PY2_)*(IncLim)*(Filter1=Source2),{1,2,3,4,5})) -> 0 | F39: =SUMPRODUCT(LARGE((Months=months1)*(PY=PY1_)*(IncLim)*(Filter1=Source2),{1,2,3,4,5})) -> 0 | H39: =IFERROR((F39-D39)/D39,"-") -> - | I39: =IFERROR((F39-E39)/E39,"-") -> -
C40: Top 5 as % of Incurred | D40: =IFERROR(D39/D13,"-") -> - | E40: =IFERROR(E39/E13,"-") -> - | F40: =IFERROR(F39/F13,"-") -> - | H40: =IFERROR(IF(((F40-D40)*100)>0,"+"&ROUND((F40-D40)*100,1),ROUND((F40-D40)*100,1)),"-") -> - | I40: =IFERROR(IF(((F40-E40)*100)>0,"+"&ROUND((F40-E40)*100,1),ROUND((F40-E40)*100,1)),"-") -> -
B44: PY2 | C44: =Source2 -> 0
C45: ="PY"&RIGHT(YEAR($F$46),2)&" at "&execute!D33&" Months" -> PY20 at 14 Months | D45: Policy Year Inception Date
D46: {=PY4_} -> 43101 | E46: {=PY3_} -> 43466 | F46: {=PY2_} -> 43831
D47: valued as of | E47: valued as of | F47: valued as of
D48: {=MONTH(Val_current)&"/"&DAY(Val_current)&"/"&YEAR(Val_current)-2} -> 2/28/2019 | E48: {=MONTH(Val_current)&"/"&DAY(Val_current)&"/"&YEAR(Val_current)-1} -> 2/28/2020 | F48: {=MONTH(Val_current)&"/"&DAY(Val_current)&"/"&YEAR(Val_current)} -> 2/28/2021 | G48: Trend | H48: {=(IF(IncYr_yn="Y",RIGHT(YEAR($D$46),2)&" vs "&RIGHT(YEAR($F$46),2),RIGHT(YEAR($D$46),2)+1&" vs "&RIGHT(YEAR($F$46),2)+1))} -> 18 vs 20 | I48: {=(IF(IncYr_yn="Y",RIGHT(YEAR($E$46),2)&" vs "&RIGHT(YEAR($F$46),2),RIGHT(YEAR($E$46),2)+1&" vs "&RIGHT(YEAR($F$46)+1,2)))} -> 19 vs 20
C50: Ultimates | D50: {=IFERROR(VLOOKUP(PY4_,$M$4:$R$13,3,FALSE),"-")} -> 98000 | E50: {=IFERROR(VLOOKUP(PY3_,$M$4:$R$13,3,FALSE),"-")} -> 219000 | F50: {=IFERROR(VLOOKUP(PY2_,$M$4:$R$13,3,FALSE),"-")} -> 340000 | H50: =IFERROR((F50-D50)/D50,"-") -> 2.4693878 | I50: =IFERROR((F50-E50)/E50,"-") -> 0.55251142
...

Sheet Filtered Scorecard 3
A1: =Source3 -> 0
A2: =MIN(Months)&" Months" -> 2 Months | K2: =IF(ISBLANK('Total Scorecards'!K2),"-",'Total Scorecards'!K2) -> Notes | M2: =A1&" Exposures" -> 0 Exposures
K3: =IF(ISBLANK('Total Scorecards'!K3),"-",'Total Scorecards'!K3) -> $0 incurred claims excluded
B4: PY1 | C4: =Source3 -> 0 | K4: =IF(ISBLANK('Total Scorecards'!K4),"-",'Total Scorecards'!K4) -> financials limited to retention | M4: Policy Year Inception | N4: Retention | O4: Ultimate Incurred | P4: Ultimate Claim Count | Q4: Payroll (actual)
C5: ="PY"&RIGHT(YEAR($F$6),2)&" at "&execute!D32&" Months" -> PY21 at 2 Months | D5: Policy Year Inception Date | K5: =IF(ISBLANK('Total Scorecards'!K5),"-",'Total Scorecards'!K5) -> indemnity status defined by indemnity incurred >$0 | M5: {=PY1_} -> 44197 | N5: 500000 | O5: 7758404 | Q5: 10000111
D6: {=PY3_} -> 43466 | E6: {=PY2_} -> 43831 | F6: {=PY1_} -> 44197 | K6: =IF(ISBLANK('Total Scorecards'!K6),"-",'Total Scorecards'!K6) -> closure status defined by TPA | M6: {=PY2_} -> 43831 | N6: 500000 | O6: 5378698 | P6: 207 | Q6: 10444000
D7: valued as of | E7: valued as of | F7: valued as of | K7: =IF(ISBLANK('Total Scorecards'!K7),"-",'Total Scorecards'!K7) -> litigation defined as represented date before valuation | M7: =PY3_ -> 43466 | N7: 500000 | O7: 8192021 | P7: 162 | Q7: 15500000
D8: {=MONTH(Val_current)&"/"&DAY(Val_current)&"/"&YEAR(Val_current)-2} -> 2/28/2019 | E8: {=MONTH(Val_current)&"/"&DAY(Val_current)&"/"&YEAR(Val_current)-1} -> 2/28/2020 | F8: {=Val_current} -> 44255 | G8: Trend | H8: {=IF(IncYr_yn="Y",RIGHT(YEAR($D$6),2)&" vs "&RIGHT(YEAR($F$6),2),RIGHT(YEAR($D$6),2)+1&" vs "&RIGHT(YEAR($F$6)+1,2))} -> 19 vs 21 | I8: {=IF(IncYr_yn="Y",RIGHT(YEAR($E$6),2)&" vs "&RIGHT(YEAR($F$6),2),RIGHT(YEAR($E$6),2)+1&" vs "&RIGHT(YEAR($F$6)+1,2))} -> 20 vs 21 | K8: =IF(ISBLANK('Total Scorecards'!K8),"-",'Total Scorecards'!K8) -> Actuarial: Milliman as of 3/31/19 | M8: =PY4_ -> 43101 | N8: 500000 | O8: 6444927 | P8: 155 | Q8: 10660000
K9: =IF(ISBLANK('Total Scorecards'!K9),"-",'Total Scorecards'!K9) -> PY 7/1/18 ultimates are prorated from actuarial report | M9: =PY5_ -> 39083 | N9: 500000 | O9: 7260618 | P9: 154 | Q9: 10000000
C10: Ultimates | D10: {=IFERROR(VLOOKUP(PY3_,$M$4:$R$13,3,FALSE),"-")} -> 8192021 | E10: =IFERROR(VLOOKUP(PY2_,$M$4:$R$13,3,FALSE),"-") -> 5378698 | F10: {=IFERROR(VLOOKUP(PY1_,$M$4:$R$13,3,FALSE),"-")} -> 7758404 | H10: =IFERROR((F10-D10)/D10,"-") -> -0.052931627 | I10: =IFERROR((F10-E10)/E10,"-") -> 0.44243161 | M10: =PY6_ -> 42370 | N10: 500000 | Q10: 10000000
C11: Ultimate Claim Count | D11: =IFERROR(VLOOKUP(PY3_,$M$4:$P$11,4,FALSE),"-") -> 162 | E11: =IFERROR(VLOOKUP(PY2_,$M$4:$P$11,4,FALSE),"-") -> 207 | F11: =IFERROR(VLOOKUP(PY1_,$M$4:$P$11,4,FALSE),"-") -> 0 | H11: =IFERROR((F11-D11)/D11,"-") -> -1 | I11: =IFERROR((F11-E11)/E11,"-") -> -1 | M11: =PY7_ -> 42005
C13: Total Incurred | D13: {=SUM((IncLim)*(Months=months1)*(PY=PY3_)*(Filter1=Source3))} -> 0 | E13: {=SUM((IncLim)*(Months=months1)*(PY=PY2_)*(Filter1=Source3))} -> 0 | F13: {=SUM((IncLim)*(Months=months1)*(PY=PY1_)*(Filter1=Source3)*(Filter1=Source3))} -> 0 | H13: =IFERROR((F13-D13)/D13,"-") -> - | I13: =IFERROR((F13-E13)/E13,"-") -> -
C14: Total Paid | D14: {=SUM((pdLim)*(Months=months1)*(PY=PY3_)*(Filter1=Source3))} -> 0 | E14: {=SUM((pdLim)*(Months=months1)*(PY=PY2_)*(Filter1=Source3))} -> 0 | F14: {=SUM((pdLim)*(Months=months1)*(PY=PY1_)*(Filter1=Source3))} -> 0 | H14: =IFERROR((F14-D14)/D14,"-") -> - | I14: =IFERROR((F14-E14)/E14,"-") -> -
C15: Total Outstanding | D15: =D13-D14 -> 0 | E15: =E13-E14 -> 0 | F15: =F13-F14 -> 0 | H15: =IFERROR((F15-D15)/D15,"-") -> - | I15: =IFERROR((F15-E15)/E15,"-") -> -
C17: Total Claims >$0 | D17: {=SUM((IncLim>0)*(Months=months1)*(PY=PY3_)*(Filter1=Source3))} -> 0 | E17: {=SUM((IncLim>0)*(Months=months1)*(PY=PY2_)*(Filter1=Source3))} -> 0 | F17: {=SUM((IncLim>0)*(Months=months1)*(PY=PY1_)*(Filter1=Source3))} -> 0 | H17: =IFERROR((F17-D17)/D17,"-") -> - | I17: =IFERROR((F17-E17)/E17,"-") -> -
C18: Average Cost per Claim | D18: =IFERROR(D13/D17,"-") -> - | E18: =IFERROR(E13/E17,"-") -> - | F18: =IFERROR(F13/F17,"-") -> - | H18: =IFERROR((F18-D18)/D18,"-") -> - | I18: =IFERROR((F18-E18)/E18,"-") -> -
C19: Median CPC | D19: {=IFERROR(MEDIAN(IF(IncLim>0, IF(Months=months1,IF(PY=PY3_, IF(Filter1=Source3, IncLim))))),"-")} -> - | E19: {=IFERROR(MEDIAN(IF(IncLim>0, IF(Months=months1,IF(PY=PY2_, IF(Filter1=Source3, IncLim))))),"-")} -> - | F19: {=IFERROR(MEDIAN(IF(IncLim>0, IF(Months=months1,IF(PY=PY1_, IF(Filter1=Source3,IncLim))))),"-")} -> - | H19: =IFERROR((F19-D19)/D19,"-") -> - | I19: =IFERROR((F19-E19)/E19,"-") -> -
C21: Payroll per $100 | D21: =IFERROR((VLOOKUP(PY3_,$M$4:$Q$10,5,FALSE)/100),"-") -> 155000 | E21: =IFERROR((VLOOKUP(PY2_,$M$4:$Q$10,5,FALSE)/100),"-") -> 104440 | F21: =IFERROR((VLOOKUP(PY1_,$M$4:$Q$10,5,FALSE)/100),"-") -> 100001.11 | H21: =IFERROR((F21-D21)/D21,"-") -> -0.35483155 | I21: =IFERROR((F21-E21)/E21,"-") -> -0.042501819
C22: Incurred Loss Rate | D22: =IFERROR(D13/D21,"-") -> 0 | E22: =IFERROR(E13/E21,"-") -> 0 | F22: =IFERROR(F13/F21,"-") -> 0 | H22: =IFERROR((F22-D22)/D22,"-") -> - | I22: =IFERROR((F22-E22)/E22,"-") -> -
C24: Indemnity Claims | D24: {=SUM((IncLim>0)*(indType>0)*(Months=months1)*(PY=PY3_)*(Filter1=Source3))} -> 0 | E24: {=SUM((IncLim>0)*(indType>0)*(Months=months1)*(PY=PY2_)*(Filter1=Source3))} -> 0 | F24: {=SUM((IncLim>0)*(indType>0)*(Months=months1)*(PY=PY1_)*(Filter1=Source3))} -> 0 | H24: =IFERROR((F24-D24)/D24,"-") -> - | I24: =IFERROR((F24-E24)/E24,"-") -> -
C25: Indemnity Rate | D25: =IFERROR(D24/D17,"-") -> - | E25: =IFERROR(E24/E17,"-") -> - | F25: =IFERROR(F24/F17,"-") -> - | H25: =IFERROR(IF(((F25-D25)*100)>0,"+"&ROUND((F25-D25)*100,1),ROUND((F25-D25)*100,1)),"-") -> - | I25: =IFERROR(IF(((F25-E25)*100)>0,"+"&ROUND((F25-E25)*100,1),ROUND((F25-E25)*100,1)),"-") -> -
C26: Total Inc- Ind Claims | D26: {=SUM((IncLim)*(indType>0)*(Months=months1)*(PY=PY3_)*(Filter1=Source3))} -> 0 | E26: {=SUM((IncLim)*(indType>0)*(Months=months1)*(PY=PY2_)*(Filter1=Source3))} -> 0 | F26: {=SUM((IncLim)*(indType>0)*(Months=months1)*(PY=PY1_)*(Filter1=Source3))} -> 0 | H26: =IFERROR((F26-D26)/D26,"-") -> - | I26: =IFERROR((F26-E26)/E26,"-") -> -
C27: ACPC- Ind Claims | D27: =IFERROR(D26/D24,"-") -> - | E27: =IFERROR(E26/E24,"-") -> - | F27: =IFERROR(F26/F24,"-") -> - | H27: =IFERROR((F27-D27)/D27,"-") -> - | I27: =IFERROR((F27-E27)/E27,"-") -> -
C28: Indemnity Closure Rate | D28: =IFERROR(1-(D29/D24),"-") -> - | E28: =IFERROR(1-(E29/E24),"-") -> - | F28: =IFERROR(1-(F29/F24),"-") -> - | H28: =IFERROR(IF(((F28-D28)*100)>0,"+"&ROUND((F28-D28)*100,1),ROUND((F28-D28)*100,1)),"-") -> - | I28: =IFERROR(IF(((F28-E28)*100)>0,"+"&ROUND((F28-E28)*100,1),ROUND((F28-E28)*100,1)),"-") -> -
C29: Open Indemnity Claims | D29: {=D24-SUM((IncLim>0)*(indType>0)*(Closed>0)*(Months=months1)*(PY=PY3_)*(Filter1=Source3))} -> 0 | E29: {=E24-SUM((IncLim>0)*(indType>0)*(Closed>0)*(Months=months1)*(PY=PY2_)*(Filter1=Source3))} -> 0 | F29: {=F24-SUM((IncLim>0)*(indType>0)*(Closed>0)*(Months=months1)*(PY=PY1_)*(Filter1=Source3))} -> 0 | H29: =IFERROR((F29-D29)/D29,"-") -> - | I29: =IFERROR((F29-E29)/E29,"-") -> -
C31: Litigated Ind Claims | D31: {=SUM((IncLim>0)*(Lit>0)*(Months=months1)*(PY=PY3_)*(Filter1=Source3))} -> 0 | E31: {=SUM((IncLim>0)*(Lit>0)*(Months=months1)*(PY=PY2_)*(Filter1=Source3))} -> 0 | F31: {=SUM((IncLim>0)*(Lit>0)*(Months=months1)*(PY=PY1_)*(Filter1=Source3))} -> 0 | H31: =IFERROR((F31-D31)/D31,"-") -> - | I31: =IFERROR((F31-E31)/E31,"-") -> -
C32: Ind Litigation Rate | D32: =IFERROR(D31/D24,"-") -> - | E32: =IFERROR(E31/E24,"-") -> - | F32: =IFERROR(F31/F24,"-") -> - | H32: =IFERROR(IF(((F32-D32)*100)>0,"+"&ROUND((F32-D32)*100,1),ROUND((F32-D32)*100,1)),"-") -> - | I32: =IFERROR(IF(((F32-E32)*100)>0,"+"&ROUND((F32-E32)*100,1),ROUND((F32-E32)*100,1)),"-") -> -
C33: Total Lit Ind Incurred | D33: {=SUM((IncLim)*(Lit>0)*(indType>0)*(Months=months1)*(PY=PY3_)*(Filter1=Source3))} -> 0 | E33: {=SUM((IncLim)*(Lit>0)*(indType>0)*(Months=months1)*(PY=PY2_)*(Filter1=Source3))} -> 0 | F33: {=SUM((IncLim)*(Lit>0)*(indType>0)*(Months=months1)*(PY=PY1_)*(Filter1=Source3))} -> 0 | H33: =IFERROR((F33-D33)/D33,"-") -> - | I33: =IFERROR((F33-E33)/E33,"-") -> -
C34: Lit Ind Inc % of Tot Ind Inc | D34: =IFERROR(D33/D26,"-") -> - | E34: =IFERROR(E33/E26,"-") -> - | F34: =IFERROR(F33/F26,"-") -> - | H34: =IFERROR(IF(((F34-D34)*100)>0,"+"&ROUND((F34-D34)*100,1),ROUND((F34-D34)*100,1)),"-") -> - | I34: =IFERROR(IF(((F34-E34)*100)>0,"+"&ROUND((F34-E34)*100,1),ROUND((F34-E34)*100,1)),"-") -> -
C35: Total Litigated Claims | D35: {=SUM((IncLim>0)*(Lit>0)*(Months=months1)*(PY=PY3_)*(Filter1=Source3))} -> 0 | E35: {=SUM((IncLim>0)*(Lit>0)*(Months=months1)*(PY=PY2_)*(Filter1=Source3))} -> 0 | F35: {=SUM((IncLim>0)*(Lit>0)*(Months=months1)*(PY=PY1_)*(Filter1=Source3))} -> 0 | H35: =IFERROR((F35-D35)/D35,"-") -> - | I35: =IFERROR((F35-E35)/E35,"-") -> -
C36: Total Litigated Incurred | D36: {=SUM((IncLim)*(Lit>0)*(Months=months1)*(PY=PY3_)*(Filter1=Source3))} -> 0 | E36: {=SUM((IncLim)*(Lit>0)*(Months=months1)*(PY=PY2_)*(Filter1=Source3))} -> 0 | F36: {=SUM((IncLim)*(Lit>0)*(Months=months1)*(PY=PY1_)*(Filter1=Source3))} -> 0 | H36: =IFERROR((F36-D36)/D36,"-") -> - | I36: =IFERROR((F36-E36)/E36,"-") -> -
C37: Average Days to Litigation | H37: =IFERROR((F37-D37)/D37,"-") -> - | I37: =IFERROR((F37-E37)/E37,"-") -> -
C39: Top 5 Claims | D39: =SUMPRODUCT(LARGE((Months=months1)*(PY=PY3_)*(IncLim)*(Filter1=Source3),{1,2,3,4,5})) -> 0 | E39: =SUMPRODUCT(LARGE((Months=months1)*(PY=PY2_)*(IncLim)*(Filter1=Source3),{1,2,3,4,5})) -> 0 | F39: =SUMPRODUCT(LARGE((Months=months1)*(PY=PY1_)*(IncLim)*(Filter1=Source3),{1,2,3,4,5})) -> 0 | H39: =IFERROR((F39-D39)/D39,"-") -> - | I39: =IFERROR((F39-E39)/E39,"-") -> -
C40: Top 5 as % of Incurred | D40: =IFERROR(D39/D13,"-") -> - | E40: =IFERROR(E39/E13,"-") -> - | F40: =IFERROR(F39/F13,"-") -> - | H40: =IFERROR(IF(((F40-D40)*100)>0,"+"&ROUND((F40-D40)*100,1),ROUND((F40-D40)*100,1)),"-") -> - | I40: =IFERROR(IF(((F40-E40)*100)>0,"+"&ROUND((F40-E40)*100,1),ROUND((F40-E40)*100,1)),"-") -> -
B44: PY2 | C44: =Source3 -> 0
C45: ="PY"&RIGHT(YEAR($F$46),2)&" at "&execute!D33&" Months" -> PY20 at 14 Months | D45: Policy Year Inception Date
D46: {=PY4_} -> 43101 | E46: {=PY3_} -> 43466 | F46: {=PY2_} -> 43831
D47: valued as of | E47: valued as of | F47: valued as of
D48: {=MONTH(Val_current)&"/"&DAY(Val_current)&"/"&YEAR(Val_current)-2} -> 2/28/2019 | E48: {=MONTH(Val_current)&"/"&DAY(Val_current)&"/"&YEAR(Val_current)-1} -> 2/28/2020 | F48: {=MONTH(Val_current)&"/"&DAY(Val_current)&"/"&YEAR(Val_current)} -> 2/28/2021 | G48: Trend | H48: {=(IF(IncYr_yn="Y",RIGHT(YEAR($D$46),2)&" vs "&RIGHT(YEAR($F$46),2),RIGHT(YEAR($D$46),2)+1&" vs "&RIGHT(YEAR($F$46),2)+1))} -> 18 vs 20 | I48: {=(IF(IncYr_yn="Y",RIGHT(YEAR($E$46),2)&" vs "&RIGHT(YEAR($F$46),2),RIGHT(YEAR($E$46),2)+1&" vs "&RIGHT(YEAR($F$46)+1,2)))} -> 19 vs 20
C50: Ultimates | D50: {=IFERROR(VLOOKUP(PY4_,$M$4:$R$13,3,FALSE),"-")} -> 6444927 | E50: {=IFERROR(VLOOKUP(PY3_,$M$4:$R$13,3,FALSE),"-")} -> 8192021 | F50: {=IFERROR(VLOOKUP(PY2_,$M$4:$R$13,3,FALSE),"-")} -> 5378698 | H50: =IFERROR((F50-D50)/D50,"-") -> -0.16543694 | I50: =IFERROR((F50-E50)/E50,"-") -> -0.34342234
...

Sheet Indemnity Rate
B4: Policy Effective Date | C4: Claims | D4: Indemnity Claims | E4: Indemnity Rate
