Workbook
Name Closed: execute!$O$2:$O$100000
Name DOL: execute!$I$2:$I$100000
Name Filter1: execute!$S$2:$S$100000
Name IncLim: execute!$K$2:$K$100000
Name IncYr_yn: execute!$A$32
Name indType: execute!$N$2:$N$100000
Name Lit: execute!$Q$2:$Q$100000
Name Months: execute!$U$2:$U$100000
Name months1: execute!$D$32
Name months2: execute!$D$33
Name months3: execute!$D$34
Name months4: execute!$D$35
Name months5: execute!$D$36
Name osLim: execute!$M$2:$M$100000
Name pdLim: execute!$L$2:$L$100000
Name PY: execute!$J$2:$J$100000
Name PY1_: execute!$A$26
Name PY1_ret: 'Total Scorecards'!$N$5
Name PY1_ult: 'Total Scorecards'!$O$5
Name PY1_ultCt: 'Total Scorecards'!$P$5
Name PY2_: execute!$A$25
Name PY2_ret: 'Total Scorecards'!$N$6
Name PY2_ult: 'Total Scorecards'!$O$6
Name PY2_ultCt: 'Total Scorecards'!$P$6
Name PY3_: execute!$A$24
Name PY3_ret: 'Total Scorecards'!$N$7
Name PY3_ult: 'Total Scorecards'!$O$7
Name PY3_ultCt: 'Total Scorecards'!$P$7
Name PY4_: execute!$A$23
Name PY4_ret: 'Total Scorecards'!$N$8
Name PY4_ult: 'Total Scorecards'!$O$8
Name PY4_ultCt: 'Total Scorecards'!$P$8
Name PY5_: execute!$A$22
Name PY5_ret: 'Total Scorecards'!$N$9
Name PY5_ult: 'Total Scorecards'!$O$9
Name PY5_ultCt: 'Total Scorecards'!$P$9
Name PY6_: execute!$A$21
Name PY6_ret: 'Total Scorecards'!$N$10
Name PY6_ult: 'Total Scorecards'!$O$10
Name PY6_ultCt: 'Total Scorecards'!$P$10
Name PY7_: execute!$A$20
Name PY7_ult: 'Total Scorecards'!$O$11
Name PY7_ultCT: 'Total Scorecards'!$P$11
Name PY8_: execute!$A$19
Name PY8_ult: 'Total Scorecards'!$O$12
Name PY8_ultCt: 'Total Scorecards'!$P$12
Name Source1: execute!$B$9
Name Source2: execute!$B$10
Name Source3: execute!$B$11
Name Val_current: execute!$A$5
Name Valuation: execute!$T$2:$T$100000

Sheet Instructions

Sheet execute
A1: PY TREND REPORT CREATOR | H1: Claim Number | I1: Date of Loss | J1: Policy Inception | K1: Incurred Limited | L1: Paid Limited | M1: Outstanding Reserves | N1: Indemnity Incurred | O1: Claim Status C=1 | P1: Litigation Date | Q1: Litigated =1 | R1: Days to Litigation | S1: Filter | T1: Valuation | U1: Months
I2: 44197 | J2: =IFERROR(VLOOKUP(I2,$A$19:$B$29,2,TRUE),"") -> 44197 | M2: =IF(K2<>"",K2-L2,"") | Q2: =IF(AND(P2<>"",P2<=T2),P2=I2,"")
I3: 43586 | J3: =IFERROR(VLOOKUP(I3,$A$19:$B$29,2,TRUE),"") -> 43466 | M3: =IF(K3<>"",K3-L3,"") | Q3: =IF(AND(P3<>"",P3<=T3),P3=I3,"")
A4: Current Valuation | I4: 44105 | J4: =IFERROR(VLOOKUP(I4,$A$19:$B$29,2,TRUE),"") -> 43831 | M4: =IF(K4<>"",K4-L4,"") | Q4: =IF(AND(P4<>"",P4<=T4),P4=I4,"")
A5: {=MAX(Valuation)} -> 0 | J5: =IFERROR(VLOOKUP(I5,$A$19:$B$29,2,TRUE),"") | M5: =IF(K5<>"",K5-L5,"") | Q5: =IF(AND(P5<>"",P5<=T5),P5=I5,"")
J6: =IFERROR(VLOOKUP(I6,$A$19:$B$29,2,TRUE),"") | M6: =IF(K6<>"",K6-L6,"") | Q6: =IF(AND(P6<>"",P6<=T6),P6=I6,"")
A7: Scorecard Names | J7: =IFERROR(VLOOKUP(I7,$A$19:$B$29,2,TRUE),"") | M7: =IF(K7<>"",K7-L7,"") | Q7: =IF(AND(P7<>"",P7<=T7),P7=I7,"")
A8: Total Scorecard | B8: [Client Name] WC Scorecard | J8: =IFERROR(VLOOKUP(I8,$A$19:$B$29,2,TRUE),"") | M8: =IF(K8<>"",K8-L8,"") | Q8: =IF(AND(P8<>"",P8<=T8),P8=I8,"")
A9: Filtered Scorecard 1 | B9: California | J9: =IFERROR(VLOOKUP(I9,$A$19:$B$29,2,TRUE),"") | M9: =IF(K9<>"",K9-L9,"") | Q9: =IF(AND(P9<>"",P9<=T9),P9=I9,"")
A10: Filtered Scorecard 2 | J10: =IFERROR(VLOOKUP(I10,$A$19:$B$29,2,TRUE),"") | M10: =IF(K10<>"",K10-L10,"") | Q10: =IF(AND(P10<>"",P10<=T10),P10=I10,"")
A11: Filtered Scorecard 3 | J11: =IFERROR(VLOOKUP(I11,$A$19:$B$29,2,TRUE),"") | M11: =IF(K11<>"",K11-L11,"") | Q11: =IF(AND(P11<>"",P11<=T11),P11=I11,"")
J12: =IFERROR(VLOOKUP(I12,$A$19:$B$29,2,TRUE),"") | M12: =IF(K12<>"",K12-L12,"") | Q12: =IF(AND(P12<>"",P12<=T12),P12=I12,"")
J13: =IFERROR(VLOOKUP(I13,$A$19:$B$29,2,TRUE),"") | M13: =IF(K13<>"",K13-L13,"") | Q13: =IF(AND(P13<>"",P13<=T13),P13=I13,"")
J14: =IFERROR(VLOOKUP(I14,$A$19:$B$29,2,TRUE),"") | M14: =IF(K14<>"",K14-L14,"") | Q14: =IF(AND(P14<>"",P14<=T14),P14=I14,"")
J15: =IFERROR(VLOOKUP(I15,$A$19:$B$29,2,TRUE),"") | M15: =IF(K15<>"",K15-L15,"") | Q15: =IF(AND(P15<>"",P15<=T15),P15=I15,"")
J16: =IFERROR(VLOOKUP(I16,$A$19:$B$29,2,TRUE),"") | M16: =IF(K16<>"",K16-L16,"") | Q16: =IF(AND(P16<>"",P16<=T16),P16=I16,"")
A17: Used as a vlookup in Policy Inception column to recode older years | D17: Used to recode | J17: =IFERROR(VLOOKUP(I17,$A$19:$B$29,2,TRUE),"") | M17: =IF(K17<>"",K17-L17,"") | Q17: =IF(AND(P17<>"",P17<=T17),P17=I17,"")
A18: Policy Year Inception | B18: Policy Inception | D18: $ | E18: Bin | J18: =IFERROR(VLOOKUP(I18,$A$19:$B$29,2,TRUE),"") | M18: =IF(K18<>"",K18-L18,"") | Q18: =IF(AND(P18<>"",P18<=T18),P18=I18,"")
A19: 1 | B19: Older | D19: 0 | E19: a. 0 | J19: =IFERROR(VLOOKUP(I19,$A$19:$B$29,2,TRUE),"") | M19: =IF(K19<>"",K19-L19,"") | Q19: =IF(AND(P19<>"",P19<=T19),P19=I19,"")
A20: 42005 | B20: =A20 -> 42005 | D20: 1 | E20: b. 1-100 | J20: =IFERROR(VLOOKUP(I20,$A$19:$B$29,2,TRUE),"") | M20: =IF(K20<>"",K20-L20,"") | Q20: =IF(AND(P20<>"",P20<=T20),P20=I20,"")
A21: 42370 | B21: =A21 -> 42370 | D21: 100 | E21: c. 100-10k | J21: =IFERROR(VLOOKUP(I21,$A$19:$B$29,2,TRUE),"") | M21: =IF(K21<>"",K21-L21,"") | Q21: =IF(AND(P21<>"",P21<=T21),P21=I21,"")
A22: 39083 | B22: =A22 -> 39083 | D22: 10000 | E22: d. 10k-25k | J22: =IFERROR(VLOOKUP(I22,$A$19:$B$29,2,TRUE),"") | M22: =IF(K22<>"",K22-L22,"") | Q22: =IF(AND(P22<>"",P22<=T22),P22=I22,"")
A23: 43101 | B23: =A23 -> 43101 | D23: 25000 | E23: d. 25k-50k | J23: =IFERROR(VLOOKUP(I23,$A$19:$B$29,2,TRUE),"") | M23: =IF(K23<>"",K23-L23,"") | Q23: =IF(AND(P23<>"",P23<=T23),P23=I23,"")
A24: 43466 | B24: =A24 -> 43466 | D24: 50000 | E24: e. 50k-75k | J24: =IFERROR(VLOOKUP(I24,$A$19:$B$29,2,TRUE),"") | M24: =IF(K24<>"",K24-L24,"") | Q24: =IF(AND(P24<>"",P24<=T24),P24=I24,"")
A25: 43831 | B25: =A25 -> 43831 | D25: 75000 | E25: f. 75k-100k | J25: =IFERROR(VLOOKUP(I25,$A$19:$B$29,2,TRUE),"") | M25: =IF(K25<>"",K25-L25,"") | Q25: =IF(AND(P25<>"",P25<=T25),P25=I25,"")
A26: 44197 | B26: =A26 -> 44197 | D26: 100000 | E26: g. 100k-200k
D27: 200000 | E27: h. 200k+
A31: Policy Year same as inception year? Y/N | B31: Policy Inception | D31: Months
A32: Y | D32: =MIN(U:U) -> 0
D33: =months1+12 -> 12
D34: =months2+12 -> 24
D35: =months3+12 -> 36
D36: =D35+12 -> 48
D37: =D36+12 -> 60

Sheet Analysis

Sheet Loss Run 1

Sheet Loss Run 2

Sheet Loss Run 3

Sheet Total Scorecards
A1: =execute!B8 -> [Client Name] WC Scorecard
A2: =MIN(Months)&" Months" -> 0 Months | H2: [Impact logo] | M2: =A1&" Exposures" -> [Client Name] WC Scorecard Exposures
C4: Notes | M4: Policy Year Inception | N4: Retention | O4: Ultimate Incurred | P4: Ultimate Claim Count | Q4: Payroll (actual)
C5: $0 incurred claims excluded | M5: {=PY1_} -> 44197
C6: financials limited to retention | M6: {=PY2_} -> 43831
C7: indemnity status defined by indemnity incurred >$0 | M7: =PY3_ -> 43466
C8: closure status defined by TPA | M8: =PY4_ -> 43101
C9: litigation defined as represented date before valuation | M9: =PY5_ -> 39083
C10: Actuarial: Milliman as of 3/31/19 | M10: =PY6_ -> 42370
C11: PY 7/1/18 ultimates are prorated from actuarial report | M11: =PY7_ -> 42005
B13: PY1 | C13: =execute!$B$8 -> [Client Name] WC Scorecard
C14: ="PY"&RIGHT(YEAR($F$15),2)&" at "&execute!D32&" Months" -> PY21 at 0 Months | D14: Policy Year Inception Date
D15: {=PY3_} -> 43466 | E15: {=PY2_} -> 43831 | F15: {=PY1_} -> 44197
D16: valued as of | E16: valued as of | F16: valued as of
D17: {=MONTH(Val_current)&"/"&DAY(Val_current)&"/"&YEAR(Val_current)-2} -> 1/0/1898 | E17: {=MONTH(Val_current)&"/"&DAY(Val_current)&"/"&YEAR(Val_current)-1} -> 1/0/1899 | F17: {=Val_current} -> 0 | G17: Trend | H17: {=IF(IncYr_yn="Y",RIGHT(YEAR($D$15),2)&" vs "&RIGHT(YEAR($F$15),2),RIGHT(YEAR($D$15),2)+1&" vs "&RIGHT(YEAR($F$15)+1,2))} -> 19 vs 21 | I17: {=IF(IncYr_yn="Y",RIGHT(YEAR($E$15),2)&" vs "&RIGHT(YEAR($F$15),2),RIGHT(YEAR($E$15),2)+1&" vs "&RIGHT(YEAR($F$15)+1,2))} -> 20 vs 21
C19: Ultimates | D19: {=IFERROR(VLOOKUP(PY3_,$M$4:$Q$12,3,FALSE),"-")} -> 0 | E19: =IFERROR(VLOOKUP(PY2_,$M$4:$Q$12,3,FALSE),"-") -> 0 | F19: {=IFERROR(VLOOKUP(PY1_,$M$4:$Q$12,3,FALSE),"-")} -> 0 | H19: =IFERROR((F19-D19)/D19,"-") -> - | I19: =IFERROR((F19-E19)/E19,"-") -> -
C20: Ultimate Claim Count | D20: =IFERROR(VLOOKUP(PY3_,'Total Scorecards'!$M$4:$P$11,4,FALSE),"-") -> 0 | E20: {=IFERROR(VLOOKUP(PY2_,'Total Scorecards'!$M$4:$P$11,4,FALSE),"-")} -> 0 | F20: {=IFERROR(VLOOKUP(PY1_,'Total Scorecards'!$M$4:$P$11,4,FALSE),"-")} -> 0 | H20: =IFERROR((F20-D20)/D20,"-") -> - | I20: =IFERROR((F20-E20)/E20,"-") -> -
C22: Total Incurred | D22: {=SUM((IncLim)*(Months=months1)*(PY=PY3_))} -> 0 | E22: {=SUM((IncLim)*(Months=months1)*(PY=PY2_))} -> 0 | F22: {=SUM((IncLim)*(Months=months1)*(PY=PY1_))} -> 0 | H22: =IFERROR((F22-D22)/D22,"-") -> - | I22: =IFERROR((F22-E22)/E22,"-") -> -
C23: Total Paid | D23: {=SUM((pdLim)*(Months=months1)*(PY=PY3_))} -> 0 | E23: {=SUM((pdLim)*(Months=months1)*(PY=PY2_))} -> 0 | F23: {=SUM((pdLim)*(Months=months1)*(PY=PY1_))} -> 0 | H23: =IFERROR((F23-D23)/D23,"-") -> - | I23: =IFERROR((F23-E23)/E23,"-") -> -
C24: Total Outstanding | D24: =D22-D23 -> 0 | E24: =E22-E23 -> 0 | F24: =F22-F23 -> 0 | H24: =IFERROR((F24-D24)/D24,"-") -> - | I24: =IFERROR((F24-E24)/E24,"-") -> -
C26: Total Claims >$0 | D26: {=SUM((IncLim>0)*(Months=months1)*(PY=PY3_))} -> 0 | E26: {=SUM((IncLim>0)*(Months=months1)*(PY=PY2_))} -> 0 | F26: {=SUM((IncLim>0)*(Months=months1)*(PY=PY1_))} -> 0 | H26: =IFERROR((F26-D26)/D26,"-") -> - | I26: =IFERROR((F26-E26)/E26,"-") -> -
C27: Average Cost per Claim | D27: =IFERROR(D22/D26,"-") -> - | E27: =IFERROR(E22/E26,"-") -> - | F27: =IFERROR(F22/F26,"-") -> - | H27: =IFERROR((F27-D27)/D27,"-") -> - | I27: =IFERROR((F27-E27)/E27,"-") -> -
C28: Median CPC | D28: {=IFERROR(MEDIAN(IF(IncLim>0, IF(Months=months1,IF(PY=PY3_, IncLim)))),"-")} -> - | E28: {=IFERROR(MEDIAN(IF(IncLim>0, IF(Months=months1,IF(PY=PY2_, IncLim)))),"-")} -> - | F28: {=IFERROR(MEDIAN(IF(IncLim>0, IF(Months=months1,IF(PY=PY1_, IncLim)))),"-")} -> - | H28: =IFERROR((F28-D28)/D28,"-") -> - | I28: =IFERROR((F28-E28)/E28,"-") -> -
C30: Payroll per $100 | D30: =IFERROR((VLOOKUP(PY3_,'Total Scorecards'!$M$4:$Q$10,5,FALSE)/100),"-") -> 0 | E30: =IFERROR((VLOOKUP(PY2_,'Total Scorecards'!$M$4:$Q$10,5,FALSE)/100),"-") -> 0 | F30: =IFERROR((VLOOKUP(PY1_,'Total Scorecards'!$M$4:$Q$10,5,FALSE)/100),"-") -> 0 | H30: =IFERROR((F30-D30)/D30,"-") -> - | I30: =IFERROR((F30-E30)/E30,"-") -> -
C31: Incurred Loss Rate | D31: =IFERROR(D22/D30,"-") -> - | E31: =IFERROR(E22/E30,"-") -> - | F31: =IFERROR(F22/F30,"-") -> - | H31: =IFERROR((F31-D31)/D31,"-") -> - | I31: =IFERROR((F31-E31)/E31,"-") -> -
C33: Indemnity Claims | D33: {=SUM((IncLim>0)*(indType>0)*(Months=months1)*(PY=PY3_))} -> 0 | E33: {=SUM((IncLim>0)*(indType>0)*(Months=months1)*(PY=PY2_))} -> 0 | F33: {=SUM((IncLim>0)*(indType>0)*(Months=months1)*(PY=PY1_))} -> 0 | H33: =IFERROR((F33-D33)/D33,"-") -> - | I33: =IFERROR((F33-E33)/E33,"-") -> -
C34: Indemnity Rate | D34: =IFERROR(D33/D26,"-") -> - | E34: =IFERROR(E33/E26,"-") -> - | F34: =IFERROR(F33/F26,"-") -> - | H34: =IFERROR(IF(((F34-D34)*100)>0,"+"&ROUND((F34-D34)*100,1),ROUND((F34-D34)*100,1)),"-") -> - | I34: =IFERROR(IF(((F34-E34)*100)>0,"+"&ROUND((F34-E34)*100,1),ROUND((F34-E34)*100,1)),"-") -> -
C35: Total Inc- Ind Claims | D35: {=SUM((IncLim)*(indType>0)*(Months=months1)*(PY=PY3_))} -> 0 | E35: {=SUM((IncLim)*(indType>0)*(Months=months1)*(PY=PY2_))} -> 0 | F35: {=SUM((IncLim)*(indType>0)*(Months=months1)*(PY=PY1_))} -> 0 | H35: =IFERROR((F35-D35)/D35,"-") -> - | I35: =IFERROR((F35-E35)/E35,"-") -> -
C36: ACPC- Ind Claims | D36: =IFERROR(D35/D33,"-") -> - | E36: =IFERROR(E35/E33,"-") -> - | F36: =IFERROR(F35/F33,"-") -> - | H36: =IFERROR((F36-D36)/D36,"-") -> - | I36: =IFERROR((F36-E36)/E36,"-") -> -
C37: Indemnity Closure Rate | D37: =IFERROR(1-(D38/D33),"-") -> - | E37: =IFERROR(1-(E38/E33),"-") -> - | F37: =IFERROR(1-(F38/F33),"-") -> - | H37: =IFERROR(IF(((F37-D37)*100)>0,"+"&ROUND((F37-D37)*100,1),ROUND((F37-D37)*100,1)),"-") -> - | I37: =IFERROR(IF(((F37-E37)*100)>0,"+"&ROUND((F37-E37)*100,1),ROUND((F37-E37)*100,1)),"-") -> -
C38: Open Indemnity Claims | D38: {=SUM((IncLim>0)*(indType>0)*(Closed=0)*(Months=months1)*(PY=PY3_))} -> 0 | E38: {=SUM((IncLim>0)*(indType>0)*(Closed=0)*(Months=months1)*(PY=PY2_))} -> 0 | F38: {=SUM((IncLim>0)*(indType>0)*(Closed=0)*(Months=months1)*(PY=PY1_))} -> 0 | H38: =IFERROR((F38-D38)/D38,"-") -> - | I38: =IFERROR((F38-E38)/E38,"-") -> -
C40: Ind Litigated Claims | D40: {=IFERROR(SUM((IncLim>0)*(Lit>0)*(indType>0)*(Months=months1)*(PY=PY3_)),"-")} -> 0 | E40: {=IFERROR(SUM((IncLim>0)*(Lit>0)*(indType>0)*(Months=months1)*(PY=PY2_)),"-")} -> 0 | F40: {=IFERROR(SUM((IncLim>0)*(Lit>0)*(indType>0)*(Months=months1)*(PY=PY1_)),"-")} -> 0 | H40: =IFERROR((F40-D40)/D40,"-") -> - | I40: =IFERROR((F40-E40)/E40,"-") -> -
C41: Ind Litigation Rate | D41: =IFERROR(D40/D33,"-") -> - | E41: =IFERROR(E40/E33,"-") -> - | F41: =IFERROR(F40/F33,"-") -> - | H41: =IFERROR(IF(((F41-D41)*100)>0,"+"&ROUND((F41-D41)*100,1),ROUND((F41-D41)*100,1)),"-") -> - | I41: =IFERROR(IF(((F41-E41)*100)>0,"+"&ROUND((F41-E41)*100,1),ROUND((F41-E41)*100,1)),"-") -> -
C42: Total Lit Ind Incurred | D42: {=SUM((IncLim)*(Lit>0)*(indType>0)*(Months=months1)*(PY=PY3_))} -> 0 | E42: {=SUM((IncLim)*(Lit>0)*(indType>0)*(Months=months1)*(PY=PY2_))} -> 0 | F42: {=SUM((IncLim)*(Lit>0)*(indType>0)*(Months=months1)*(PY=PY1_))} -> 0 | H42: =IFERROR((F42-D42)/D42,"-") -> - | I42: =IFERROR((F42-E42)/E42,"-") -> -
C43: Lit Ind Inc % of Tot Ind Inc | D43: =IFERROR(D42/D35,"-") -> - | E43: =IFERROR(E42/E35,"-") -> - | F43: =IFERROR(F42/F35,"-") -> - | H43: =IFERROR(IF(((F43-D43)*100)>0,"+"&ROUND((F43-D43)*100,1),ROUND((F43-D43)*100,1)),"-") -> - | I43: =IFERROR(IF(((F43-E43)*100)>0,"+"&ROUND((F43-E43)*100,1),ROUND((F43-E43)*100,1)),"-") -> -
C44: Total Litigated Claims | D44: {=SUM((IncLim>0)*(Lit>0)*(Months=months1)*(PY=PY3_))} -> 0 | E44: {=SUM((IncLim>0)*(Lit>0)*(Months=months1)*(PY=PY2_))} -> 0 | F44: {=SUM((IncLim>0)*(Lit>0)*(Months=months1)*(PY=PY1_))} -> 0 | H44: =IFERROR((F44-D44)/D44,"-") -> - | I44: =IFERROR((F44-E44)/E44,"-") -> -
C45: Total Litigated Incurred | D45: {=SUM((IncLim)*(Lit>0)*(Months=months1)*(PY=PY3_))} -> 0 | E45: {=SUM((IncLim)*(Lit>0)*(Months=months1)*(PY=PY2_))} -> 0 | F45: {=SUM((IncLim)*(Lit>0)*(Months=months1)*(PY=PY1_))} -> 0 | H45: =IFERROR((F45-D45)/D45,"-") -> - | I45: =IFERROR((F45-E45)/E45,"-") -> -
C46: Average Days to Litigation | H46: =IFERROR((F46-D46)/D46,"-") -> - | I46: =IFERROR((F46-E46)/E46,"-") -> -
C48: Top 5 Claims | D48: {=SUMPRODUCT(LARGE((Months=months1)*(PY=PY3_)*(IncLim),{1,2,3,4,5}))} -> 0 | E48: {=SUMPRODUCT(LARGE((Months=months1)*(PY=PY2_)*(IncLim),{1,2,3,4,5}))} -> 0 | F48: {=SUMPRODUCT(LARGE((Months=months1)*(PY=PY1_)*(IncLim),{1,2,3,4,5}))} -> 0 | H48: =IFERROR((F48-D48)/D48,"-") -> - | I48: =IFERROR((F48-E48)/E48,"-") -> -
C49: Top 5 as % of Incurred | D49: =IFERROR(D48/D22,"-") -> - | E49: =IFERROR(E48/E22,"-") -> - | F49: =IFERROR(F48/F22,"-") -> - | H49: =IFERROR(IF(((F49-D49)*100)>0,"+"&ROUND((F49-D49)*100,1),ROUND((F49-D49)*100,1)),"-") -> - | I49: =IFERROR(IF(((F49-E49)*100)>0,"+"&ROUND((F49-E49)*100,1),ROUND((F49-E49)*100,1)),"-") -> -
...

Sheet Filtered Scorecard 1
A1: =Source1 -> California
A2: =MIN(Months)&" Months" -> 0 Months | K2: =IF(ISBLANK('Total Scorecards'!C4),"-",'Total Scorecards'!C4) -> Notes | M2: =A1&" Exposures" -> California Exposures
K3: =IF(ISBLANK('Total Scorecards'!C5),"-",'Total Scorecards'!C5) -> $0 incurred claims excluded
B4: PY1 | C4: =Source1 -> California | K4: =IF(ISBLANK('Total Scorecards'!C6),"-",'Total Scorecards'!C6) -> financials limited to retention | M4: Policy Year Inception | N4: Retention | O4: Ultimate Incurred | P4: Ultimate Claim Count | Q4: Payroll (actual)
C5: ="PY"&RIGHT(YEAR($F$6),2)&" at "&execute!D32&" Months" -> PY21 at 0 Months | D5: Policy Year Inception Date | K5: =IF(ISBLANK('Total Scorecards'!C7),"-",'Total Scorecards'!C7) -> indemnity status defined by indemnity incurred >$0 | M5: {=PY1_} -> 44197 | N5: 1000000 | O5: 13800000 | P5: 755 | Q5: 401627000
D6: {=PY3_} -> 43466 | E6: {=PY2_} -> 43831 | F6: {=PY1_} -> 44197 | K6: =IF(ISBLANK('Total Scorecards'!C8),"-",'Total Scorecards'!C8) -> closure status defined by TPA | M6: {=PY2_} -> 43831 | N6: 1000000 | O6: 12000000 | P6: 717 | Q6: 366586000
D7: valued as of | E7: valued as of | F7: valued as of | K7: =IF(ISBLANK('Total Scorecards'!C9),"-",'Total Scorecards'!C9) -> litigation defined as represented date before valuation | M7: =PY3_ -> 43466 | N7: 1000000 | O7: 12830000 | P7: 690 | Q7: 372921000
D8: {=MONTH(Val_current)&"/"&DAY(Val_current)&"/"&YEAR(Val_current)-2} -> 1/0/1898 | E8: {=MONTH(Val_current)&"/"&DAY(Val_current)&"/"&YEAR(Val_current)-1} -> 1/0/1899 | F8: {=Val_current} -> 0 | G8: Trend | H8: {=IF(IncYr_yn="Y",RIGHT(YEAR($D$6),2)&" vs "&RIGHT(YEAR($F$6),2),RIGHT(YEAR($D$6),2)+1&" vs "&RIGHT(YEAR($F$6)+1,2))} -> 19 vs 21 | I8: {=IF(IncYr_yn="Y",RIGHT(YEAR($E$6),2)&" vs "&RIGHT(YEAR($F$6),2),RIGHT(YEAR($E$6),2)+1&" vs "&RIGHT(YEAR($F$6)+1,2))} -> 20 vs 21 | K8: =IF(ISBLANK('Total Scorecards'!C10),"-",'Total Scorecards'!C10) -> Actuarial: Milliman as of 3/31/19 | M8: =PY4_ -> 43101 | N8: 1000000 | O8: 9020000 | P8: 645 | Q8: 359650000
K9: =IF(ISBLANK('Total Scorecards'!C11),"-",'Total Scorecards'!C11) -> PY 7/1/18 ultimates are prorated from actuarial report | M9: =PY5_ -> 39083 | N9: 1000000 | O9: 9030000 | P9: 697 | Q9: 376975000
C10: Ultimates | D10: {=IFERROR(VLOOKUP(PY3_,$M$4:$R$13,3,FALSE),"-")} -> 12830000 | E10: =IFERROR(VLOOKUP(PY2_,$M$4:$R$13,3,FALSE),"-") -> 12000000 | F10: {=IFERROR(VLOOKUP(PY1_,$M$4:$R$13,3,FALSE),"-")} -> 13800000 | H10: =IFERROR((F10-D10)/D10,"-") -> 0.075604053 | I10: =IFERROR((F10-E10)/E10,"-") -> 0.15 | M10: =PY6_ -> 42370 | N10: 1000000 | O10: 9820000 | P10: 712 | Q10: 379000000
C11: Ultimate Claim Count | D11: =IFERROR(VLOOKUP(PY3_,$M$4:$P$11,4,FALSE),"-") -> 690 | E11: =IFERROR(VLOOKUP(PY2_,$M$4:$P$11,4,FALSE),"-") -> 717 | F11: =IFERROR(VLOOKUP(PY1_,$M$4:$P$11,4,FALSE),"-") -> 755 | H11: =IFERROR((F11-D11)/D11,"-") -> 0.094202899 | I11: =IFERROR((F11-E11)/E11,"-") -> 0.052998605 | M11: =PY7_ -> 42005
C13: Total Incurred | D13: {=SUM((IncLim)*(Months=months1)*(PY=PY3_)*(Filter1=Source1))} -> 0 | E13: {=SUM((IncLim)*(Months=months1)*(PY=PY2_)*(Filter1=Source1))} -> 0 | F13: {=SUM((IncLim)*(Months=months1)*(PY=PY1_)*(Filter1=Source1)*(Filter1=Source1))} -> 0 | H13: =IFERROR((F13-D13)/D13,"-") -> - | I13: =IFERROR((F13-E13)/E13,"-") -> -
C14: Total Paid | D14: {=SUM((pdLim)*(Months=months1)*(PY=PY3_)*(Filter1=Source1))} -> 0 | E14: {=SUM((pdLim)*(Months=months1)*(PY=PY2_)*(Filter1=Source1))} -> 0 | F14: {=SUM((pdLim)*(Months=months1)*(PY=PY1_)*(Filter1=Source1))} -> 0 | H14: =IFERROR((F14-D14)/D14,"-") -> - | I14: =IFERROR((F14-E14)/E14,"-") -> -
C15: Total Outstanding | D15: =D13-D14 -> 0 | E15: =E13-E14 -> 0 | F15: =F13-F14 -> 0 | H15: =IFERROR((F15-D15)/D15,"-") -> - | I15: =IFERROR((F15-E15)/E15,"-") -> -
C17: Total Claims >$0 | D17: {=SUM((IncLim>0)*(Months=months1)*(PY=PY3_)*(Filter1=Source1))} -> 0 | E17: {=SUM((IncLim>0)*(Months=months1)*(PY=PY2_)*(Filter1=Source1))} -> 0 | F17: {=SUM((IncLim>0)*(Months=months1)*(PY=PY1_)*(Filter1=Source1))} -> 0 | H17: =IFERROR((F17-D17)/D17,"-") -> - | I17: =IFERROR((F17-E17)/E17,"-") -> -
C18: Average Cost per Claim | D18: =IFERROR(D13/D17,"-") -> - | E18: =IFERROR(E13/E17,"-") -> - | F18: =IFERROR(F13/F17,"-") -> - | H18: =IFERROR((F18-D18)/D18,"-") -> - | I18: =IFERROR((F18-E18)/E18,"-") -> -
C19: Median CPC | D19: {=IFERROR(MEDIAN(IF(IncLim>0, IF(Months=months1,IF(PY=PY3_, IF(Filter1=Source1, IncLim))))),"-")} -> - | E19: {=IFERROR(MEDIAN(IF(IncLim>0, IF(Months=months1,IF(PY=PY2_, IF(Filter1=Source1, IncLim))))),"-")} -> - | F19: {=IFERROR(MEDIAN(IF(IncLim>0, IF(Months=months1,IF(PY=PY1_, IF(Filter1=Source1,IncLim))))),"-")} -> - | H19: =IFERROR((F19-D19)/D19,"-") -> - | I19: =IFERROR((F19-E19)/E19,"-") -> -
C21: Payroll per $100 | D21: =IFERROR((VLOOKUP(PY3_,$M$4:$Q$10,5,FALSE)/100),"-") -> 3729210 | E21: =IFERROR((VLOOKUP(PY2_,$M$4:$Q$10,5,FALSE)/100),"-") -> 3665860 | F21: =IFERROR((VLOOKUP(PY1_,$M$4:$Q$10,5,FALSE)/100),"-") -> 4016270 | H21: =IFERROR((F21-D21)/D21,"-") -> 0.076976089 | I21: =IFERROR((F21-E21)/E21,"-") -> 0.095587393
C22: Incurred Loss Rate | D22: =IFERROR(D13/D21,"-") -> 0 | E22: =IFERROR(E13/E21,"-") -> 0 | F22: =IFERROR(F13/F21,"-") -> 0 | H22: =IFERROR((F22-D22)/D22,"-") -> - | I22: =IFERROR((F22-E22)/E22,"-") -> -
C24: Indemnity Claims | D24: {=SUM((IncLim>0)*(indType>0)*(Months=months1)*(PY=PY3_)*(Filter1=Source1))} -> 0 | E24: {=SUM((IncLim>0)*(indType>0)*(Months=months1)*(PY=PY2_)*(Filter1=Source1))} -> 0 | F24: {=SUM((IncLim>0)*(indType>0)*(Months=months1)*(PY=PY1_)*(Filter1=Source1))} -> 0 | H24: =IFERROR((F24-D24)/D24,"-") -> - | I24: =IFERROR((F24-E24)/E24,"-") -> -
C25: Indemnity Rate | D25: =IFERROR(D24/D17,"-") -> - | E25: =IFERROR(E24/E17,"-") -> - | F25: =IFERROR(F24/F17,"-") -> - | H25: =IFERROR(IF(((F25-D25)*100)>0,"+"&ROUND((F25-D25)*100,1),ROUND((F25-D25)*100,1)),"-") -> - | I25: =IFERROR(IF(((F25-E25)*100)>0,"+"&ROUND((F25-E25)*100,1),ROUND((F25-E25)*100,1)),"-") -> -
C26: Total Inc- Ind Claims | D26: {=SUM((IncLim)*(indType>0)*(Months=months1)*(PY=PY3_)*(Filter1=Source1))} -> 0 | E26: {=SUM((IncLim)*(indType>0)*(Months=months1)*(PY=PY2_)*(Filter1=Source1))} -> 0 | F26: {=SUM((IncLim)*(indType>0)*(Months=months1)*(PY=PY1_)*(Filter1=Source1))} -> 0 | H26: =IFERROR((F26-D26)/D26,"-") -> - | I26: =IFERROR((F26-E26)/E26,"-") -> -
C27: ACPC- Ind Claims | D27: =IFERROR(D26/D24,"-") -> - | E27: =IFERROR(E26/E24,"-") -> - | F27: =IFERROR(F26/F24,"-") -> - | H27: =IFERROR((F27-D27)/D27,"-") -> - | I27: =IFERROR((F27-E27)/E27,"-") -> -
C28: Indemnity Closure Rate | D28: =IFERROR(1-(D29/D24),"-") -> - | E28: =IFERROR(1-(E29/E24),"-") -> - | F28: =IFERROR(1-(F29/F24),"-") -> - | H28: =IFERROR(IF(((F28-D28)*100)>0,"+"&ROUND((F28-D28)*100,1),ROUND((F28-D28)*100,1)),"-") -> - | I28: =IFERROR(IF(((F28-E28)*100)>0,"+"&ROUND((F28-E28)*100,1),ROUND((F28-E28)*100,1)),"-") -> -
C29: Open Indemnity Claims | D29: {=D24-SUM((IncLim>0)*(indType>0)*(Closed>0)*(Months=months1)*(PY=PY3_)*(Filter1=Source1))} -> 0 | E29: {=E24-SUM((IncLim>0)*(indType>0)*(Closed>0)*(Months=months1)*(PY=PY2_)*(Filter1=Source1))} -> 0 | F29: {=F24-SUM((IncLim>0)*(indType>0)*(Closed>0)*(Months=months1)*(PY=PY1_)*(Filter1=Source1))} -> 0 | H29: =IFERROR((F29-D29)/D29,"-") -> - | I29: =IFERROR((F29-E29)/E29,"-") -> -
C31: Litigated Ind Claims | D31: {=SUM((IncLim>0)*(Lit>0)*(indType>0)*(Months=months1)*(PY=PY3_)*(Filter1=Source1))} -> 0 | E31: {=SUM((IncLim>0)*(Lit>0)*(indType>0)*(Months=months1)*(PY=PY2_)*(Filter1=Source1))} -> 0 | F31: {=SUM((IncLim>0)*(Lit>0)*(indType>0)*(Months=months1)*(PY=PY1_)*(Filter1=Source1))} -> 0 | H31: =IFERROR((F31-D31)/D31,"-") -> - | I31: =IFERROR((F31-E31)/E31,"-") -> -
C32: Ind Litigation Rate | D32: =IFERROR(D31/D24,"-") -> - | E32: =IFERROR(E31/E24,"-") -> - | F32: =IFERROR(F31/F24,"-") -> - | H32: =IFERROR(IF(((F32-D32)*100)>0,"+"&ROUND((F32-D32)*100,1),ROUND((F32-D32)*100,1)),"-") -> - | I32: =IFERROR(IF(((F32-E32)*100)>0,"+"&ROUND((F32-E32)*100,1),ROUND((F32-E32)*100,1)),"-") -> -
C33: Total Lit Ind Incurred | D33: {=SUM((IncLim)*(Lit>0)*(indType>0)*(Months=months1)*(PY=PY3_)*(Filter1=Source1))} -> 0 | E33: {=SUM((IncLim)*(Lit>0)*(indType>0)*(Months=months1)*(PY=PY2_)*(Filter1=Source1))} -> 0 | F33: {=SUM((IncLim)*(Lit>0)*(indType>0)*(Months=months1)*(PY=PY1_)*(Filter1=Source1))} -> 0 | H33: =IFERROR((F33-D33)/D33,"-") -> - | I33: =IFERROR((F33-E33)/E33,"-") -> -
C34: Lit Ind Inc % of Tot Ind Inc | D34: =IFERROR(D33/D26,"-") -> - | E34: =IFERROR(E33/E26,"-") -> - | F34: =IFERROR(F33/F26,"-") -> - | H34: =IFERROR(IF(((F34-D34)*100)>0,"+"&ROUND((F34-D34)*100,1),ROUND((F34-D34)*100,1)),"-") -> - | I34: =IFERROR(IF(((F34-E34)*100)>0,"+"&ROUND((F34-E34)*100,1),ROUND((F34-E34)*100,1)),"-") -> -
C35: Total Litigated Claims | D35: {=SUM((IncLim>0)*(Lit>0)*(Months=months1)*(PY=PY3_)*(Filter1=Source1))} -> 0 | E35: {=SUM((IncLim>0)*(Lit>0)*(Months=months1)*(PY=PY2_)*(Filter1=Source1))} -> 0 | F35: {=SUM((IncLim>0)*(Lit>0)*(Months=months1)*(PY=PY1_)*(Filter1=Source1))} -> 0 | H35: =IFERROR((F35-D35)/D35,"-") -> - | I35: =IFERROR((F35-E35)/E35,"-") -> -
C36: Total Litigated Incurred | D36: {=SUM((IncLim)*(Lit>0)*(Months=months1)*(PY=PY3_)*(Filter1=Source1))} -> 0 | E36: {=SUM((IncLim)*(Lit>0)*(Months=months1)*(PY=PY2_)*(Filter1=Source1))} -> 0 | F36: {=SUM((IncLim)*(Lit>0)*(Months=months1)*(PY=PY1_)*(Filter1=Source1))} -> 0 | H36: =IFERROR((F36-D36)/D36,"-") -> - | I36: =IFERROR((F36-E36)/E36,"-") -> -
C37: Average Days to Litigation | H37: =IFERROR((F37-D37)/D37,"-") -> - | I37: =IFERROR((F37-E37)/E37,"-") -> -
C39: Top 5 Claims | D39: =SUMPRODUCT(LARGE((Months=months1)*(PY=PY3_)*(IncLim)*(Filter1=Source1),{1,2,3,4,5})) -> 0 | E39: =SUMPRODUCT(LARGE((Months=months1)*(PY=PY2_)*(IncLim)*(Filter1=Source1),{1,2,3,4,5})) -> 0 | F39: =SUMPRODUCT(LARGE((Months=months1)*(PY=PY1_)*(IncLim)*(Filter1=Source1),{1,2,3,4,5})) -> 0 | H39: =IFERROR((F39-D39)/D39,"-") -> - | I39: =IFERROR((F39-E39)/E39,"-") -> -
C40: Top 5 as % of Incurred | D40: =IFERROR(D39/D13,"-") -> - | E40: =IFERROR(E39/E13,"-") -> - | F40: =IFERROR(F39/F13,"-") -> - | H40: =IFERROR(IF(((F40-D40)*100)>0,"+"&ROUND((F40-D40)*100,1),ROUND((F40-D40)*100,1)),"-") -> - | I40: =IFERROR(IF(((F40-E40)*100)>0,"+"&ROUND((F40-E40)*100,1),ROUND((F40-E40)*100,1)),"-") -> -
B44: PY2 | C44: =Source1 -> California
C45: ="PY"&RIGHT(YEAR($F$46),2)&" at "&execute!D33&" Months" -> PY20 at 12 Months | D45: Policy Year Inception Date
D46: {=PY4_} -> 43101 | E46: {=PY3_} -> 43466 | F46: {=PY2_} -> 43831
D47: valued as of | E47: valued as of | F47: valued as of
D48: {=MONTH(Val_current)&"/"&DAY(Val_current)&"/"&YEAR(Val_current)-2} -> 1/0/1898 | E48: {=MONTH(Val_current)&"/"&DAY(Val_current)&"/"&YEAR(Val_current)-1} -> 1/0/1899 | F48: {=MONTH(Val_current)&"/"&DAY(Val_current)&"/"&YEAR(Val_current)} -> 1/0/1900 | G48: Trend | H48: {=(IF(IncYr_yn="Y",RIGHT(YEAR($D$46),2)&" vs "&RIGHT(YEAR($F$46),2),RIGHT(YEAR($D$46),2)+1&" vs "&RIGHT(YEAR($F$46),2)+1))} -> 18 vs 20 | I48: {=(IF(IncYr_yn="Y",RIGHT(YEAR($E$46),2)&" vs "&RIGHT(YEAR($F$46),2),RIGHT(YEAR($E$46),2)+1&" vs "&RIGHT(YEAR($F$46)+1,2)))} -> 19 vs 20
C50: Ultimates | D50: {=IFERROR(VLOOKUP(PY4_,$M$4:$R$13,3,FALSE),"-")} -> 9020000 | E50: {=IFERROR(VLOOKUP(PY3_,$M$4:$R$13,3,FALSE),"-")} -> 12830000 | F50: {=IFERROR(VLOOKUP(PY2_,$M$4:$R$13,3,FALSE),"-")} -> 12000000 | H50: =IFERROR((F50-D50)/D50,"-") -> 0.33037694 | I50: =IFERROR((F50-E50)/E50,"-") -> -0.064692128
...

Sheet Filtered Scorecard 2
A1: =Source2 -> 0
A2: =MIN(Months)&" Months" -> 0 Months | K2: =IF(ISBLANK('Total Scorecards'!C4),"-",'Total Scorecards'!C4) -> Notes | M2: =A1&" Exposures" -> 0 Exposures
K3: =IF(ISBLANK('Total Scorecards'!C5),"-",'Total Scorecards'!C5) -> $0 incurred claims excluded
B4: PY1 | C4: =Source2 -> 0 | K4: =IF(ISBLANK('Total Scorecards'!C6),"-",'Total Scorecards'!C6) -> financials limited to retention | M4: Policy Year Inception | N4: Retention | O4: Ultimate Incurred | P4: Ultimate Claim Count | Q4: Payroll (actual)
C5: ="PY"&RIGHT(YEAR($F$6),2)&" at "&execute!D32&" Months" -> PY21 at 0 Months | D5: Policy Year Inception Date | K5: =IF(ISBLANK('Total Scorecards'!C7),"-",'Total Scorecards'!C7) -> indemnity status defined by indemnity incurred >$0 | M5: {=PY1_} -> 44197 | N5: 400000 | O5: 700000 | P5: 30 | Q5: 55341000
D6: {=PY3_} -> 43466 | E6: {=PY2_} -> 43831 | F6: {=PY1_} -> 44197 | K6: =IF(ISBLANK('Total Scorecards'!C8),"-",'Total Scorecards'!C8) -> closure status defined by TPA | M6: {=PY2_} -> 43831 | N6: 400000 | O6: 340000 | P6: 62 | Q6: 27862000
D7: valued as of | E7: valued as of | F7: valued as of | K7: =IF(ISBLANK('Total Scorecards'!C9),"-",'Total Scorecards'!C9) -> litigation defined as represented date before valuation | M7: =PY3_ -> 43466 | N7: 400000 | O7: 219000 | P7: 49 | Q7: 26720000
D8: {=MONTH(Val_current)&"/"&DAY(Val_current)&"/"&YEAR(Val_current)-2} -> 1/0/1898 | E8: {=MONTH(Val_current)&"/"&DAY(Val_current)&"/"&YEAR(Val_current)-1} -> 1/0/1899 | F8: {=Val_current} -> 0 | G8: Trend | H8: {=IF(IncYr_yn="Y",RIGHT(YEAR($D$6),2)&" vs "&RIGHT(YEAR($F$6),2),RIGHT(YEAR($D$6),2)+1&" vs "&RIGHT(YEAR($F$6)+1,2))} -> 19 vs 21 | I8: {=IF(IncYr_yn="Y",RIGHT(YEAR($E$6),2)&" vs "&RIGHT(YEAR($F$6),2),RIGHT(YEAR($E$6),2)+1&" vs "&RIGHT(YEAR($F$6)+1,2))} -> 20 vs 21 | K8: =IF(ISBLANK('Total Scorecards'!C10),"-",'Total Scorecards'!C10) -> Actuarial: Milliman as of 3/31/19 | M8: =PY4_ -> 43101 | N8: 400000 | O8: 98000 | P8: 46 | Q8: 29312000
K9: =IF(ISBLANK('Total Scorecards'!C11),"-",'Total Scorecards'!C11) -> PY 7/1/18 ultimates are prorated from actuarial report | M9: =PY5_ -> 39083 | N9: 400000 | O9: 364000 | P9: 51 | Q9: 27408000
C10: Ultimates | D10: {=IFERROR(VLOOKUP(PY3_,$M$4:$R$13,3,FALSE),"-")} -> 219000 | E10: =IFERROR(VLOOKUP(PY2_,$M$4:$R$13,3,FALSE),"-") -> 340000 | F10: {=IFERROR(VLOOKUP(PY1_,$M$4:$R$13,3,FALSE),"-")} -> 700000 | H10: =IFERROR((F10-D10)/D10,"-") -> 2.196347 | I10: =IFERROR((F10-E10)/E10,"-") -> 1.0588235 | M10: =PY6_ -> 42370 | N10: 400000 | O10: 372000 | P10: 46 | Q10: 29300000
C11: Ultimate Claim Count | D11: =IFERROR(VLOOKUP(PY3_,$M$4:$P$11,4,FALSE),"-") -> 49 | E11: =IFERROR(VLOOKUP(PY2_,$M$4:$P$11,4,FALSE),"-") -> 62 | F11: =IFERROR(VLOOKUP(PY1_,$M$4:$P$11,4,FALSE),"-") -> 30 | H11: =IFERROR((F11-D11)/D11,"-") -> -0.3877551 | I11: =IFERROR((F11-E11)/E11,"-") -> -0.51612903 | M11: =PY7_ -> 42005
C13: Total Incurred | D13: {=SUM((IncLim)*(Months=months1)*(PY=PY3_)*(Filter1=Source2))} -> 0 | E13: {=SUM((IncLim)*(Months=months1)*(PY=PY2_)*(Filter1=Source2))} -> 0 | F13: {=SUM((IncLim)*(Months=months1)*(PY=PY1_)*(Filter1=Source2)*(Filter1=Source2))} -> 0 | H13: =IFERROR((F13-D13)/D13,"-") -> - | I13: =IFERROR((F13-E13)/E13,"-") -> -
C14: Total Paid | D14: {=SUM((pdLim)*(Months=months1)*(PY=PY3_)*(Filter1=Source2))} -> 0 | E14: {=SUM((pdLim)*(Months=months1)*(PY=PY2_)*(Filter1=Source2))} -> 0 | F14: =SUM((pdLim)*(Months=months1)*(PY=PY1_)*(Filter1=Source2)) -> 0 | H14: =IFERROR((F14-D14)/D14,"-") -> - | I14: =IFERROR((F14-E14)/E14,"-") -> -
C15: Total Outstanding | D15: =D13-D14 -> 0 | E15: =E13-E14 -> 0 | F15: =F13-F14 -> 0 | H15: =IFERROR((F15-D15)/D15,"-") -> - | I15: =IFERROR((F15-E15)/E15,"-") -> -
C17: Total Claims >$0 | D17: {=SUM((IncLim>0)*(Months=months1)*(PY=PY3_)*(Filter1=Source2))} -> 0 | E17: {=SUM((IncLim>0)*(Months=months1)*(PY=PY2_)*(Filter1=Source2))} -> 0 | F17: {=SUM((IncLim>0)*(Months=months1)*(PY=PY1_)*(Filter1=Source2))} -> 0 | H17: =IFERROR((F17-D17)/D17,"-") -> - | I17: =IFERROR((F17-E17)/E17,"-") -> -
C18: Average Cost per Claim | D18: =IFERROR(D13/D17,"-") -> - | E18: =IFERROR(E13/E17,"-") -> - | F18: =IFERROR(F13/F17,"-") -> - | H18: =IFERROR((F18-D18)/D18,"-") -> - | I18: =IFERROR((F18-E18)/E18,"-") -> -
C19: Median CPC | D19: {=IFERROR(MEDIAN(IF(IncLim>0, IF(Months=months1,IF(PY=PY3_, IF(Filter1=Source2, IncLim))))),"-")} -> - | E19: {=IFERROR(MEDIAN(IF(IncLim>0, IF(Months=months1,IF(PY=PY2_, IF(Filter1=Source2, IncLim))))),"-")} -> - | F19: {=IFERROR(MEDIAN(IF(IncLim>0, IF(Months=months1,IF(PY=PY1_, IF(Filter1=Source2,IncLim))))),"-")} -> - | H19: =IFERROR((F19-D19)/D19,"-") -> - | I19: =IFERROR((F19-E19)/E19,"-") -> -
C21: Payroll per $100 | D21: =IFERROR((VLOOKUP(PY3_,$M$4:$Q$10,5,FALSE)/100),"-") -> 267200 | E21: =IFERROR((VLOOKUP(PY2_,$M$4:$Q$10,5,FALSE)/100),"-") -> 278620 | F21: =IFERROR((VLOOKUP(PY1_,$M$4:$Q$10,5,FALSE)/100),"-") -> 553410 | H21: =IFERROR((F21-D21)/D21,"-") -> 1.0711452 | I21: =IFERROR((F21-E21)/E21,"-") -> 0.98625368
C22: Incurred Loss Rate | D22: =IFERROR(D13/D21,"-") -> 0 | E22: =IFERROR(E13/E21,"-") -> 0 | F22: =IFERROR(F13/F21,"-") -> 0 | H22: =IFERROR((F22-D22)/D22,"-") -> - | I22: =IFERROR((F22-E22)/E22,"-") -> -
C24: Indemnity Claims | D24: {=SUM((IncLim>0)*(indType>0)*(Months=months1)*(PY=PY3_)*(Filter1=Source2))} -> 0 | E24: {=SUM((IncLim>0)*(indType>0)*(Months=months1)*(PY=PY2_)*(Filter1=Source2))} -> 0 | F24: {=SUM((IncLim>0)*(indType>0)*(Months=months1)*(PY=PY1_)*(Filter1=Source2))} -> 0 | H24: =IFERROR((F24-D24)/D24,"-") -> - | I24: =IFERROR((F24-E24)/E24,"-") -> -
C25: Indemnity Rate | D25: =IFERROR(D24/D17,"-") -> - | E25: =IFERROR(E24/E17,"-") -> - | F25: =IFERROR(F24/F17,"-") -> - | H25: =IFERROR(IF(((F25-D25)*100)>0,"+"&ROUND((F25-D25)*100,1),ROUND((F25-D25)*100,1)),"-") -> - | I25: =IFERROR(IF(((F25-E25)*100)>0,"+"&ROUND((F25-E25)*100,1),ROUND((F25-E25)*100,1)),"-") -> -
C26: Total Inc- Ind Claims | D26: {=SUM((IncLim)*(indType>0)*(Months=months1)*(PY=PY3_)*(Filter1=Source2))} -> 0 | E26: {=SUM((IncLim)*(indType>0)*(Months=months1)*(PY=PY2_)*(Filter1=Source2))} -> 0 | F26: {=SUM((IncLim)*(indType>0)*(Months=months1)*(PY=PY1_)*(Filter1=Source2))} -> 0 | H26: =IFERROR((F26-D26)/D26,"-") -> - | I26: =IFERROR((F26-E26)/E26,"-") -> -
C27: ACPC- Ind Claims | D27: =IFERROR(D26/D24,"-") -> - | E27: =IFERROR(E26/E24,"-") -> - | F27: =IFERROR(F26/F24,"-") -> - | H27: =IFERROR((F27-D27)/D27,"-") -> - | I27: =IFERROR((F27-E27)/E27,"-") -> -
C28: Indemnity Closure Rate | D28: =IFERROR(1-(D29/D24),"-") -> - | E28: =IFERROR(1-(E29/E24),"-") -> - | F28: =IFERROR(1-(F29/F24),"-") -> - | H28: =IFERROR(IF(((F28-D28)*100)>0,"+"&ROUND((F28-D28)*100,1),ROUND((F28-D28)*100,1)),"-") -> - | I28: =IFERROR(IF(((F28-E28)*100)>0,"+"&ROUND((F28-E28)*100,1),ROUND((F28-E28)*100,1)),"-") -> -
C29: Open Indemnity Claims | D29: {=D24-SUM((IncLim>0)*(indType>0)*(Closed>0)*(Months=months1)*(PY=PY3_)*(Filter1=Source2))} -> 0 | E29: {=E24-SUM((IncLim>0)*(indType>0)*(Closed>0)*(Months=months1)*(PY=PY2_)*(Filter1=Source2))} -> 0 | F29: {=F24-SUM((IncLim>0)*(indType>0)*(Closed>0)*(Months=months1)*(PY=PY1_)*(Filter1=Source2))} -> 0 | H29: =IFERROR((F29-D29)/D29,"-") -> - | I29: =IFERROR((F29-E29)/E29,"-") -> -
C31: Litigated Ind Claims | D31: {=SUM((IncLim>0)*(Lit>0)*(indType>0)*(Months=months1)*(PY=PY3_)*(Filter1=Source2))} -> 0 | E31: {=SUM((IncLim>0)*(Lit>0)*(indType>0)*(Months=months1)*(PY=PY2_)*(Filter1=Source2))} -> 0 | F31: {=SUM((IncLim>0)*(Lit>0)*(indType>0)*(Months=months1)*(PY=PY1_)*(Filter1=Source2))} -> 0 | H31: =IFERROR((F31-D31)/D31,"-") -> - | I31: =IFERROR((F31-E31)/E31,"-") -> -
C32: Ind Litigation Rate | D32: =IFERROR(D31/D24,"-") -> - | E32: =IFERROR(E31/E24,"-") -> - | F32: =IFERROR(F31/F24,"-") -> - | H32: =IFERROR(IF(((F32-D32)*100)>0,"+"&ROUND((F32-D32)*100,1),ROUND((F32-D32)*100,1)),"-") -> - | I32: =IFERROR(IF(((F32-E32)*100)>0,"+"&ROUND((F32-E32)*100,1),ROUND((F32-E32)*100,1)),"-") -> -
C33: Total Lit Ind Incurred | D33: {=SUM((IncLim)*(Lit>0)*(indType>0)*(Months=months1)*(PY=PY3_)*(Filter1=Source2))} -> 0 | E33: {=SUM((IncLim)*(Lit>0)*(indType>0)*(Months=months1)*(PY=PY2_)*(Filter1=Source2))} -> 0 | F33: =SUM((IncLim)*(Lit>0)*(indType>0)*(Months=months1)*(PY=PY1_)*(Filter1=Source2)) -> 0 | H33: =IFERROR((F33-D33)/D33,"-") -> - | I33: =IFERROR((F33-E33)/E33,"-") -> -
C34: Lit Ind Inc % of Tot Ind Inc | D34: =IFERROR(D33/D26,"-") -> - | E34: =IFERROR(E33/E26,"-") -> - | F34: =IFERROR(F33/F26,"-") -> - | H34: =IFERROR(IF(((F34-D34)*100)>0,"+"&ROUND((F34-D34)*100,1),ROUND((F34-D34)*100,1)),"-") -> - | I34: =IFERROR(IF(((F34-E34)*100)>0,"+"&ROUND((F34-E34)*100,1),ROUND((F34-E34)*100,1)),"-") -> -
C35: Total Litigated Claims | D35: {=SUM((IncLim>0)*(Lit>0)*(Months=months1)*(PY=PY3_)*(Filter1=Source2))} -> 0 | E35: {=SUM((IncLim>0)*(Lit>0)*(Months=months1)*(PY=PY2_)*(Filter1=Source2))} -> 0 | F35: {=SUM((IncLim>0)*(Lit>0)*(Months=months1)*(PY=PY1_)*(Filter1=Source2))} -> 0 | H35: =IFERROR((F35-D35)/D35,"-") -> - | I35: =IFERROR((F35-E35)/E35,"-") -> -
C36: Total Litigated Incurred | D36: {=SUM((IncLim)*(Lit>0)*(Months=months1)*(PY=PY3_)*(Filter1=Source2))} -> 0 | E36: {=SUM((IncLim)*(Lit>0)*(Months=months1)*(PY=PY2_)*(Filter1=Source2))} -> 0 | F36: {=SUM((IncLim)*(Lit>0)*(Months=months1)*(PY=PY1_)*(Filter1=Source2))} -> 0 | H36: =IFERROR((F36-D36)/D36,"-") -> - | I36: =IFERROR((F36-E36)/E36,"-") -> -
C37: Average Days to Litigation | H37: =IFERROR((F37-D37)/D37,"-") -> - | I37: =IFERROR((F37-E37)/E37,"-") -> -
C39: Top 5 Claims | D39: =SUMPRODUCT(LARGE((Months=months1)*(PY=PY3_)*(IncLim)*(Filter1=Source2),{1,2,3,4,5})) -> 0 | E39: =SUMPRODUCT(LARGE((Months=months1)*(PY=PY2_)*(IncLim)*(Filter1=Source2),{1,2,3,4,5})) -> 0 | F39: =SUMPRODUCT(LARGE((Months=months1)*(PY=PY1_)*(IncLim)*(Filter1=Source2),{1,2,3,4,5})) -> 0 | H39: =IFERROR((F39-D39)/D39,"-") -> - | I39: =IFERROR((F39-E39)/E39,"-") -> -
C40: Top 5 as % of Incurred | D40: =IFERROR(D39/D13,"-") -> - | E40: =IFERROR(E39/E13,"-") -> - | F40: =IFERROR(F39/F13,"-") -> - | H40: =IFERROR(IF(((F40-D40)*100)>0,"+"&ROUND((F40-D40)*100,1),ROUND((F40-D40)*100,1)),"-") -> - | I40: =IFERROR(IF(((F40-E40)*100)>0,"+"&ROUND((F40-E40)*100,1),ROUND((F40-E40)*100,1)),"-") -> -
B44: PY2 | C44: =Source2 -> 0
C45: ="PY"&RIGHT(YEAR($F$46),2)&" at "&execute!D33&" Months" -> PY20 at 12 Months | D45: Policy Year Inception Date
D46: {=PY4_} -> 43101 | E46: {=PY3_} -> 43466 | F46: {=PY2_} -> 43831
D47: valued as of | E47: valued as of | F47: valued as of
D48: {=MONTH(Val_current)&"/"&DAY(Val_current)&"/"&YEAR(Val_current)-2} -> 1/0/1898 | E48: {=MONTH(Val_current)&"/"&DAY(Val_current)&"/"&YEAR(Val_current)-1} -> 1/0/1899 | F48: {=MONTH(Val_current)&"/"&DAY(Val_current)&"/"&YEAR(Val_current)} -> 1/0/1900 | G48: Trend | H48: {=(IF(IncYr_yn="Y",RIGHT(YEAR($D$46),2)&" vs "&RIGHT(YEAR($F$46),2),RIGHT(YEAR($D$46),2)+1&" vs "&RIGHT(YEAR($F$46),2)+1))} -> 18 vs 20 | I48: {=(IF(IncYr_yn="Y",RIGHT(YEAR($E$46),2)&" vs "&RIGHT(YEAR($F$46),2),RIGHT(YEAR($E$46),2)+1&" vs "&RIGHT(YEAR($F$46)+1,2)))} -> 19 vs 20
C50: Ultimates | D50: {=IFERROR(VLOOKUP(PY4_,$M$4:$R$13,3,FALSE),"-")} -> 98000 | E50: {=IFERROR(VLOOKUP(PY3_,$M$4:$R$13,3,FALSE),"-")} -> 219000 | F50: {=IFERROR(VLOOKUP(PY2_,$M$4:$R$13,3,FALSE),"-")} -> 340000 | H50: =IFERROR((F50-D50)/D50,"-") -> 2.4693878 | I50: =IFERROR((F50-E50)/E50,"-") -> 0.55251142
...

Sheet Filtered Scorecard 3
A1: =Source3 -> 0
A2: =MIN(Months)&" Months" -> 0 Months | K2: =IF(ISBLANK('Total Scorecards'!C4),"-",'Total Scorecards'!C4) -> Notes | M2: =A1&" Exposures" -> 0 Exposures
K3: =IF(ISBLANK('Total Scorecards'!C5),"-",'Total Scorecards'!C5) -> $0 incurred claims excluded
B4: PY1 | C4: =Source3 -> 0 | K4: =IF(ISBLANK('Total Scorecards'!C6),"-",'Total Scorecards'!C6) -> financials limited to retention | M4: Policy Year Inception | N4: Retention | O4: Ultimate Incurred | P4: Ultimate Claim Count | Q4: Payroll (actual)
C5: ="PY"&RIGHT(YEAR($F$6),2)&" at "&execute!D32&" Months" -> PY21 at 0 Months | D5: Policy Year Inception Date | K5: =IF(ISBLANK('Total Scorecards'!C7),"-",'Total Scorecards'!C7) -> indemnity status defined by indemnity incurred >$0 | M5: {=PY1_} -> 44197 | N5: 500000 | O5: 7758404 | Q5: 10000111
D6: {=PY3_} -> 43466 | E6: {=PY2_} -> 43831 | F6: {=PY1_} -> 44197 | K6: =IF(ISBLANK('Total Scorecards'!C8),"-",'Total Scorecards'!C8) -> closure status defined by TPA | M6: {=PY2_} -> 43831 | N6: 500000 | O6: 5378698 | P6: 207 | Q6: 10444000
D7: valued as of | E7: valued as of | F7: valued as of | K7: =IF(ISBLANK('Total Scorecards'!C9),"-",'Total Scorecards'!C9) -> litigation defined as represented date before valuation | M7: =PY3_ -> 43466 | N7: 500000 | O7: 8192021 | P7: 162 | Q7: 15500000
D8: {=MONTH(Val_current)&"/"&DAY(Val_current)&"/"&YEAR(Val_current)-2} -> 1/0/1898 | E8: {=MONTH(Val_current)&"/"&DAY(Val_current)&"/"&YEAR(Val_current)-1} -> 1/0/1899 | F8: {=Val_current} -> 0 | G8: Trend | H8: {=IF(IncYr_yn="Y",RIGHT(YEAR($D$6),2)&" vs "&RIGHT(YEAR($F$6),2),RIGHT(YEAR($D$6),2)+1&" vs "&RIGHT(YEAR($F$6)+1,2))} -> 19 vs 21 | I8: {=IF(IncYr_yn="Y",RIGHT(YEAR($E$6),2)&" vs "&RIGHT(YEAR($F$6),2),RIGHT(YEAR($E$6),2)+1&" vs "&RIGHT(YEAR($F$6)+1,2))} -> 20 vs 21 | K8: =IF(ISBLANK('Total Scorecards'!C10),"-",'Total Scorecards'!C10) -> Actuarial: Milliman as of 3/31/19 | M8: =PY4_ -> 43101 | N8: 500000 | O8: 6444927 | P8: 155 | Q8: 10660000
K9: =IF(ISBLANK('Total Scorecards'!C11),"-",'Total Scorecards'!C11) -> PY 7/1/18 ultimates are prorated from actuarial report | M9: =PY5_ -> 39083 | N9: 500000 | O9: 7260618 | P9: 154 | Q9: 10000000
C10: Ultimates | D10: {=IFERROR(VLOOKUP(PY3_,$M$4:$R$13,3,FALSE),"-")} -> 8192021 | E10: =IFERROR(VLOOKUP(PY2_,$M$4:$R$13,3,FALSE),"-") -> 5378698 | F10: {=IFERROR(VLOOKUP(PY1_,$M$4:$R$13,3,FALSE),"-")} -> 7758404 | H10: =IFERROR((F10-D10)/D10,"-") -> -0.052931627 | I10: =IFERROR((F10-E10)/E10,"-") -> 0.44243161 | M10: =PY6_ -> 42370 | N10: 500000 | Q10: 10000000
C11: Ultimate Claim Count | D11: =IFERROR(VLOOKUP(PY3_,$M$4:$P$11,4,FALSE),"-") -> 162 | E11: =IFERROR(VLOOKUP(PY2_,$M$4:$P$11,4,FALSE),"-") -> 207 | F11: =IFERROR(VLOOKUP(PY1_,$M$4:$P$11,4,FALSE),"-") -> 0 | H11: =IFERROR((F11-D11)/D11,"-") -> -1 | I11: =IFERROR((F11-E11)/E11,"-") -> -1 | M11: =PY7_ -> 42005
C13: Total Incurred | D13: {=SUM((IncLim)*(Months=months1)*(PY=PY3_)*(Filter1=Source3))} -> 0 | E13: {=SUM((IncLim)*(Months=months1)*(PY=PY2_)*(Filter1=Source3))} -> 0 | F13: {=SUM((IncLim)*(Months=months1)*(PY=PY1_)*(Filter1=Source3)*(Filter1=Source3))} -> 0 | H13: =IFERROR((F13-D13)/D13,"-") -> - | I13: =IFERROR((F13-E13)/E13,"-") -> -
C14: Total Paid | D14: {=SUM((pdLim)*(Months=months1)*(PY=PY3_)*(Filter1=Source3))} -> 0 | E14: {=SUM((pdLim)*(Months=months1)*(PY=PY2_)*(Filter1=Source3))} -> 0 | F14: {=SUM((pdLim)*(Months=months1)*(PY=PY1_)*(Filter1=Source3))} -> 0 | H14: =IFERROR((F14-D14)/D14,"-") -> - | I14: =IFERROR((F14-E14)/E14,"-") -> -
C15: Total Outstanding | D15: =D13-D14 -> 0 | E15: =E13-E14 -> 0 | F15: =F13-F14 -> 0 | H15: =IFERROR((F15-D15)/D15,"-") -> - | I15: =IFERROR((F15-E15)/E15,"-") -> -
C17: Total Claims >$0 | D17: {=SUM((IncLim>0)*(Months=months1)*(PY=PY3_)*(Filter1=Source3))} -> 0 | E17: {=SUM((IncLim>0)*(Months=months1)*(PY=PY2_)*(Filter1=Source3))} -> 0 | F17: {=SUM((IncLim>0)*(Months=months1)*(PY=PY1_)*(Filter1=Source3))} -> 0 | H17: =IFERROR((F17-D17)/D17,"-") -> - | I17: =IFERROR((F17-E17)/E17,"-") -> -
C18: Average Cost per Claim | D18: =IFERROR(D13/D17,"-") -> - | E18: =IFERROR(E13/E17,"-") -> - | F18: =IFERROR(F13/F17,"-") -> - | H18: =IFERROR((F18-D18)/D18,"-") -> - | I18: =IFERROR((F18-E18)/E18,"-") -> -
C19: Median CPC | D19: {=IFERROR(MEDIAN(IF(IncLim>0, IF(Months=months1,IF(PY=PY3_, IF(Filter1=Source3, IncLim))))),"-")} -> - | E19: {=IFERROR(MEDIAN(IF(IncLim>0, IF(Months=months1,IF(PY=PY2_, IF(Filter1=Source3, IncLim))))),"-")} -> - | F19: {=IFERROR(MEDIAN(IF(IncLim>0, IF(Months=months1,IF(PY=PY1_, IF(Filter1=Source3,IncLim))))),"-")} -> - | H19: =IFERROR((F19-D19)/D19,"-") -> - | I19: =IFERROR((F19-E19)/E19,"-") -> -
C21: Payroll per $100 | D21: =IFERROR((VLOOKUP(PY3_,$M$4:$Q$10,5,FALSE)/100),"-") -> 155000 | E21: =IFERROR((VLOOKUP(PY2_,$M$4:$Q$10,5,FALSE)/100),"-") -> 104440 | F21: =IFERROR((VLOOKUP(PY1_,$M$4:$Q$10,5,FALSE)/100),"-") -> 100001.11 | H21: =IFERROR((F21-D21)/D21,"-") -> -0.35483155 | I21: =IFERROR((F21-E21)/E21,"-") -> -0.042501819
C22: Incurred Loss Rate | D22: =IFERROR(D13/D21,"-") -> 0 | E22: =IFERROR(E13/E21,"-") -> 0 | F22: =IFERROR(F13/F21,"-") -> 0 | H22: =IFERROR((F22-D22)/D22,"-") -> - | I22: =IFERROR((F22-E22)/E22,"-") -> -
C24: Indemnity Claims | D24: {=SUM((IncLim>0)*(indType>0)*(Months=months1)*(PY=PY3_)*(Filter1=Source3))} -> 0 | E24: {=SUM((IncLim>0)*(indType>0)*(Months=months1)*(PY=PY2_)*(Filter1=Source3))} -> 0 | F24: {=SUM((IncLim>0)*(indType>0)*(Months=months1)*(PY=PY1_)*(Filter1=Source3))} -> 0 | H24: =IFERROR((F24-D24)/D24,"-") -> - | I24: =IFERROR((F24-E24)/E24,"-") -> -
C25: Indemnity Rate | D25: =IFERROR(D24/D17,"-") -> - | E25: =IFERROR(E24/E17,"-") -> - | F25: =IFERROR(F24/F17,"-") -> - | H25: =IFERROR(IF(((F25-D25)*100)>0,"+"&ROUND((F25-D25)*100,1),ROUND((F25-D25)*100,1)),"-") -> - | I25: =IFERROR(IF(((F25-E25)*100)>0,"+"&ROUND((F25-E25)*100,1),ROUND((F25-E25)*100,1)),"-") -> -
C26: Total Inc- Ind Claims | D26: {=SUM((IncLim)*(indType>0)*(Months=months1)*(PY=PY3_)*(Filter1=Source3))} -> 0 | E26: {=SUM((IncLim)*(indType>0)*(Months=months1)*(PY=PY2_)*(Filter1=Source3))} -> 0 | F26: {=SUM((IncLim)*(indType>0)*(Months=months1)*(PY=PY1_)*(Filter1=Source3))} -> 0 | H26: =IFERROR((F26-D26)/D26,"-") -> - | I26: =IFERROR((F26-E26)/E26,"-") -> -
C27: ACPC- Ind Claims | D27: =IFERROR(D26/D24,"-") -> - | E27: =IFERROR(E26/E24,"-") -> - | F27: =IFERROR(F26/F24,"-") -> - | H27: =IFERROR((F27-D27)/D27,"-") -> - | I27: =IFERROR((F27-E27)/E27,"-") -> -
C28: Indemnity Closure Rate | D28: =IFERROR(1-(D29/D24),"-") -> - | E28: =IFERROR(1-(E29/E24),"-") -> - | F28: =IFERROR(1-(F29/F24),"-") -> - | H28: =IFERROR(IF(((F28-D28)*100)>0,"+"&ROUND((F28-D28)*100,1),ROUND((F28-D28)*100,1)),"-") -> - | I28: =IFERROR(IF(((F28-E28)*100)>0,"+"&ROUND((F28-E28)*100,1),ROUND((F28-E28)*100,1)),"-") -> -
C29: Open Indemnity Claims | D29: {=D24-SUM((IncLim>0)*(indType>0)*(Closed>0)*(Months=months1)*(PY=PY3_)*(Filter1=Source3))} -> 0 | E29: {=E24-SUM((IncLim>0)*(indType>0)*(Closed>0)*(Months=months1)*(PY=PY2_)*(Filter1=Source3))} -> 0 | F29: {=F24-SUM((IncLim>0)*(indType>0)*(Closed>0)*(Months=months1)*(PY=PY1_)*(Filter1=Source3))} -> 0 | H29: =IFERROR((F29-D29)/D29,"-") -> - | I29: =IFERROR((F29-E29)/E29,"-") -> -
C31: Litigated Ind Claims | D31: {=SUM((IncLim>0)*(Lit>0)*(Months=months1)*(PY=PY3_)*(Filter1=Source3))} -> 0 | E31: {=SUM((IncLim>0)*(Lit>0)*(Months=months1)*(PY=PY2_)*(Filter1=Source3))} -> 0 | F31: {=SUM((IncLim>0)*(Lit>0)*(Months=months1)*(PY=PY1_)*(Filter1=Source3))} -> 0 | H31: =IFERROR((F31-D31)/D31,"-") -> - | I31: =IFERROR((F31-E31)/E31,"-") -> -
C32: Ind Litigation Rate | D32: =IFERROR(D31/D24,"-") -> - | E32: =IFERROR(E31/E24,"-") -> - | F32: =IFERROR(F31/F24,"-") -> - | H32: =IFERROR(IF(((F32-D32)*100)>0,"+"&ROUND((F32-D32)*100,1),ROUND((F32-D32)*100,1)),"-") -> - | I32: =IFERROR(IF(((F32-E32)*100)>0,"+"&ROUND((F32-E32)*100,1),ROUND((F32-E32)*100,1)),"-") -> -
C33: Total Lit Ind Incurred | D33: {=SUM((IncLim)*(Lit>0)*(indType>0)*(Months=months1)*(PY=PY3_)*(Filter1=Source3))} -> 0 | E33: {=SUM((IncLim)*(Lit>0)*(indType>0)*(Months=months1)*(PY=PY2_)*(Filter1=Source3))} -> 0 | F33: {=SUM((IncLim)*(Lit>0)*(indType>0)*(Months=months1)*(PY=PY1_)*(Filter1=Source3))} -> 0 | H33: =IFERROR((F33-D33)/D33,"-") -> - | I33: =IFERROR((F33-E33)/E33,"-") -> -
C34: Lit Ind Inc % of Tot Ind Inc | D34: =IFERROR(D33/D26,"-") -> - | E34: =IFERROR(E33/E26,"-") -> - | F34: =IFERROR(F33/F26,"-") -> - | H34: =IFERROR(IF(((F34-D34)*100)>0,"+"&ROUND((F34-D34)*100,1),ROUND((F34-D34)*100,1)),"-") -> - | I34: =IFERROR(IF(((F34-E34)*100)>0,"+"&ROUND((F34-E34)*100,1),ROUND((F34-E34)*100,1)),"-") -> -
C35: Total Litigated Claims | D35: {=SUM((IncLim>0)*(Lit>0)*(Months=months1)*(PY=PY3_)*(Filter1=Source3))} -> 0 | E35: {=SUM((IncLim>0)*(Lit>0)*(Months=months1)*(PY=PY2_)*(Filter1=Source3))} -> 0 | F35: {=SUM((IncLim>0)*(Lit>0)*(Months=months1)*(PY=PY1_)*(Filter1=Source3))} -> 0 | H35: =IFERROR((F35-D35)/D35,"-") -> - | I35: =IFERROR((F35-E35)/E35,"-") -> -
C36: Total Litigated Incurred | D36: {=SUM((IncLim)*(Lit>0)*(Months=months1)*(PY=PY3_)*(Filter1=Source3))} -> 0 | E36: {=SUM((IncLim)*(Lit>0)*(Months=months1)*(PY=PY2_)*(Filter1=Source3))} -> 0 | F36: {=SUM((IncLim)*(Lit>0)*(Months=months1)*(PY=PY1_)*(Filter1=Source3))} -> 0 | H36: =IFERROR((F36-D36)/D36,"-") -> - | I36: =IFERROR((F36-E36)/E36,"-") -> -
C37: Average Days to Litigation | H37: =IFERROR((F37-D37)/D37,"-") -> - | I37: =IFERROR((F37-E37)/E37,"-") -> -
C39: Top 5 Claims | D39: =SUMPRODUCT(LARGE((Months=months1)*(PY=PY3_)*(IncLim)*(Filter1=Source3),{1,2,3,4,5})) -> 0 | E39: =SUMPRODUCT(LARGE((Months=months1)*(PY=PY2_)*(IncLim)*(Filter1=Source3),{1,2,3,4,5})) -> 0 | F39: =SUMPRODUCT(LARGE((Months=months1)*(PY=PY1_)*(IncLim)*(Filter1=Source3),{1,2,3,4,5})) -> 0 | H39: =IFERROR((F39-D39)/D39,"-") -> - | I39: =IFERROR((F39-E39)/E39,"-") -> -
C40: Top 5 as % of Incurred | D40: =IFERROR(D39/D13,"-") -> - | E40: =IFERROR(E39/E13,"-") -> - | F40: =IFERROR(F39/F13,"-") -> - | H40: =IFERROR(IF(((F40-D40)*100)>0,"+"&ROUND((F40-D40)*100,1),ROUND((F40-D40)*100,1)),"-") -> - | I40: =IFERROR(IF(((F40-E40)*100)>0,"+"&ROUND((F40-E40)*100,1),ROUND((F40-E40)*100,1)),"-") -> -
B44: PY2 | C44: =Source3 -> 0
C45: ="PY"&RIGHT(YEAR($F$46),2)&" at "&execute!D33&" Months" -> PY20 at 12 Months | D45: Policy Year Inception Date
D46: {=PY4_} -> 43101 | E46: {=PY3_} -> 43466 | F46: {=PY2_} -> 43831
D47: valued as of | E47: valued as of | F47: valued as of
D48: {=MONTH(Val_current)&"/"&DAY(Val_current)&"/"&YEAR(Val_current)-2} -> 1/0/1898 | E48: {=MONTH(Val_current)&"/"&DAY(Val_current)&"/"&YEAR(Val_current)-1} -> 1/0/1899 | F48: {=MONTH(Val_current)&"/"&DAY(Val_current)&"/"&YEAR(Val_current)} -> 1/0/1900 | G48: Trend | H48: {=(IF(IncYr_yn="Y",RIGHT(YEAR($D$46),2)&" vs "&RIGHT(YEAR($F$46),2),RIGHT(YEAR($D$46),2)+1&" vs "&RIGHT(YEAR($F$46),2)+1))} -> 18 vs 20 | I48: {=(IF(IncYr_yn="Y",RIGHT(YEAR($E$46),2)&" vs "&RIGHT(YEAR($F$46),2),RIGHT(YEAR($E$46),2)+1&" vs "&RIGHT(YEAR($F$46)+1,2)))} -> 19 vs 20
C50: Ultimates | D50: {=IFERROR(VLOOKUP(PY4_,$M$4:$R$13,3,FALSE),"-")} -> 6444927 | E50: {=IFERROR(VLOOKUP(PY3_,$M$4:$R$13,3,FALSE),"-")} -> 8192021 | F50: {=IFERROR(VLOOKUP(PY2_,$M$4:$R$13,3,FALSE),"-")} -> 5378698 | H50: =IFERROR((F50-D50)/D50,"-") -> -0.16543694 | I50: =IFERROR((F50-E50)/E50,"-") -> -0.34342234
...

Sheet Indemnity Rate
B4: Policy Effective Date | C4: Claims | D4: Indemnity Claims | E4: Indemnity Rate
B5: =PY7_ -> 42005 | C5: {=SUM((IncLim>0)*(Valuation=Val_current)*(PY=PY7_))} -> 0 | D5: {=SUM((IncLim>0)*(Valuation=Val_current)*(indType>0)*(PY=PY7_))} -> 0 | E5: =IFERROR(D5/C5,"-") -> -
B6: =PY6_ -> 42370 | C6: {=SUM((IncLim>0)*(Valuation=Val_current)*(PY=PY6_))} -> 0 | D6: {=SUM((IncLim>0)*(Valuation=Val_current)*(indType>0)*(PY=PY6_))} -> 0 | E6: =IFERROR(D6/C6,"-") -> -
B7: =PY5_ -> 39083 | C7: {=SUM((IncLim>0)*(Valuation=Val_current)*(PY=PY5_))} -> 0 | D7: {=SUM((IncLim>0)*(Valuation=Val_current)*(indType>0)*(PY=PY5_))} -> 0 | E7: =IFERROR(D7/C7,"-") -> -
B8: =PY4_ -> 43101 | C8: {=SUM((IncLim>0)*(Valuation=Val_current)*(PY=PY4_))} -> 0 | D8: {=SUM((IncLim>0)*(Valuation=Val_current)*(indType>0)*(PY=PY4_))} -> 0 | E8: =IFERROR(D8/C8,"-") -> -
B9: =PY3_ -> 43466 | C9: {=SUM((IncLim>0)*(Valuation=Val_current)*(PY=PY3_))} -> 0 | D9: {=SUM((IncLim>0)*(Valuation=Val_current)*(indType>0)*(PY=PY3_))} -> 0 | E9: =IFERROR(D9/C9,"-") -> -
B10: =PY2_ -> 43831 | C10: {=SUM((IncLim>0)*(Valuation=Val_current)*(PY=PY2_))} -> 0 | D10: {=SUM((IncLim>0)*(Valuation=Val_current)*(indType>0)*(PY=PY2_))} -> 0 | E10: =IFERROR(D10/C10,"-") -> -
B11: =PY1_ -> 44197 | C11: {=SUM((IncLim>0)*(Valuation=Val_current)*(PY=PY1_))} -> 0 | D11: {=SUM((IncLim>0)*(Valuation=Val_current)*(indType>0)*(PY=PY1_))} -> 0 | E11: =IFERROR(D11/C11,"-") -> -
B12: Grand Total | C12: =SUM(C6:C11) -> 0 | D12: =SUM(D6:D11) -> 0 | E12: =D12/C12 -> #DIV/0!
B14: Excludes $0 claims
B15: Current valuation

Sheet Ultimate Severity
B5: Policy Effective Date | C5: Ultimate Claims | D5: Ultimate | E5: Ultimate Severity
B6: =PY7_ -> 42005 | C6: {=PY7_ultCT} -> 0 | D6: {=PY7_ult} -> 0 | E6: =IFERROR(D6/C6,"-") -> -
B7: =PY6_ -> 42370 | C7: {=PY6_ultCt} -> 0 | D7: {=PY6_ult} -> 0 | E7: =IFERROR(D7/C7,"-") -> -
B8: =PY5_ -> 39083 | C8: {=PY5_ultCt} -> 0 | D8: {=PY5_ult} -> 0 | E8: =IFERROR(D8/C8,"-") -> -
B9: =PY4_ -> 43101 | C9: {=PY4_ultCt} -> 0 | D9: {=PY4_ult} -> 0 | E9: =IFERROR(D9/C9,"-") -> -
B10: =PY3_ -> 43466 | C10: {=PY3_ultCt} -> 0 | D10: {=PY3_ult} -> 0 | E10: =IFERROR(D10/C10,"-") -> -
B11: =PY2_ -> 43831 | C11: {=PY2_ultCt} -> 0 | D11: {=PY2_ult} -> 0 | E11: =IFERROR(D11/C11,"-") -> -
B12: =PY1_ -> 44197 | C12: {=PY1_ultCt} -> 0 | D12: {=PY1_ult} -> 0 | E12: =IFERROR(D12/C12,"-") -> -

Sheet Litigation Analysis
B5: Litigated | C5: % of claims | D5: % of incurred | E5: % of outstanding
B6: All claims open & closed since 2015 | C6: =COUNTIFS(execute!$T:$T,Val_current,execute!$Q:$Q,"1",execute!$K:$K,">"&0,execute!$I:$I,">="&42005)/COUNTIFS(execute!$T:$T,Val_current,execute!$K:$K,">"&0,execute!$I:$I,">="&42005) -> #DIV/0! | D6: =SUMIFS(execute!$K:$K,execute!$T:$T,Val_current,execute!$Q:$Q,"1",execute!$K:$K,">"&0,execute!$I:$I,">="&42005)/SUMIFS(execute!$K:$K,execute!$T:$T,Val_current,execute!$K:$K,">"&0,execute!$I:$I,">="&42005) -> #DIV/0! | E6: =SUMIFS(execute!$M:$M,execute!$T:$T,Val_current,execute!$Q:$Q,"1",execute!$K:$K,">"&0,execute!$I:$I,">="&42005)/SUMIFS(execute!$M:$M,execute!$T:$T,Val_current,execute!$K:$K,">"&0,execute!$I:$I,">="&42005) -> #DIV/0!
B7: Indemnity claims since 2015 | C7: =COUNTIFS(execute!$T:$T,Val_current,execute!$Q:$Q,"1",execute!#REF!,"1",execute!$K:$K,">"&0,execute!$I:$I,">="&42005)/COUNTIFS(execute!$T:$T,Val_current,execute!#REF!,"1",execute!$K:$K,">"&0,execute!$I:$I,">="&42005) -> #REF! | D7: =SUMIFS(execute!$K:$K,execute!$T:$T,Val_current,execute!$Q:$Q,"1",execute!#REF!,"1",execute!$K:$K,">"&0,execute!$I:$I,">="&42005)/SUMIFS(execute!$K:$K,execute!$T:$T,Val_current,execute!#REF!,"1",execute!$K:$K,">"&0,execute!$I:$I,">="&42005) -> #REF! | E7: =SUMIFS(execute!$M:$M,execute!$T:$T,Val_current,execute!$Q:$Q,"1",execute!#REF!,"1",execute!$K:$K,">"&0,execute!$I:$I,">="&42005)/SUMIFS(execute!$M:$M,execute!$T:$T,Val_current,execute!#REF!,"1",execute!$K:$K,">"&0,execute!$I:$I,">="&42005) -> #REF!
B8: All claims currently open
B9: USE OPEN INVENTORY LOSS RUN TO CALCULATE METRICS FOR All claims currently open
B11: table used for graphic
C12: Claims | D12: Incurred
B13: Not litigated | C13: =1-C14 -> #REF! | D13: =1-D14 -> #REF!
B14: Litigated | C14: =C7 -> #REF! | D14: =D7 -> #REF!
B20: Calculate average and median days to litigation
B21: Litigation Lag (days from open to litigated) | C21: # Days
B22: Mean
B23: Median
B29: Litigated | C29: # of litigated claims | D29: # of total claims | E29: litigated total incurred | F29: total incurred | G29: litigated total outstanding | H29: total outstanding
B30: All claims open & closed since 2015 | C30: =COUNTIFS(execute!$T:$T,Val_current,execute!$Q:$Q,"1",execute!$K:$K,">"&0,execute!$I:$I,">="&42005) -> 0 | D30: =COUNTIFS(execute!$T:$T,Val_current,execute!$K:$K,">"&0,execute!$I:$I,">="&42005) -> 0 | E30: =SUMIFS(execute!$K:$K,execute!$T:$T,Val_current,execute!$Q:$Q,"1",execute!$K:$K,">"&0,execute!$I:$I,">="&42005) -> 0 | F30: =SUMIFS(execute!$K:$K,execute!$T:$T,Val_current,execute!$K:$K,">"&0,execute!$I:$I,">="&42005) -> 0 | G30: =SUMIFS(execute!$M:$M,execute!$T:$T,Val_current,execute!$Q:$Q,"1",execute!$K:$K,">"&0,execute!$I:$I,">="&42005) -> 0 | H30: =SUMIFS(execute!$M:$M,execute!$T:$T,Val_current,execute!$K:$K,">"&0,execute!$I:$I,">="&42005) -> 0
B31: Indemnity claims since 2015 | C31: =COUNTIFS(execute!$T:$T,Val_current,execute!$Q:$Q,"1",execute!#REF!,"1",execute!$K:$K,">"&0,execute!$I:$I,">="&42005) -> #REF! | D31: =COUNTIFS(execute!$T:$T,Val_current,execute!#REF!,"1",execute!$K:$K,">"&0,execute!$I:$I,">="&42005) -> #REF! | E31: =SUMIFS(execute!$K:$K,execute!$T:$T,Val_current,execute!$Q:$Q,"1",execute!#REF!,"1",execute!$K:$K,">"&0,execute!$I:$I,">="&42005) -> #REF! | F31: =SUMIFS(execute!$K:$K,execute!$T:$T,Val_current,execute!#REF!,"1",execute!$K:$K,">"&0,execute!$I:$I,">="&42005) -> #REF! | G31: =SUMIFS(execute!$M:$M,execute!$T:$T,Val_current,execute!$Q:$Q,"1",execute!#REF!,"1",execute!$K:$K,">"&0,execute!$I:$I,">="&42005) -> #REF! | H31: =SUMIFS(execute!$M:$M,execute!$T:$T,Val_current,execute!#REF!,"1",execute!$K:$K,">"&0,execute!$I:$I,">="&42005) -> #REF!
B32: All claims currently open* | C32: =COUNTIFS(execute!$T:$T,Val_current,execute!$Q:$Q,"1",execute!$K:$K,">"&0,execute!$O:$O,"0") -> 0 | D32: =COUNTIFS(execute!$T:$T,Val_current,execute!$K:$K,">"&0,execute!$O:$O,"0") -> 0 | E32: =SUMIFS(execute!$K:$K,execute!$T:$T,Val_current,execute!$Q:$Q,"1",execute!$K:$K,">"&0,execute!$O:$O,"0") -> 0 | F32: =SUMIFS(execute!$K:$K,execute!$T:$T,Val_current,execute!$K:$K,">"&0,execute!$O:$O,"0") -> 0 | G32: =SUMIFS(execute!$M:$M,execute!$T:$T,Val_current,execute!$Q:$Q,"1",execute!$K:$K,">"&0,execute!$O:$O,"0") -> 0 | H32: =SUMIFS(execute!$M:$M,execute!$T:$T,Val_current,execute!$K:$K,">"&0,execute!$O:$O,"0") -> 0

Sheet Runoff Schedule
