Workbook

Sheet claims list
A1: Claim Number | B1: Claimant | C1: Accident Date | D1: Reported Date | E1: Coverage | F1: Resolution Manager | G1: Reporting Unit | H1: Status | I1: Accident State | J1: Total Incurred | K1: Claim In Suit | L1: Claim In Suit Date | M1: Total Outstanding | N1: Incurred Net Recovery - Ind/BI | O1: Part of Body | P1: Claimant Age | Q1: Claimant Represented | R1: Branch | S1: Total Paid Net Recovery | T1: FY | U1: % Paid | V1: Paid % Bucket | W1: Over $1M | X1: top state | Y1: First Draft Selections | Z1: First Draft Bin | AA1: In Suit Bin
A2: 000531-073048-WC-01 | B2: Acosta, Elizabeth | C2: 44246 | D2: 44259 | E2: Workers Compensation | F2: Marta Eilers | G2: 5374 - AUTOZONE-5374 | H2: Open | I2: CA | J2: 46001 | K2: In Suit | L2: 44274 | M2: 45991 | N2: 20000 | O2: Multiple Body Parts | P2: 33 | Q2: Yes, Attorney Disclosure Form filed | R2: GB-SACRAMENTO EAST | S2: 10 | T2: 44075 | U2: 0.00021738658 | V2: a. <10% | W2: 0 | X2: 1 | Y2: FY 2021 | Z2: 1 | AA2: 1
A3: 000531-073522-WC-01 | B3: Ramirez, Jose | C3: 43903 | D3: 44292 | E3: Workers Compensation | F3: Maria Barlow | G3: 5562 - AUTOZONE-5562 | H3: Open | I3: CA | J3: 12500 | K3: In Suit | L3: 44299 | M3: 12490 | N3: 1500 | O3: Hands | P3: 31 | Q3: Yes, Attorney Disclosure Form filed | R3: GB-SACRAMENTO EAST | S3: 10 | T3: 43709 | U3: 0.0008 | V3: a. <10% | W3: 0 | X3: 1 | Y3: FY 2020 | Z3: 1 | AA3: 1
A4: 000531-071037-WC-01 | B4: Gomez, Arnulfo | C4: 44094 | D4: 44095 | E4: Workers Compensation | F4: Marta Eilers | G4: 6218 - AUTOZONE-6218 | H4: Open | I4: CA | J4: 38693 | K4: In Suit | L4: 44309 | M4: 35461.25 | N4: 4000 | O4: Back, lower | P4: 59 | Q4: Yes, Attorney Disclosure Form filed | R4: GB-SACRAMENTO EAST | S4: 3231.75 | T4: 44075 | U4: 0.083522859 | V4: a. <10% | W4: 0 | X4: 1 | Y4: FY 2021 | Z4: 1 | AA4: 1
A5: 000531-061486-WC-01 | B5: Haynes, Felicia | C5: 43269 | D5: 43269 | E5: Workers Compensation | F5: Marta Eilers | G5: 5463 - AUTOZONE-5463 | H5: Open | I5: CA | J5: 88994 | K5: In Suit | L5: 43299 | M5: 47470.18 | N5: 34703 | O5: Neck - Multiple Injuries to the Neck | P5: 44 | Q5: Yes, Attorney Disclosure Form filed | R5: GB-SACRAMENTO EAST | S5: 41523.82 | T5: 42979 | U5: 0.46659123 | V5: b. 10-90% | W5: 0 | X5: 1 | Y5: Before FY 2020 | Z5: 1 | AA5: 1
A6: 000531-065854-WC-01 | B6: Jimenez, Jonah | C6: 43641 | D6: 43642 | E6: Workers Compensation | F6: Maria Barlow | G6: 3359 - AUTOZONE 3359 | H6: Open | I6: CA | J6: 132805 | K6: Not in Suit | M6: 99351.95 | N6: 35970 | O6: Knee, right | P6: 29 | Q6: No | R6: GB-SACRAMENTO EAST | S6: 33453.05 | T6: 43344 | U6: 0.25189601 | V6: b. 10-90% | W6: 0 | X6: 1 | Y6: Before FY 2020 | Z6: 1 | AA6: 0
A7: 000531-070118-WC-01 | B7: Castro, Donna | C7: 44015 | D7: 44018 | E7: Workers Compensation | F7: Maria Barlow | G7: 9710 - AUTOZONE DISTRIBUTION | H7: Open | I7: CA | J7: 49658 | K7: Not in Suit | M7: 28687.02 | N7: 23211 | O7: Toe, Great | P7: 52 | Q7: No | R7: GB-SACRAMENTO EAST | S7: 20970.98 | T7: 43709 | U7: 0.42230819 | V7: b. 10-90% | W7: 0 | X7: 1 | Y7: FY 2020 | Z7: 1 | AA7: 0
A8: 000531-068692-WC-01 | B8: Galindo, Jose | C8: 43852 | D8: 43881 | E8: Workers Compensation | F8: Maria Barlow | G8: 9710 - AUTOZONE DISTRIBUTION | H8: Open | I8: CA | J8: 49463 | K8: In Suit | L8: 43935 | M8: 34561.2 | N8: 2500 | O8: Back, upper (thoracic) | P8: 65 | Q8: Yes | R8: GB-SACRAMENTO EAST | S8: 14901.8 | T8: 43709 | U8: 0.30127166 | V8: b. 10-90% | W8: 0 | X8: 1 | Y8: FY 2020 | Z8: 1 | AA8: 1
A9: 000531-067923-WC-01 | B9: Zapata, Andree | C9: 43810 | D9: 43810 | E9: Workers Compensation | F9: Maria Barlow | G9: 2819 - AUTOZONE-2819 | H9: Open | I9: CA | J9: 49829 | K9: In Suit | L9: 44068 | M9: 38145.73 | N9: 4300 | O9: Multiple Body Parts | P9: 58 | Q9: Yes, Attorney Disclosure Form filed | R9: GB-SACRAMENTO EAST | S9: 11683.27 | T9: 43709 | U9: 0.23446728 | V9: b. 10-90% | W9: 0 | X9: 1 | Y9: FY 2020 | Z9: 1 | AA9: 1
A10: 000531-066858-WC-01 | B10: Vega-Bravo, Lucina | C10: 43716 | D10: 43719 | E10: Workers Compensation | F10: Marta Eilers | G10: 9710 - AUTOZONE DISTRIBUTION | H10: Open | I10: CA | J10: 162161 | K10: In Suit | L10: 43920 | M10: 81175.14 | N10: 24661 | O10: Leg, right | P10: 47 | Q10: Yes, Attorney Disclosure Form filed | R10: GB-SACRAMENTO EAST | S10: 80985.86 | T10: 43709 | U10: 0.49941638 | V10: b. 10-90% | W10: 0 | X10: 1 | Y10: FY 2020 | Z10: 1 | AA10: 1
A11: 000531-072994-WC-01 | B11: Lehman, Allan | C11: 44257 | D11: 44258 | E11: Workers Compensation | F11: Jody Curtis | G11: 4819 - AUTOZONE #4819 | H11: Open | I11: FL | J11: 49447 | K11: Not in Suit | M11: 48331.39 | N11: 2156 | O11: Arm, right | P11: 60 | Q11: No | R11: GALLAGHER BASSETT -NASHVILLE | S11: 1115.61 | T11: 44075 | U11: 0.022561733 | V11: a. <10% | W11: 0 | X11: 1 | Y11: FY 2021 | Z11: 1 | AA11: 0
A12: 000531-069395-WC-01 | B12: Carvajal, Roger | C12: 43957 | D12: 43959 | E12: Workers Compensation | F12: Jody Curtis | G12: 4961 - AUTOZONE-4961 | H12: Open | I12: FL | J12: 49878 | K12: In Suit | L12: 43978 | M12: 22148.83 | N12: 16239 | O12: Knee, left | P12: 52 | Q12: Yes | R12: GALLAGHER BASSETT -NASHVILLE | S12: 27729.17 | T12: 43709 | U12: 0.55593989 | V12: b. 10-90% | W12: 0 | X12: 1 | Y12: FY 2020 | Z12: 1 | AA12: 1
A13: 000531-070995-WC-01 | B13: Rosas, Rafael | C13: 44090 | D13: 44095 | E13: Workers Compensation | F13: Jody Curtis | G13: 4852 - AUTO ZONE-4852 | H13: Reopened | I13: FL | J13: 35423 | K13: In Suit | L13: 44278 | M13: 29985.05 | N13: 10000 | O13: Back, lower | P13: 38 | Q13: Yes | R13: GALLAGHER BASSETT -NASHVILLE | S13: 5437.95 | T13: 44075 | U13: 0.15351467 | V13: b. 10-90% | W13: 0 | X13: 1 | Y13: FY 2021 | Z13: 1 | AA13: 1
A14: 000531-067917-WC-01 | B14: Davis, Gregory | C14: 43799 | D14: 43808 | E14: Workers Compensation | F14: Jody Curtis | G14: 2448 - AUTOZONE-2448 | H14: Open | I14: FL | J14: 97259 | K14: In Suit | L14: 43978 | M14: 50635.16 | N14: 36882 | O14: Back, lower | P14: 54 | Q14: Yes | R14: GALLAGHER BASSETT -NASHVILLE | S14: 46623.84 | T14: 43709 | U14: 0.47937816 | V14: b. 10-90% | W14: 0 | X14: 1 | Y14: FY 2020 | Z14: 1 | AA14: 1
A15: 000531-070650-WC-01 | B15: Hunt, Michael | C15: 44068 | D15: 44068 | E15: Workers Compensation | F15: Candyce Graham | G15: 0158 - AUTOZONE-0158 | H15: Open | I15: GA | J15: 114781 | K15: Not in Suit | M15: 23806.08 | N15: 26990 | O15: Neck - cervical disc | P15: 51 | Q15: No | R15: GALLAGHER BASSETT -NASHVILLE | S15: 90974.92 | T15: 43709 | U15: 0.79259564 | V15: b. 10-90% | W15: 0 | X15: 1 | Y15: FY 2020 | Z15: 1 | AA15: 0
A16: 000531-070204-WC-01 | B16: Cedar, Harry | C16: 44028 | D16: 44029 | E16: Workers Compensation | F16: Candyce Graham | G16: 3169 - AUTOZONE 3169 | H16: Open | I16: GA | J16: 49300 | K16: Not in Suit | M16: 38035.15 | N16: 4956 | O16: Shoulder, right | P16: 59 | Q16: No | R16: GALLAGHER BASSETT -NASHVILLE | S16: 11264.85 | T16: 43709 | U16: 0.22849594 | V16: b. 10-90% | W16: 0 | X16: 1 | Y16: FY 2020 | Z16: 1 | AA16: 0
A17: 000531-069687-WC-01 | B17: Gatlin, Vivian | C17: 43990 | D17: 43990 | E17: Workers Compensation | F17: Candyce Graham | G17: 0940 - AUTOZONE-0940 | H17: Open | I17: GA | J17: 138979 | K17: In Suit | L17: 44142 | M17: 81932.01 | N17: 67508 | O17: Back, lower | P17: 62 | Q17: Yes | R17: GALLAGHER BASSETT -NASHVILLE | S17: 57046.99 | T17: 43709 | U17: 0.41047201 | V17: b. 10-90% | W17: 0 | X17: 1 | Y17: FY 2020 | Z17: 1 | AA17: 1
A18: 000531-071987-WC-01 | B18: Lee, Robert | C18: 44179 | D18: 44179 | E18: Workers Compensation | F18: Donna Tincher | G18: 2680 - AUTOZONE-2680 | H18: Open | I18: IL | J18: 402698 | K18: Not in Suit | M18: 377136.77 | N18: 352358 | O18: Chest and/or ribs | P18: 69 | Q18: No | R18: GB-ROLLING MEADOWS / REGIONAL | S18: 25561.23 | T18: 44075 | U18: 0.063474937 | V18: a. <10% | W18: 0 | X18: 1 | Y18: FY 2021 | Z18: 1 | AA18: 0
A19: 000531-067756-WC-01 | B19: Mulligan, Sean | C19: 43798 | D19: 43801 | E19: Workers Compensation | F19: Donna Tincher | G19: 2651 - AUTOZONE-2651 | H19: Open | I19: IL | J19: 104340 | K19: Not in Suit | M19: 8751.81 | N19: 18382 | O19: Shoulder, right | P19: 54 | Q19: Yes | R19: GB-ROLLING MEADOWS / REGIONAL | S19: 95588.19 | T19: 43709 | U19: 0.9161222 | V19: c. 90%+ | W19: 0 | X19: 1 | Y19: FY 2020 | Z19: 1 | AA19: 0
A20: 000531-070989-WC-01 | B20: Farrell, Trisa | C20: 44016 | D20: 44096 | E20: Workers Compensation | F20: Donna Tincher | G20: 2640 - AUTOZONE-2640 | H20: Open | I20: IL | J20: 10750 | K20: Not in Suit | M20: 10026.5 | N20: 2500 | O20: No physical injury | P20: 45 | Q20: Yes | R20: GB-ROLLING MEADOWS / REGIONAL | S20: 723.5 | T20: 43709 | U20: 0.067302326 | V20: a. <10% | W20: 0 | X20: 1 | Y20: FY 2020 | Z20: 1 | AA20: 0
A21: 000531-059202-WC-01 | B21: Tree, Derek | C21: 43097 | D21: 43098 | E21: Workers Compensation | F21: Donna Tincher | G21: 2691 - AUTOZONE-2691 | H21: Open | I21: IL | J21: 259033 | K21: In Suit | L21: 43270 | M21: 140242.52 | N21: 56681 | O21: Neck - cervical disc | P21: 65 | Q21: Yes | R21: GB-ROLLING MEADOWS / REGIONAL | S21: 118790.48 | T21: 42979 | U21: 0.45859207 | V21: b. 10-90% | W21: 0 | X21: 1 | Y21: Before FY 2020 | Z21: 1 | AA21: 1
A22: 000531-068868-WC-01 | B22: Perez, Carlos | C22: 43895 | D22: 43899 | E22: Workers Compensation | F22: Donna Tincher | G22: 4469 - AUTOZONE-4469 | H22: Open | I22: IL | J22: 376177 | K22: Not in Suit | M22: 256582.82 | N22: 200787 | O22: Back, lower | P22: 42 | Q22: No | R22: GB-ROLLING MEADOWS / REGIONAL | S22: 119594.18 | T22: 43709 | U22: 0.31791997 | V22: b. 10-90% | W22: 0 | X22: 1 | Y22: FY 2020 | Z22: 1 | AA22: 0
A23: 000531-066911-WC-01 | B23: Moore, Shan | C23: 43722 | D23: 43724 | E23: Workers Compensation | F23: Donna Tincher | G23: 2571 - AUTOZONE-2571S | H23: Open | I23: IL | J23: 111156 | K23: In Suit | L23: 44124 | M23: 72298.68 | N23: 35014 | O23: Shoulder, right | P23: 43 | Q23: Yes | R23: GB-ROLLING MEADOWS / REGIONAL | S23: 38857.32 | T23: 43709 | U23: 0.34957465 | V23: b. 10-90% | W23: 0 | X23: 1 | Y23: FY 2020 | Z23: 1 | AA23: 1
A24: 000531-069791-WC-01 | B24: Schomaker, Jason | C24: 43997 | D24: 43998 | E24: Workers Compensation | F24: Michael Cline | G24: 0710 - AUTOZONE-0710 | H24: Open | I24: OH | J24: 59472 | K24: In Suit | L24: 44155 | M24: 21476.92 | N24: 21896 | O24: Arm, right | P24: 41 | Q24: No | R24: GALLAGHER BASSETT - COLUMBUS | S24: 37995.08 | T24: 43709 | U24: 0.63887342 | V24: b. 10-90% | W24: 0 | X24: 1 | Y24: FY 2020 | Z24: 1 | AA24: 1
A25: 000531-066810-WC-01 | B25: Roberts, Merrell | C25: 43713 | D25: 43717 | E25: Workers Compensation | F25: Claire Goodyear | G25: 1122 - AUTOZONE-1122 | H25: Open | I25: PA | J25: 105034 | K25: Not in Suit | M25: 7473.29 | N25: 44323 | O25: Back, lower | P25: 28 | Q25: No | R25: GB-BURLINGTON WC | S25: 97560.71 | T25: 43709 | U25: 0.92884885 | V25: c. 90%+ | W25: 0 | X25: 1 | Y25: FY 2020 | Z25: 1 | AA25: 0
A26: 000531-067087-WC-01 | B26: Nichols, Harry | C26: 43738 | D26: 43741 | E26: Workers Compensation | F26: Claire Goodyear | G26: 9720 - AUTOZONE #9720 | H26: Open | I26: PA | J26: 108190 | K26: In Suit | L26: 44305 | M26: 7956.19 | N26: 54645 | O26: Face | P26: 45 | Q26: Yes | R26: GB-BURLINGTON WC | S26: 100233.81 | T26: 43709 | U26: 0.92646095 | V26: c. 90%+ | W26: 0 | X26: 1 | Y26: FY 2020 | Z26: 1 | AA26: 1
A27: 000531-069344-WC-01 | B27: Lebron, Angel | C27: 43955 | D27: 43955 | E27: Workers Compensation | F27: Claire Goodyear | G27: 5290 - AUTOZONE-5290 | H27: Open | I27: PA | J27: 49922 | K27: In Suit | L27: 43999 | M27: 24426.16 | N27: 7436 | O27: Teeth or tooth | P27: 40 | Q27: Yes | R27: GB-BURLINGTON WC | S27: 25495.84 | T27: 43709 | U27: 0.51071351 | V27: b. 10-90% | W27: 0 | X27: 1 | Y27: FY 2020 | Z27: 1 | AA27: 1
A28: 000531-061686-WC-01 | B28: Goldwire, Jeffery | C28: 43304 | D28: 43312 | E28: Workers Compensation | F28: Claire Goodyear | G28: 8351 - AUTOZONE MAINTENANCE 8351 | H28: Open | I28: PA | J28: 178982 | K28: In Suit | L28: 43460 | M28: 43809.38 | N28: 108147 | O28: Leg, left | P28: 50 | Q28: Yes | R28: GB-BURLINGTON WC | S28: 135172.62 | T28: 42979 | U28: 0.75523025 | V28: b. 10-90% | W28: 0 | X28: 1 | Y28: Before FY 2020 | Z28: 1 | AA28: 1
A29: 000531-069959-WC-01 | B29: Rodenheiser, Shannon | C29: 43999 | D29: 44011 | E29: Workers Compensation | F29: Claire Goodyear | G29: 1831 - AUTOZONE-1831 | H29: Open | I29: PA | J29: 139312 | K29: Not in Suit | M29: 55801.53 | N29: 34711 | O29: Foot, right | P29: 40 | Q29: No | R29: GB-BURLINGTON WC | S29: 83510.47 | T29: 43709 | U29: 0.59944922 | V29: b. 10-90% | W29: 0 | X29: 1 | Y29: FY 2020 | Z29: 1 | AA29: 0
A30: 000531-070487-WC-01 | B30: Poole, Kenneth | C30: 44026 | D30: 44049 | E30: Workers Compensation | F30: Claire Goodyear | G30: 2843 - AUTOZONE-2843 | H30: Open | I30: PA | J30: 132522 | K30: Not in Suit | M30: 72937.84 | N30: 44251 | O30: Shoulders | P30: 76 | Q30: No | R30: GB-BURLINGTON WC | S30: 59584.16 | T30: 43709 | U30: 0.44961712 | V30: b. 10-90% | W30: 0 | X30: 1 | Y30: FY 2020 | Z30: 1 | AA30: 0
A31: 000531-060014-WC-01 | B31: Budd, Roman | C31: 43161 | D31: 43161 | E31: Workers Compensation | F31: Claire Goodyear | G31: 5294 - AUTOZONE-5294 | H31: Open | I31: PA | J31: 619989 | K31: In Suit | L31: 43313 | M31: 237512.36 | N31: 287178 | O31: Back, lower | P31: 30 | Q31: Yes | R31: GB-BURLINGTON WC | S31: 382476.64 | T31: 42979 | U31: 0.61690875 | V31: b. 10-90% | W31: 0 | X31: 1 | Y31: Before FY 2020 | Z31: 1 | AA31: 1

Sheet claim 1
A1: EPIC Risk Consulting Quality Claim Assessment Tool
A3: Claimant: | B3: ='claims list'!B2 -> Acosta, Elizabeth | D3: Jurisdiction: | E3: ='claims list'!I2 -> CA | F3: Date Reported | G3: Indemnity | H3: Incurred | I3: Paid | J3: Outstanding
A4: Claim #: | B4: ='claims list'!A2 -> 000531-073048-WC-01 | D4: Adjuster: | E4: ='claims list'!F2 -> Marta Eilers | F4: ='claims list'!D2 -> 44259 | G4: ='claims list'!N2 -> 20000 | H4: ='claims list'!J2 -> 46001 | I4: ='claims list'!S2 -> 10 | J4: ='claims list'!M2 -> 45991
E5: Meets Standard | F5: Leakage Value | G5: Brief Comment/Explanation
A6: Claim Investigation
A7: 1 | B7: Was the claim properly investigated to include taking recorded statements, obtaining prior medical reports, obtaining witness statements, verifying causation, etc.? | E7: N/A
A8: 2 | B8: Does the adjuster re-evaluate causation when new/additional body parts are added? | E8: N/A
A9: 3 | B9: Does the file reflect any evidence of any adjuster rapport tactics such benefit explanation to EE and/ or bi-weekly EE contact during lost time period? | E9: N/A
A10: 4 | B10: Does the adjuster properly address any lag times from the DOI to the date reported to the TPA/carrier? (Late report is defined as greater than 2 days to the time the employee reported the claim to the employer or TPA) | E10: N/A
A11: 5 | B11: Are recovery opportunities being realized (subrogation)? | E11: N/A
A12: Resolution Plans & Claim Follow Up
A13: 6 | B13: Do the action plans contain a specific and aggressive plan to bring the claim to closure? | E13: N/A
A14: 7 | B14: Does the action plan have completion due dates for any necessary follow up activities? | E14: N/A
A15: 8 | B15: Are the action plans executed in a timely manner that do not hinder the claim outcome? If not, indicate the Opportunity Cost | E15: N/A
A16: 9 | B16: Does the adjuster keep an appropriate diary? | E16: N/A
A17: Supervisor Direction & Special Handling
A18: 10 | B18: Are the supervisor reviews completed timely? | E18: N/A
A19: 11 | B19: Do the supervisor review address any missed opportunities for resoultion and provide clear direction/recommendations | E19: N/A
A20: 12 | B20: Does the adjustet take action and or respond to the Supervisor recommendations? | E20: N/A
A21: 13 | B21: Does the supervisor hold the adjuster accountable for moving claim to resolution? | E21: N/A
A22: 14 | B22: Does the Superisor update recommendations based on current file status at time of review (does not cut and paste) | E22: N/A
A23: Reserving
A24: 15 | B24: Are the current reserves appropriate to resolve the claim? | E24: N/A
A25: 16 | B25: Are the reserves adjusted timely in accordance with the claim developments? | E25: N/A
A26: Disability & Medical Management
A27: 17 | B27: Does the adjuster (or nurse) use ODG to manage RTW? | E27: N/A
A28: 18 | B28: Are the RTW target dates being communicated to all parties (i.e. EE, client contact, and treating physician)? | E28: N/A
A29: 19 | B29: Does the adjuster (or nurse) pro-actively address expired RTW target dates with the treating physician? If not, indicate leakage amount. | E29: N/A
A30: 20 | B30: Does the file reflect evidence of a non-accommodation RTW escalation process? | E30: N/A
A31: 21 | B31: Did the adjuster obtain the medical information on a timely basis? | E31: N/A
A32: 22 | B32: Is the adjuster pro-active in engaging ancillary resources and programs (TCM/NCM, IME, Pharmacy programs, etc.) | E32: N/A
A33: 23 | B33: If applicable, does the adjuster property manage the UR process to reduce medical delays and administrative denials? | E33: N/A
A34: 24 | B34: Is there a causal relationship between the current treatment plan and the accepted WC injury? | E34: N/A
A35: Settlement Disposition
A36: 25 | B36: Have early settlement opportunities been realized? If not, indicate amount of leakage. | E36: N/A
A37: 26 | B37: Has the adjuster completed his or her own evaluation and negotiations rather than defense counsel? | E37: N/A
A38: 27 | B38: Does the settlement evaluation include the future exposure, recommended settlement range, and planned negotiation plan? | E38: N/A
A39: 28 | B39: Upon receipt of settlement authority, has the adjuster/defense counsel made a reasonable offer of resolution within 2 business days? | E39: N/A
A40: 29 | B40: Did the adjuster extend a timed initial offer? | E40: N/A
A41: Litigation Management
...

Sheet claim 2
A1: EPIC Risk Consulting Quality Claim Assessment Tool
A3: Claimant: | B3: ='claims list'!B3 -> Ramirez, Jose | D3: Jurisdiction: | E3: ='claims list'!I3 -> CA | F3: Date Reported | G3: Indemnity | H3: Incurred | I3: Paid | J3: Outstanding
A4: Claim #: | B4: ='claims list'!A3 -> 000531-073522-WC-01 | D4: Adjuster: | E4: ='claims list'!F3 -> Maria Barlow | F4: ='claims list'!D3 -> 44292 | G4: ='claims list'!N3 -> 1500 | H4: ='claims list'!J3 -> 12500 | I4: ='claims list'!S3 -> 10 | J4: ='claims list'!M3 -> 12490
E5: Meets Standard | F5: Leakage Value | G5: Brief Comment/Explanation
A6: Claim Investigation
A7: 1 | B7: Was the claim properly investigated to include taking recorded statements, obtaining prior medical reports, obtaining witness statements, verifying causation, etc.? | E7: N/A
A8: 2 | B8: Does the adjuster re-evaluate causation when new/additional body parts are added? | E8: N/A
A9: 3 | B9: Does the file reflect any evidence of any adjuster rapport tactics such benefit explanation to EE and/ or bi-weekly EE contact during lost time period? | E9: N/A
A10: 4 | B10: Does the adjuster properly address any lag times from the DOI to the date reported to the TPA/carrier? (Late report is defined as greater than 2 days to the time the employee reported the claim to the employer or TPA) | E10: N/A
A11: 5 | B11: Are recovery opportunities being realized (subrogation)? | E11: N/A
A12: Resolution Plans & Claim Follow Up
A13: 6 | B13: Do the action plans contain a specific and aggressive plan to bring the claim to closure? | E13: N/A
A14: 7 | B14: Does the action plan have completion due dates for any necessary follow up activities? | E14: N/A
A15: 8 | B15: Are the action plans executed in a timely manner that do not hinder the claim outcome? If not, indicate the Opportunity Cost | E15: N/A
A16: 9 | B16: Does the adjuster keep an appropriate diary? | E16: N/A
A17: Supervisor Direction & Special Handling
A18: 10 | B18: Are the supervisor reviews completed timely? | E18: N/A
A19: 11 | B19: Do the supervisor review address any missed opportunities for resoultion and provide clear direction/recommendations | E19: N/A
A20: 12 | B20: Does the adjustet take action and or respond to the Supervisor recommendations? | E20: N/A
A21: 13 | B21: Does the supervisor hold the adjuster accountable for moving claim to resolution? | E21: N/A
A22: 14 | B22: Does the Superisor update recommendations based on current file status at time of review (does not cut and paste) | E22: N/A
A23: Reserving
A24: 15 | B24: Are the current reserves appropriate to resolve the claim? | E24: N/A
A25: 16 | B25: Are the reserves adjusted timely in accordance with the claim developments? | E25: N/A
A26: Disability & Medical Management
A27: 17 | B27: Does the adjuster (or nurse) use ODG to manage RTW? | E27: N/A
A28: 18 | B28: Are the RTW target dates being communicated to all parties (i.e. EE, client contact, and treating physician)? | E28: N/A
A29: 19 | B29: Does the adjuster (or nurse) pro-actively address expired RTW target dates with the treating physician? If not, indicate leakage amount. | E29: N/A
A30: 20 | B30: Does the file reflect evidence of a non-accommodation RTW escalation process? | E30: N/A
A31: 21 | B31: Did the adjuster obtain the medical information on a timely basis? | E31: N/A
A32: 22 | B32: Is the adjuster pro-active in engaging ancillary resources and programs (TCM/NCM, IME, Pharmacy programs, etc.) | E32: N/A
A33: 23 | B33: If applicable, does the adjuster property manage the UR process to reduce medical delays and administrative denials? | E33: N/A
A34: 24 | B34: Is there a causal relationship between the current treatment plan and the accepted WC injury? | E34: N/A
A35: Settlement Disposition
A36: 25 | B36: Have early settlement opportunities been realized? If not, indicate amount of leakage. | E36: N/A
A37: 26 | B37: Has the adjuster completed his or her own evaluation and negotiations rather than defense counsel? | E37: N/A
A38: 27 | B38: Does the settlement evaluation include the future exposure, recommended settlement range, and planned negotiation plan? | E38: N/A
A39: 28 | B39: Upon receipt of settlement authority, has the adjuster/defense counsel made a reasonable offer of resolution within 2 business days? | E39: N/A
A40: 29 | B40: Did the adjuster extend a timed initial offer? | E40: N/A
A41: Litigation Management
...

Sheet claim 3
A1: EPIC Risk Consulting Quality Claim Assessment Tool
A3: Claimant: | B3: ='claims list'!B4 -> Gomez, Arnulfo | D3: Jurisdiction: | E3: ='claims list'!I4 -> CA | F3: Date Reported | G3: Indemnity | H3: Incurred | I3: Paid | J3: Outstanding
A4: Claim #: | B4: ='claims list'!A4 -> 000531-071037-WC-01 | D4: Adjuster: | E4: ='claims list'!F4 -> Marta Eilers | F4: ='claims list'!D4 -> 44095 | G4: ='claims list'!N4 -> 4000 | H4: ='claims list'!J4 -> 38693 | I4: ='claims list'!S4 -> 3231.75 | J4: ='claims list'!M4 -> 35461.25
E5: Meets Standard | F5: Leakage Value | G5: Brief Comment/Explanation
A6: Claim Investigation
A7: 1 | B7: Was the claim properly investigated to include taking recorded statements, obtaining prior medical reports, obtaining witness statements, verifying causation, etc.? | E7: N/A
A8: 2 | B8: Does the adjuster re-evaluate causation when new/additional body parts are added? | E8: N/A
A9: 3 | B9: Does the file reflect any evidence of any adjuster rapport tactics such benefit explanation to EE and/ or bi-weekly EE contact during lost time period? | E9: N/A
A10: 4 | B10: Does the adjuster properly address any lag times from the DOI to the date reported to the TPA/carrier? (Late report is defined as greater than 2 days to the time the employee reported the claim to the employer or TPA) | E10: N/A
A11: 5 | B11: Are recovery opportunities being realized (subrogation)? | E11: N/A
A12: Resolution Plans & Claim Follow Up
A13: 6 | B13: Do the action plans contain a specific and aggressive plan to bring the claim to closure? | E13: N/A
A14: 7 | B14: Does the action plan have completion due dates for any necessary follow up activities? | E14: N/A
A15: 8 | B15: Are the action plans executed in a timely manner that do not hinder the claim outcome? If not, indicate the Opportunity Cost | E15: N/A
A16: 9 | B16: Does the adjuster keep an appropriate diary? | E16: N/A
A17: Supervisor Direction & Special Handling
A18: 10 | B18: Are the supervisor reviews completed timely? | E18: N/A
A19: 11 | B19: Do the supervisor review address any missed opportunities for resoultion and provide clear direction/recommendations | E19: N/A
A20: 12 | B20: Does the adjustet take action and or respond to the Supervisor recommendations? | E20: N/A
A21: 13 | B21: Does the supervisor hold the adjuster accountable for moving claim to resolution? | E21: N/A
A22: 14 | B22: Does the Superisor update recommendations based on current file status at time of review (does not cut and paste) | E22: N/A
A23: Reserving
A24: 15 | B24: Are the current reserves appropriate to resolve the claim? | E24: N/A
A25: 16 | B25: Are the reserves adjusted timely in accordance with the claim developments? | E25: N/A
A26: Disability & Medical Management
A27: 17 | B27: Does the adjuster (or nurse) use ODG to manage RTW? | E27: N/A
A28: 18 | B28: Are the RTW target dates being communicated to all parties (i.e. EE, client contact, and treating physician)? | E28: N/A
A29: 19 | B29: Does the adjuster (or nurse) pro-actively address expired RTW target dates with the treating physician? If not, indicate leakage amount. | E29: N/A
A30: 20 | B30: Does the file reflect evidence of a non-accommodation RTW escalation process? | E30: N/A
A31: 21 | B31: Did the adjuster obtain the medical information on a timely basis? | E31: N/A
A32: 22 | B32: Is the adjuster pro-active in engaging ancillary resources and programs (TCM/NCM, IME, Pharmacy programs, etc.) | E32: N/A
A33: 23 | B33: If applicable, does the adjuster property manage the UR process to reduce medical delays and administrative denials? | E33: N/A
A34: 24 | B34: Is there a causal relationship between the current treatment plan and the accepted WC injury? | E34: N/A
A35: Settlement Disposition
A36: 25 | B36: Have early settlement opportunities been realized? If not, indicate amount of leakage. | E36: N/A
A37: 26 | B37: Has the adjuster completed his or her own evaluation and negotiations rather than defense counsel? | E37: N/A
A38: 27 | B38: Does the settlement evaluation include the future exposure, recommended settlement range, and planned negotiation plan? | E38: N/A
A39: 28 | B39: Upon receipt of settlement authority, has the adjuster/defense counsel made a reasonable offer of resolution within 2 business days? | E39: N/A
A40: 29 | B40: Did the adjuster extend a timed initial offer? | E40: N/A
A41: Litigation Management
...

Sheet claim 4
A1: EPIC Risk Consulting Quality Claim Assessment Tool
A3: Claimant: | B3: ='claims list'!B5 -> Haynes, Felicia | D3: Jurisdiction: | E3: ='claims list'!I5 -> CA | F3: Date Reported | G3: Indemnity | H3: Incurred | I3: Paid | J3: Outstanding
A4: Claim #: | B4: ='claims list'!A5 -> 000531-061486-WC-01 | D4: Adjuster: | E4: ='claims list'!F5 -> Marta Eilers | F4: ='claims list'!D5 -> 43269 | G4: ='claims list'!N5 -> 34703 | H4: ='claims list'!J5 -> 88994 | I4: ='claims list'!S5 -> 41523.82 | J4: ='claims list'!M5 -> 47470.18
E5: Meets Standard | F5: Leakage Value | G5: Brief Comment/Explanation
A6: Claim Investigation
A7: 1 | B7: Was the claim properly investigated to include taking recorded statements, obtaining prior medical reports, obtaining witness statements, verifying causation, etc.? | E7: N/A
A8: 2 | B8: Does the adjuster re-evaluate causation when new/additional body parts are added? | E8: N/A
A9: 3 | B9: Does the file reflect any evidence of any adjuster rapport tactics such benefit explanation to EE and/ or bi-weekly EE contact during lost time period? | E9: N/A
A10: 4 | B10: Does the adjuster properly address any lag times from the DOI to the date reported to the TPA/carrier? (Late report is defined as greater than 2 days to the time the employee reported the claim to the employer or TPA) | E10: N/A
A11: 5 | B11: Are recovery opportunities being realized (subrogation)? | E11: N/A
A12: Resolution Plans & Claim Follow Up
A13: 6 | B13: Do the action plans contain a specific and aggressive plan to bring the claim to closure? | E13: N/A
A14: 7 | B14: Does the action plan have completion due dates for any necessary follow up activities? | E14: N/A
A15: 8 | B15: Are the action plans executed in a timely manner that do not hinder the claim outcome? If not, indicate the Opportunity Cost | E15: N/A
A16: 9 | B16: Does the adjuster keep an appropriate diary? | E16: N/A
A17: Supervisor Direction & Special Handling
A18: 10 | B18: Are the supervisor reviews completed timely? | E18: N/A
A19: 11 | B19: Do the supervisor review address any missed opportunities for resoultion and provide clear direction/recommendations | E19: N/A
A20: 12 | B20: Does the adjustet take action and or respond to the Supervisor recommendations? | E20: N/A
A21: 13 | B21: Does the supervisor hold the adjuster accountable for moving claim to resolution? | E21: N/A
A22: 14 | B22: Does the Superisor update recommendations based on current file status at time of review (does not cut and paste) | E22: N/A
A23: Reserving
A24: 15 | B24: Are the current reserves appropriate to resolve the claim? | E24: N/A
A25: 16 | B25: Are the reserves adjusted timely in accordance with the claim developments? | E25: N/A
A26: Disability & Medical Management
A27: 17 | B27: Does the adjuster (or nurse) use ODG to manage RTW? | E27: N/A
A28: 18 | B28: Are the RTW target dates being communicated to all parties (i.e. EE, client contact, and treating physician)? | E28: N/A
A29: 19 | B29: Does the adjuster (or nurse) pro-actively address expired RTW target dates with the treating physician? If not, indicate leakage amount. | E29: N/A
A30: 20 | B30: Does the file reflect evidence of a non-accommodation RTW escalation process? | E30: N/A
A31: 21 | B31: Did the adjuster obtain the medical information on a timely basis? | E31: N/A
A32: 22 | B32: Is the adjuster pro-active in engaging ancillary resources and programs (TCM/NCM, IME, Pharmacy programs, etc.) | E32: N/A
A33: 23 | B33: If applicable, does the adjuster property manage the UR process to reduce medical delays and administrative denials? | E33: N/A
A34: 24 | B34: Is there a causal relationship between the current treatment plan and the accepted WC injury? | E34: N/A
A35: Settlement Disposition
A36: 25 | B36: Have early settlement opportunities been realized? If not, indicate amount of leakage. | E36: N/A
A37: 26 | B37: Has the adjuster completed his or her own evaluation and negotiations rather than defense counsel? | E37: N/A
A38: 27 | B38: Does the settlement evaluation include the future exposure, recommended settlement range, and planned negotiation plan? | E38: N/A
A39: 28 | B39: Upon receipt of settlement authority, has the adjuster/defense counsel made a reasonable offer of resolution within 2 business days? | E39: N/A
A40: 29 | B40: Did the adjuster extend a timed initial offer? | E40: N/A
A41: Litigation Management
...

Sheet claim 5
A1: EPIC Risk Consulting Quality Claim Assessment Tool
A3: Claimant: | B3: ='claims list'!B6 -> Jimenez, Jonah | D3: Jurisdiction: | E3: ='claims list'!I6 -> CA | F3: Date Reported | G3: Indemnity | H3: Incurred | I3: Paid | J3: Outstanding
A4: Claim #: | B4: ='claims list'!A6 -> 000531-065854-WC-01 | D4: Adjuster: | E4: ='claims list'!F6 -> Maria Barlow | F4: ='claims list'!D6 -> 43642 | G4: ='claims list'!N6 -> 35970 | H4: ='claims list'!J6 -> 132805 | I4: ='claims list'!S6 -> 33453.05 | J4: ='claims list'!M6 -> 99351.95
E5: Meets Standard | F5: Leakage Value | G5: Brief Comment/Explanation
A6: Claim Investigation
A7: 1 | B7: Was the claim properly investigated to include taking recorded statements, obtaining prior medical reports, obtaining witness statements, verifying causation, etc.? | E7: N/A
A8: 2 | B8: Does the adjuster re-evaluate causation when new/additional body parts are added? | E8: N/A
A9: 3 | B9: Does the file reflect any evidence of any adjuster rapport tactics such benefit explanation to EE and/ or bi-weekly EE contact during lost time period? | E9: N/A
A10: 4 | B10: Does the adjuster properly address any lag times from the DOI to the date reported to the TPA/carrier? (Late report is defined as greater than 2 days to the time the employee reported the claim to the employer or TPA) | E10: N/A
A11: 5 | B11: Are recovery opportunities being realized (subrogation)? | E11: N/A
A12: Resolution Plans & Claim Follow Up
A13: 6 | B13: Do the action plans contain a specific and aggressive plan to bring the claim to closure? | E13: N/A
A14: 7 | B14: Does the action plan have completion due dates for any necessary follow up activities? | E14: N/A
A15: 8 | B15: Are the action plans executed in a timely manner that do not hinder the claim outcome? If not, indicate the Opportunity Cost | E15: N/A
A16: 9 | B16: Does the adjuster keep an appropriate diary? | E16: N/A
A17: Supervisor Direction & Special Handling
A18: 10 | B18: Are the supervisor reviews completed timely? | E18: N/A
A19: 11 | B19: Do the supervisor review address any missed opportunities for resoultion and provide clear direction/recommendations | E19: N/A
A20: 12 | B20: Does the adjustet take action and or respond to the Supervisor recommendations? | E20: N/A
A21: 13 | B21: Does the supervisor hold the adjuster accountable for moving claim to resolution? | E21: N/A
A22: 14 | B22: Does the Superisor update recommendations based on current file status at time of review (does not cut and paste) | E22: N/A
A23: Reserving
A24: 15 | B24: Are the current reserves appropriate to resolve the claim? | E24: N/A
A25: 16 | B25: Are the reserves adjusted timely in accordance with the claim developments? | E25: N/A
A26: Disability & Medical Management
A27: 17 | B27: Does the adjuster (or nurse) use ODG to manage RTW? | E27: N/A
A28: 18 | B28: Are the RTW target dates being communicated to all parties (i.e. EE, client contact, and treating physician)? | E28: N/A
A29: 19 | B29: Does the adjuster (or nurse) pro-actively address expired RTW target dates with the treating physician? If not, indicate leakage amount. | E29: N/A
A30: 20 | B30: Does the file reflect evidence of a non-accommodation RTW escalation process? | E30: N/A
A31: 21 | B31: Did the adjuster obtain the medical information on a timely basis? | E31: N/A
A32: 22 | B32: Is the adjuster pro-active in engaging ancillary resources and programs (TCM/NCM, IME, Pharmacy programs, etc.) | E32: N/A
A33: 23 | B33: If applicable, does the adjuster property manage the UR process to reduce medical delays and administrative denials? | E33: N/A
A34: 24 | B34: Is there a causal relationship between the current treatment plan and the accepted WC injury? | E34: N/A
A35: Settlement Disposition
A36: 25 | B36: Have early settlement opportunities been realized? If not, indicate amount of leakage. | E36: N/A
A37: 26 | B37: Has the adjuster completed his or her own evaluation and negotiations rather than defense counsel? | E37: N/A
A38: 27 | B38: Does the settlement evaluation include the future exposure, recommended settlement range, and planned negotiation plan? | E38: N/A
A39: 28 | B39: Upon receipt of settlement authority, has the adjuster/defense counsel made a reasonable offer of resolution within 2 business days? | E39: N/A
A40: 29 | B40: Did the adjuster extend a timed initial offer? | E40: N/A
A41: Litigation Management
...

Sheet claim 6
A1: EPIC Risk Consulting Quality Claim Assessment Tool
A3: Claimant: | B3: ='claims list'!B7 -> Castro, Donna | D3: Jurisdiction: | E3: ='claims list'!I7 -> CA | F3: Date Reported | G3: Indemnity | H3: Incurred | I3: Paid | J3: Outstanding
A4: Claim #: | B4: ='claims list'!A7 -> 000531-070118-WC-01 | D4: Adjuster: | E4: ='claims list'!F7 -> Maria Barlow | F4: ='claims list'!D7 -> 44018 | G4: ='claims list'!N7 -> 23211 | H4: ='claims list'!J7 -> 49658 | I4: ='claims list'!S7 -> 20970.98 | J4: ='claims list'!M7 -> 28687.02
E5: Meets Standard | F5: Leakage Value | G5: Brief Comment/Explanation
A6: Claim Investigation
A7: 1 | B7: Was the claim properly investigated to include taking recorded statements, obtaining prior medical reports, obtaining witness statements, verifying causation, etc.? | E7: N/A
A8: 2 | B8: Does the adjuster re-evaluate causation when new/additional body parts are added? | E8: N/A
A9: 3 | B9: Does the file reflect any evidence of any adjuster rapport tactics such benefit explanation to EE and/ or bi-weekly EE contact during lost time period? | E9: N/A
A10: 4 | B10: Does the adjuster properly address any lag times from the DOI to the date reported to the TPA/carrier? (Late report is defined as greater than 2 days to the time the employee reported the claim to the employer or TPA) | E10: N/A
A11: 5 | B11: Are recovery opportunities being realized (subrogation)? | E11: N/A
A12: Resolution Plans & Claim Follow Up
A13: 6 | B13: Do the action plans contain a specific and aggressive plan to bring the claim to closure? | E13: N/A
A14: 7 | B14: Does the action plan have completion due dates for any necessary follow up activities? | E14: N/A
A15: 8 | B15: Are the action plans executed in a timely manner that do not hinder the claim outcome? If not, indicate the Opportunity Cost | E15: N/A
A16: 9 | B16: Does the adjuster keep an appropriate diary? | E16: N/A
A17: Supervisor Direction & Special Handling
A18: 10 | B18: Are the supervisor reviews completed timely? | E18: N/A
A19: 11 | B19: Do the supervisor review address any missed opportunities for resoultion and provide clear direction/recommendations | E19: N/A
A20: 12 | B20: Does the adjustet take action and or respond to the Supervisor recommendations? | E20: N/A
A21: 13 | B21: Does the supervisor hold the adjuster accountable for moving claim to resolution? | E21: N/A
A22: 14 | B22: Does the Superisor update recommendations based on current file status at time of review (does not cut and paste) | E22: N/A
A23: Reserving
A24: 15 | B24: Are the current reserves appropriate to resolve the claim? | E24: N/A
A25: 16 | B25: Are the reserves adjusted timely in accordance with the claim developments? | E25: N/A
A26: Disability & Medical Management
A27: 17 | B27: Does the adjuster (or nurse) use ODG to manage RTW? | E27: N/A
A28: 18 | B28: Are the RTW target dates being communicated to all parties (i.e. EE, client contact, and treating physician)? | E28: N/A
A29: 19 | B29: Does the adjuster (or nurse) pro-actively address expired RTW target dates with the treating physician? If not, indicate leakage amount. | E29: N/A
A30: 20 | B30: Does the file reflect evidence of a non-accommodation RTW escalation process? | E30: N/A
A31: 21 | B31: Did the adjuster obtain the medical information on a timely basis? | E31: N/A
A32: 22 | B32: Is the adjuster pro-active in engaging ancillary resources and programs (TCM/NCM, IME, Pharmacy programs, etc.) | E32: N/A
A33: 23 | B33: If applicable, does the adjuster property manage the UR process to reduce medical delays and administrative denials? | E33: N/A
A34: 24 | B34: Is there a causal relationship between the current treatment plan and the accepted WC injury? | E34: N/A
A35: Settlement Disposition
A36: 25 | B36: Have early settlement opportunities been realized? If not, indicate amount of leakage. | E36: N/A
A37: 26 | B37: Has the adjuster completed his or her own evaluation and negotiations rather than defense counsel? | E37: N/A
A38: 27 | B38: Does the settlement evaluation include the future exposure, recommended settlement range, and planned negotiation plan? | E38: N/A
A39: 28 | B39: Upon receipt of settlement authority, has the adjuster/defense counsel made a reasonable offer of resolution within 2 business days? | E39: N/A
A40: 29 | B40: Did the adjuster extend a timed initial offer? | E40: N/A
A41: Litigation Management
...

Sheet claim 7
A1: EPIC Risk Consulting Quality Claim Assessment Tool
A3: Claimant: | B3: ='claims list'!B8 -> Galindo, Jose | D3: Jurisdiction: | E3: ='claims list'!I8 -> CA | F3: Date Reported | G3: Indemnity | H3: Incurred | I3: Paid | J3: Outstanding
A4: Claim #: | B4: ='claims list'!A8 -> 000531-068692-WC-01 | D4: Adjuster: | E4: ='claims list'!F8 -> Maria Barlow | F4: ='claims list'!D8 -> 43881 | G4: ='claims list'!N8 -> 2500 | H4: ='claims list'!J8 -> 49463 | I4: ='claims list'!S8 -> 14901.8 | J4: ='claims list'!M8 -> 34561.2
E5: Meets Standard | F5: Leakage Value | G5: Brief Comment/Explanation
A6: Claim Investigation
A7: 1 | B7: Was the claim properly investigated to include taking recorded statements, obtaining prior medical reports, obtaining witness statements, verifying causation, etc.? | E7: N/A
A8: 2 | B8: Does the adjuster re-evaluate causation when new/additional body parts are added? | E8: N/A
A9: 3 | B9: Does the file reflect any evidence of any adjuster rapport tactics such benefit explanation to EE and/ or bi-weekly EE contact during lost time period? | E9: N/A
A10: 4 | B10: Does the adjuster properly address any lag times from the DOI to the date reported to the TPA/carrier? (Late report is defined as greater than 2 days to the time the employee reported the claim to the employer or TPA) | E10: N/A
A11: 5 | B11: Are recovery opportunities being realized (subrogation)? | E11: N/A
A12: Resolution Plans & Claim Follow Up
A13: 6 | B13: Do the action plans contain a specific and aggressive plan to bring the claim to closure? | E13: N/A
A14: 7 | B14: Does the action plan have completion due dates for any necessary follow up activities? | E14: N/A
A15: 8 | B15: Are the action plans executed in a timely manner that do not hinder the claim outcome? If not, indicate the Opportunity Cost | E15: N/A
A16: 9 | B16: Does the adjuster keep an appropriate diary? | E16: N/A
A17: Supervisor Direction & Special Handling
A18: 10 | B18: Are the supervisor reviews completed timely? | E18: N/A
A19: 11 | B19: Do the supervisor review address any missed opportunities for resoultion and provide clear direction/recommendations | E19: N/A
A20: 12 | B20: Does the adjustet take action and or respond to the Supervisor recommendations? | E20: N/A
A21: 13 | B21: Does the supervisor hold the adjuster accountable for moving claim to resolution? | E21: N/A
A22: 14 | B22: Does the Superisor update recommendations based on current file status at time of review (does not cut and paste) | E22: N/A
A23: Reserving
A24: 15 | B24: Are the current reserves appropriate to resolve the claim? | E24: N/A
A25: 16 | B25: Are the reserves adjusted timely in accordance with the claim developments? | E25: N/A
A26: Disability & Medical Management
A27: 17 | B27: Does the adjuster (or nurse) use ODG to manage RTW? | E27: N/A
A28: 18 | B28: Are the RTW target dates being communicated to all parties (i.e. EE, client contact, and treating physician)? | E28: N/A
A29: 19 | B29: Does the adjuster (or nurse) pro-actively address expired RTW target dates with the treating physician? If not, indicate leakage amount. | E29: N/A
A30: 20 | B30: Does the file reflect evidence of a non-accommodation RTW escalation process? | E30: N/A
A31: 21 | B31: Did the adjuster obtain the medical information on a timely basis? | E31: N/A
A32: 22 | B32: Is the adjuster pro-active in engaging ancillary resources and programs (TCM/NCM, IME, Pharmacy programs, etc.) | E32: N/A
A33: 23 | B33: If applicable, does the adjuster property manage the UR process to reduce medical delays and administrative denials? | E33: N/A
A34: 24 | B34: Is there a causal relationship between the current treatment plan and the accepted WC injury? | E34: N/A
A35: Settlement Disposition
A36: 25 | B36: Have early settlement opportunities been realized? If not, indicate amount of leakage. | E36: N/A
A37: 26 | B37: Has the adjuster completed his or her own evaluation and negotiations rather than defense counsel? | E37: N/A
A38: 27 | B38: Does the settlement evaluation include the future exposure, recommended settlement range, and planned negotiation plan? | E38: N/A
A39: 28 | B39: Upon receipt of settlement authority, has the adjuster/defense counsel made a reasonable offer of resolution within 2 business days? | E39: N/A
A40: 29 | B40: Did the adjuster extend a timed initial offer? | E40: N/A
A41: Litigation Management
...

Sheet claim 8
A1: EPIC Risk Consulting Quality Claim Assessment Tool
A3: Claimant: | B3: ='claims list'!B9 -> Zapata, Andree | D3: Jurisdiction: | E3: ='claims list'!I9 -> CA | F3: Date Reported | G3: Indemnity | H3: Incurred | I3: Paid | J3: Outstanding
A4: Claim #: | B4: ='claims list'!A9 -> 000531-067923-WC-01 | D4: Adjuster: | E4: ='claims list'!F9 -> Maria Barlow | F4: ='claims list'!D9 -> 43810 | G4: ='claims list'!N9 -> 4300 | H4: ='claims list'!J9 -> 49829 | I4: ='claims list'!S9 -> 11683.27 | J4: ='claims list'!M9 -> 38145.73
E5: Meets Standard | F5: Leakage Value | G5: Brief Comment/Explanation
A6: Claim Investigation
A7: 1 | B7: Was the claim properly investigated to include taking recorded statements, obtaining prior medical reports, obtaining witness statements, verifying causation, etc.? | E7: N/A
A8: 2 | B8: Does the adjuster re-evaluate causation when new/additional body parts are added? | E8: N/A
A9: 3 | B9: Does the file reflect any evidence of any adjuster rapport tactics such benefit explanation to EE and/ or bi-weekly EE contact during lost time period? | E9: N/A
A10: 4 | B10: Does the adjuster properly address any lag times from the DOI to the date reported to the TPA/carrier? (Late report is defined as greater than 2 days to the time the employee reported the claim to the employer or TPA) | E10: N/A
A11: 5 | B11: Are recovery opportunities being realized (subrogation)? | E11: N/A
A12: Resolution Plans & Claim Follow Up
A13: 6 | B13: Do the action plans contain a specific and aggressive plan to bring the claim to closure? | E13: N/A
A14: 7 | B14: Does the action plan have completion due dates for any necessary follow up activities? | E14: N/A
A15: 8 | B15: Are the action plans executed in a timely manner that do not hinder the claim outcome? If not, indicate the Opportunity Cost | E15: N/A
A16: 9 | B16: Does the adjuster keep an appropriate diary? | E16: N/A
A17: Supervisor Direction & Special Handling
A18: 10 | B18: Are the supervisor reviews completed timely? | E18: N/A
A19: 11 | B19: Do the supervisor review address any missed opportunities for resoultion and provide clear direction/recommendations | E19: N/A
A20: 12 | B20: Does the adjustet take action and or respond to the Supervisor recommendations? | E20: N/A
A21: 13 | B21: Does the supervisor hold the adjuster accountable for moving claim to resolution? | E21: N/A
A22: 14 | B22: Does the Superisor update recommendations based on current file status at time of review (does not cut and paste) | E22: N/A
A23: Reserving
A24: 15 | B24: Are the current reserves appropriate to resolve the claim? | E24: N/A
A25: 16 | B25: Are the reserves adjusted timely in accordance with the claim developments? | E25: N/A
A26: Disability & Medical Management
A27: 17 | B27: Does the adjuster (or nurse) use ODG to manage RTW? | E27: N/A
A28: 18 | B28: Are the RTW target dates being communicated to all parties (i.e. EE, client contact, and treating physician)? | E28: N/A
A29: 19 | B29: Does the adjuster (or nurse) pro-actively address expired RTW target dates with the treating physician? If not, indicate leakage amount. | E29: N/A
A30: 20 | B30: Does the file reflect evidence of a non-accommodation RTW escalation process? | E30: N/A
A31: 21 | B31: Did the adjuster obtain the medical information on a timely basis? | E31: N/A
A32: 22 | B32: Is the adjuster pro-active in engaging ancillary resources and programs (TCM/NCM, IME, Pharmacy programs, etc.) | E32: N/A
A33: 23 | B33: If applicable, does the adjuster property manage the UR process to reduce medical delays and administrative denials? | E33: N/A
A34: 24 | B34: Is there a causal relationship between the current treatment plan and the accepted WC injury? | E34: N/A
A35: Settlement Disposition
A36: 25 | B36: Have early settlement opportunities been realized? If not, indicate amount of leakage. | E36: N/A
A37: 26 | B37: Has the adjuster completed his or her own evaluation and negotiations rather than defense counsel? | E37: N/A
A38: 27 | B38: Does the settlement evaluation include the future exposure, recommended settlement range, and planned negotiation plan? | E38: N/A
A39: 28 | B39: Upon receipt of settlement authority, has the adjuster/defense counsel made a reasonable offer of resolution within 2 business days? | E39: N/A
A40: 29 | B40: Did the adjuster extend a timed initial offer? | E40: N/A
A41: Litigation Management
...

Sheet claim 9
A1: EPIC Risk Consulting Quality Claim Assessment Tool
A3: Claimant: | B3: ='claims list'!B10 -> Vega-Bravo, Lucina | D3: Jurisdiction: | E3: ='claims list'!I10 -> CA | F3: Date Reported | G3: Indemnity | H3: Incurred | I3: Paid | J3: Outstanding
A4: Claim #: | B4: ='claims list'!A10 -> 000531-066858-WC-01 | D4: Adjuster: | E4: ='claims list'!F10 -> Marta Eilers | F4: ='claims list'!D10 -> 43719 | G4: ='claims list'!N10 -> 24661 | H4: ='claims list'!J10 -> 162161 | I4: ='claims list'!S10 -> 80985.86 | J4: ='claims list'!M10 -> 81175.14
E5: Meets Standard | F5: Leakage Value | G5: Brief Comment/Explanation
A6: Claim Investigation
A7: 1 | B7: Was the claim properly investigated to include taking recorded statements, obtaining prior medical reports, obtaining witness statements, verifying causation, etc.? | E7: N/A
A8: 2 | B8: Does the adjuster re-evaluate causation when new/additional body parts are added? | E8: N/A
A9: 3 | B9: Does the file reflect any evidence of any adjuster rapport tactics such benefit explanation to EE and/ or bi-weekly EE contact during lost time period? | E9: N/A
A10: 4 | B10: Does the adjuster properly address any lag times from the DOI to the date reported to the TPA/carrier? (Late report is defined as greater than 2 days to the time the employee reported the claim to the employer or TPA) | E10: N/A
A11: 5 | B11: Are recovery opportunities being realized (subrogation)? | E11: N/A
A12: Resolution Plans & Claim Follow Up
A13: 6 | B13: Do the action plans contain a specific and aggressive plan to bring the claim to closure? | E13: N/A
A14: 7 | B14: Does the action plan have completion due dates for any necessary follow up activities? | E14: N/A
A15: 8 | B15: Are the action plans executed in a timely manner that do not hinder the claim outcome? If not, indicate the Opportunity Cost | E15: N/A
A16: 9 | B16: Does the adjuster keep an appropriate diary? | E16: N/A
A17: Supervisor Direction & Special Handling
A18: 10 | B18: Are the supervisor reviews completed timely? | E18: N/A
A19: 11 | B19: Do the supervisor review address any missed opportunities for resoultion and provide clear direction/recommendations | E19: N/A
A20: 12 | B20: Does the adjustet take action and or respond to the Supervisor recommendations? | E20: N/A
A21: 13 | B21: Does the supervisor hold the adjuster accountable for moving claim to resolution? | E21: N/A
A22: 14 | B22: Does the Superisor update recommendations based on current file status at time of review (does not cut and paste) | E22: N/A
A23: Reserving
A24: 15 | B24: Are the current reserves appropriate to resolve the claim? | E24: N/A
A25: 16 | B25: Are the reserves adjusted timely in accordance with the claim developments? | E25: N/A
A26: Disability & Medical Management
A27: 17 | B27: Does the adjuster (or nurse) use ODG to manage RTW? | E27: N/A
A28: 18 | B28: Are the RTW target dates being communicated to all parties (i.e. EE, client contact, and treating physician)? | E28: N/A
A29: 19 | B29: Does the adjuster (or nurse) pro-actively address expired RTW target dates with the treating physician? If not, indicate leakage amount. | E29: N/A
A30: 20 | B30: Does the file reflect evidence of a non-accommodation RTW escalation process? | E30: N/A
A31: 21 | B31: Did the adjuster obtain the medical information on a timely basis? | E31: N/A
A32: 22 | B32: Is the adjuster pro-active in engaging ancillary resources and programs (TCM/NCM, IME, Pharmacy programs, etc.) | E32: N/A
A33: 23 | B33: If applicable, does the adjuster property manage the UR process to reduce medical delays and administrative denials? | E33: N/A
A34: 24 | B34: Is there a causal relationship between the current treatment plan and the accepted WC injury? | E34: N/A
A35: Settlement Disposition
A36: 25 | B36: Have early settlement opportunities been realized? If not, indicate amount of leakage. | E36: N/A
A37: 26 | B37: Has the adjuster completed his or her own evaluation and negotiations rather than defense counsel? | E37: N/A
A38: 27 | B38: Does the settlement evaluation include the future exposure, recommended settlement range, and planned negotiation plan? | E38: N/A
A39: 28 | B39: Upon receipt of settlement authority, has the adjuster/defense counsel made a reasonable offer of resolution within 2 business days? | E39: N/A
A40: 29 | B40: Did the adjuster extend a timed initial offer? | E40: N/A
A41: Litigation Management
...

Sheet claim 10
A1: EPIC Risk Consulting Quality Claim Assessment Tool
A3: Claimant: | B3: ='claims list'!B11 -> Lehman, Allan | D3: Jurisdiction: | E3: ='claims list'!I11 -> FL | F3: Date Reported | G3: Indemnity | H3: Incurred | I3: Paid | J3: Outstanding
A4: Claim #: | B4: ='claims list'!A11 -> 000531-072994-WC-01 | D4: Adjuster: | E4: ='claims list'!F11 -> Jody Curtis | F4: ='claims list'!D11 -> 44258 | G4: ='claims list'!N11 -> 2156 | H4: ='claims list'!J11 -> 49447 | I4: ='claims list'!S11 -> 1115.61 | J4: ='claims list'!M11 -> 48331.39
E5: Meets Standard | F5: Leakage Value | G5: Brief Comment/Explanation
A6: Claim Investigation
A7: 1 | B7: Was the claim properly investigated to include taking recorded statements, obtaining prior medical reports, obtaining witness statements, verifying causation, etc.? | E7: N/A
A8: 2 | B8: Does the adjuster re-evaluate causation when new/additional body parts are added? | E8: N/A
A9: 3 | B9: Does the file reflect any evidence of any adjuster rapport tactics such benefit explanation to EE and/ or bi-weekly EE contact during lost time period? | E9: N/A
A10: 4 | B10: Does the adjuster properly address any lag times from the DOI to the date reported to the TPA/carrier? (Late report is defined as greater than 2 days to the time the employee reported the claim to the employer or TPA) | E10: N/A
A11: 5 | B11: Are recovery opportunities being realized (subrogation)? | E11: N/A
A12: Resolution Plans & Claim Follow Up
A13: 6 | B13: Do the action plans contain a specific and aggressive plan to bring the claim to closure? | E13: N/A
A14: 7 | B14: Does the action plan have completion due dates for any necessary follow up activities? | E14: N/A
A15: 8 | B15: Are the action plans executed in a timely manner that do not hinder the claim outcome? If not, indicate the Opportunity Cost | E15: N/A
A16: 9 | B16: Does the adjuster keep an appropriate diary? | E16: N/A
A17: Supervisor Direction & Special Handling
A18: 10 | B18: Are the supervisor reviews completed timely? | E18: N/A
A19: 11 | B19: Do the supervisor review address any missed opportunities for resoultion and provide clear direction/recommendations | E19: N/A
A20: 12 | B20: Does the adjustet take action and or respond to the Supervisor recommendations? | E20: N/A
A21: 13 | B21: Does the supervisor hold the adjuster accountable for moving claim to resolution? | E21: N/A
A22: 14 | B22: Does the Superisor update recommendations based on current file status at time of review (does not cut and paste) | E22: N/A
A23: Reserving
A24: 15 | B24: Are the current reserves appropriate to resolve the claim? | E24: N/A
A25: 16 | B25: Are the reserves adjusted timely in accordance with the claim developments? | E25: N/A
A26: Disability & Medical Management
A27: 17 | B27: Does the adjuster (or nurse) use ODG to manage RTW? | E27: N/A
A28: 18 | B28: Are the RTW target dates being communicated to all parties (i.e. EE, client contact, and treating physician)? | E28: N/A
A29: 19 | B29: Does the adjuster (or nurse) pro-actively address expired RTW target dates with the treating physician? If not, indicate leakage amount. | E29: N/A
A30: 20 | B30: Does the file reflect evidence of a non-accommodation RTW escalation process? | E30: N/A
A31: 21 | B31: Did the adjuster obtain the medical information on a timely basis? | E31: N/A
A32: 22 | B32: Is the adjuster pro-active in engaging ancillary resources and programs (TCM/NCM, IME, Pharmacy programs, etc.) | E32: N/A
A33: 23 | B33: If applicable, does the adjuster property manage the UR process to reduce medical delays and administrative denials? | E33: N/A
A34: 24 | B34: Is there a causal relationship between the current treatment plan and the accepted WC injury? | E34: N/A
A35: Settlement Disposition
A36: 25 | B36: Have early settlement opportunities been realized? If not, indicate amount of leakage. | E36: N/A
A37: 26 | B37: Has the adjuster completed his or her own evaluation and negotiations rather than defense counsel? | E37: N/A
A38: 27 | B38: Does the settlement evaluation include the future exposure, recommended settlement range, and planned negotiation plan? | E38: N/A
A39: 28 | B39: Upon receipt of settlement authority, has the adjuster/defense counsel made a reasonable offer of resolution within 2 business days? | E39: N/A
A40: 29 | B40: Did the adjuster extend a timed initial offer? | E40: N/A
A41: Litigation Management
...

Sheet claim 11
A1: EPIC Risk Consulting Quality Claim Assessment Tool
A3: Claimant: | B3: ='claims list'!B12 -> Carvajal, Roger | D3: Jurisdiction: | E3: ='claims list'!I12 -> FL | F3: Date Reported | G3: Indemnity | H3: Incurred | I3: Paid | J3: Outstanding
A4: Claim #: | B4: ='claims list'!A12 -> 000531-069395-WC-01 | D4: Adjuster: | E4: ='claims list'!F12 -> Jody Curtis | F4: ='claims list'!D12 -> 43959 | G4: ='claims list'!N12 -> 16239 | H4: ='claims list'!J12 -> 49878 | I4: ='claims list'!S12 -> 27729.17 | J4: ='claims list'!M12 -> 22148.83
E5: Meets Standard | F5: Leakage Value | G5: Brief Comment/Explanation
A6: Claim Investigation
A7: 1 | B7: Was the claim properly investigated to include taking recorded statements, obtaining prior medical reports, obtaining witness statements, verifying causation, etc.? | E7: N/A
A8: 2 | B8: Does the adjuster re-evaluate causation when new/additional body parts are added? | E8: N/A
A9: 3 | B9: Does the file reflect any evidence of any adjuster rapport tactics such benefit explanation to EE and/ or bi-weekly EE contact during lost time period? | E9: N/A
A10: 4 | B10: Does the adjuster properly address any lag times from the DOI to the date reported to the TPA/carrier? (Late report is defined as greater than 2 days to the time the employee reported the claim to the employer or TPA) | E10: N/A
A11: 5 | B11: Are recovery opportunities being realized (subrogation)? | E11: N/A
A12: Resolution Plans & Claim Follow Up
A13: 6 | B13: Do the action plans contain a specific and aggressive plan to bring the claim to closure? | E13: N/A
A14: 7 | B14: Does the action plan have completion due dates for any necessary follow up activities? | E14: N/A
A15: 8 | B15: Are the action plans executed in a timely manner that do not hinder the claim outcome? If not, indicate the Opportunity Cost | E15: N/A
A16: 9 | B16: Does the adjuster keep an appropriate diary? | E16: N/A
A17: Supervisor Direction & Special Handling
A18: 10 | B18: Are the supervisor reviews completed timely? | E18: N/A
A19: 11 | B19: Do the supervisor review address any missed opportunities for resoultion and provide clear direction/recommendations | E19: N/A
A20: 12 | B20: Does the adjustet take action and or respond to the Supervisor recommendations? | E20: N/A
A21: 13 | B21: Does the supervisor hold the adjuster accountable for moving claim to resolution? | E21: N/A
