Workbook

Sheet Cover & Assumptions
A1: P&C INSURANCE BROKERAGE — FINANCIAL MODEL v8
A2: Solo Founder | No Outside Capital | 5-Year (2026-2030) | Milestone-Based Staffing | 6 JVs | Tiered Exit | PE-Ready
A4: REVENUE ASSUMPTIONS
A5: Blended Commission Rate | B5: 12.0%
A6: Avg Annual Commission per Client (Blended) | B6: $18,000
A7: Avg Annual Premium per Client (Implied) | B7: $150,000
A9: DIRECT PRODUCTION — AARON
A10: Y1 New Commission Revenue | B10: $400,000
A11: New Production Annual Growth Rate (Y2+) | B11: 15% per year (1.15x)
A12: Organic Growth on Existing Book | B12: 7% per year
A13: Direct Client Churn Y1-Y2 / Y3-Y4 / Y5 | B13: 5% / 4% / 3%
A15: JV PARTNER NETWORK
A16: Y1 JV Partners (Full Year) | B16: 1
A17: Y1 — 2nd JV Partner (Late Q4 Join) | B17: 25% partial year revenue
A18: Y2 JV Partners | B18: 4
A19: Y3-Y5 JV Partners | B19: 6
A20: New Clients per JV Partner per Year | B20: 8 (Y1) → 15 (Y5)
A21: Aaron's Share of JV Revenue | B21: 80%
A22: JV Partner Commission (Producer Rate) | B22: 20% of gross book revenue
A23: JV Client Churn Rate | B23: 6.0%
A25: CONTINGENT INCOME
A26: Premium Threshold to Qualify | B26: $500,000 NWP
A27: Contingency Rate (Blended) | B27: 3.5% of Net Written Premium
A29: AARON'S COMPENSATION
A30: Y1 Salary | B30: $0 (reinvesting into growth)
A31: Y2-Y5 Annual Salary | B31: $185,000
A32: Admin Burden on Salary (Benefits + Taxes) | B32: 23% of base salary
A34: COLD CALLERS — DIRECT BOOK (MILESTONE-TRIGGERED)
A35: First 2 Callers Trigger | B35: When cumulative cash profit >= $80,000
A36: Additional Callers | B36: 1 per additional $80K cumulative cash profit
A37: Cost per Cold Caller (1099) | B37: $40,000/year
A39: RESOURCEPRO (OUTSOURCED SERVICE STAFF)
A40: First Hire Trigger | B40: 10 total clients
A41: Ongoing Ratio | B41: 1 person per 14 clients
A42: Cost per Head | B42: $40,000 (no admin burden — outsourced)
A44: ACCOUNT MANAGERS (W-2)
A45: First Hire Trigger | B45: 20 total clients
A46: Ongoing Ratio | B46: 1 AM per 20 clients
A47: Base Salary (Y1 Rate) | B47: $140,000
A48: Annual Salary Escalation | B48: 3% per year
...

Sheet P&L Summary (Annual)
A1: P&L SUMMARY — 5-YEAR ANNUAL (2026-2030)
A2: Aaron's Production + JV Network + Contingent Income | Milestone Staffing | Tiered Exit | PE-Ready v8
A3: Line Item | B3: Y1 2026 | C3: Y2 2027 | D3: Y3 2028 | E3: Y4 2029 | F3: Y5 2030 | G3: 5-Yr Total | H3: Notes
A4: REVENUE
A5: Direct Book — Aaron's Production | B5: 704357 | C5: 1527393 | D5: 2581022 | E5: 3824762 | F5: 5470087 | G5: 7751562.3 | H5: $400K Y1 new prod; 15% growth; 7% organic uplift on book
A6: JV Network — Aaron's 80% Share | B6: 241920 | C6: 1252087 | D6: 2936656 | E6: 4776314 | F6: 6940180 | G6: 9230400 | H6: 1 JV Y1 (+1 late Q4) → 4 Y2 → 6 Y3+
A7: Contingent Income (Carrier Profit Share) | B7: 293637 | C7: 883572 | D7: 1716192 | E7: 2637157 | F7: 3667303 | G7: 5626122.4 | H7: 3.5% of NWP; activates at $500K premium threshold
A8: TOTAL REVENUE | B8: 1239914 | C8: 3663052 | D8: 7233870 | E8: 11238233 | F8: 16077571 | G8: 22608085
A9: DIRECT BOOK COLD CALLERS (1099 — MILESTONE-TRIGGERED)
A10: Cold Caller Heads (Direct Book) | B10: ='Cash on Hand'!B20 -> 2 | C10: ='Cash on Hand'!C20 -> 2 | D10: ='Cash on Hand'!D20 -> 2 | E10: ='Cash on Hand'!E20 -> 2 | F10: ='Cash on Hand'!F20 -> 2 | G10: 2 | H10: Trigger: 2 callers at $80K cumulative cash profit
A11: TOTAL COLD CALLER COST | B11: ='Cash on Hand'!B22 -> 80000 | C11: ='Cash on Hand'!C22 -> 80000 | D11: ='Cash on Hand'!D22 -> 80000 | E11: ='Cash on Hand'!E22 -> 80000 | F11: ='Cash on Hand'!F22 -> 80000 | G11: =SUM(B11:F11) -> 400000 | H11: $40K/head — 1099, no admin burden
A12: STAFFING COSTS — MILESTONE-TRIGGERED
A13: Total Active Clients | B13: 31 | C13: 96 | D13: 192 | E13: 300 | F13: 414 | G13: 1033 | H13: RP trigger: 10 | AM trigger: 20
A14: Aaron's Base Salary | B14: 0 | C14: 185000 | D14: 185000 | E14: 185000 | F14: 185000 | G14: 740000 | H14: $0 Y1; $185K Y2+
A15: Aaron's Admin Burden (23%) | B15: 0 | C15: 42550 | D15: 42550 | E15: 42550 | F15: 42550 | G15: 170200
A16: Aaron's Total Loaded Comp | B16: 0 | C16: 227550 | D16: 227550 | E16: 227550 | F16: 227550 | G16: 910200
A17: ResourcePro Heads | B17: 3 | C17: 7 | D17: 14 | E17: 22 | F17: 30 | G17: 76 | H17: 0 until 10 clients; 1-per-14 after
A18: ResourcePro Cost | B18: 120000 | C18: 280000 | D18: 560000 | E18: 880000 | F18: 1200000 | G18: 3040000 | H18: $40K/head — outsourced, no admin burden
A19: Account Manager Heads | B19: 2 | C19: 5 | D19: 10 | E19: 15 | F19: 21 | G19: 53 | H19: 0 until 20 clients; 1-per-20 after
A20: AM Base Salary (3% annual escalation) | B20: 280000 | C20: 721000 | D20: 1485260 | E20: 2294726.7 | F20: 3308995.9 | G20: 8089982.6
A21: AM Admin Burden (23%) | B21: 64400 | C21: 165830 | D21: 341609.8 | E21: 527787.14 | F21: 761069.06 | G21: 1860696
A22: AM Total Loaded Cost | B22: 344400 | C22: 886830 | D22: 1826869.8 | E22: 2822513.8 | F22: 4070065 | G22: 9950678.6
A23: TOTAL STAFFING COSTS | B23: 464400 | C23: 1394380 | D23: 2614419.8 | E23: 3930063.8 | F23: 5497615 | G23: 13900879
A24: PREMIUM CLIENT SERVICE COSTS | B24: Year 1 | C24: Year 2 | D24: Year 3 | E24: Year 4 | F24: Year 5
A25: Service Cost (% of Revenue) | B25: 0.14 | C25: 0.16 | D25: 0.18 | E25: 0.19 | F25: 0.2
A26: Total Service Cost | B26: 173588 | C26: 586088 | D26: 1302097 | E26: 2135264 | F26: 3215514
A27: GROSS PROFIT | B27: 521926 | C27: 1602584 | D27: 3237354 | E27: 5092905 | F27: 7284442 | G27: 7627206.1
A28: Gross Margin % | B28: 0.4209 | C28: 0.4374 | D28: 0.4475 | E28: 0.4532 | F28: 0.4531 | G28: =G27/G8 -> 0.33736631
A29: FIXED OPERATING EXPENSES
A30: E&O Insurance | B30: 13000 | C30: 39000 | D30: 78000 | E30: 117000 | F30: 162500 | G30: 247000 | H30: $6,500 per $650K revenue band
A31: Agency Management System (Tech) | B31: 35000 | C31: 35000 | D31: 35000 | E31: 35000 | F31: 35000 | G31: 175000 | H31: $35K/yr — activates at 10 total clients
A32: Marketing & Business Development | B32: 5000 | C32: 8000 | D32: 12000 | E32: 15000 | F32: 18000 | G32: 58000
A33: Professional Services | B33: 3000 | C33: 4000 | D33: 5000 | E33: 6000 | F33: 6000 | G33: 24000
A34: Misc / Admin | B34: 2400 | C34: 2400 | D34: 3000 | E34: 3600 | F34: 3600 | G34: 15000
A35: TOTAL FIXED OPEX | B35: 58400 | C35: 88400 | D35: 133000 | E35: 176600 | F35: 225100 | G35: =SUM(G30:G34) -> 519000
A36: PROFITABILITY
A37: EBITDA | B37: 463526 | C37: 1514184 | D37: 3104354 | E37: 4916305 | F37: 7059342 | G37: 7788206.1
A38: EBITDA Margin % | B38: 0.3738 | C38: 0.4134 | D38: 0.4291 | E38: 0.4375 | F38: 0.4391 | G38: 0.344571
A39: Tax Provision (25%) | B39: 115881.5 | C39: 378546 | D39: 776088.5 | E39: 1229076.2 | F39: 1764835.5 | G39: 1947051.5
A40: NET INCOME | B40: 347644.5 | C40: 1135638 | D40: 2328265.5 | E40: 3687228.8 | F40: 5294506.5 | G40: 5841154.6
...

Sheet Cash on Hand
A1: CASH ON HAND — OWNER COMPENSATION & RETAINED CAPITAL
A2: Aaron's salary expensed in P&L | Retained cash reinvested for growth | JV revenue accelerates expansion
A3: Line Item | B3: Y1 2026 | C3: Y2 2027 | D3: Y3 2028 | E3: Y4 2029 | F3: Y5 2030 | G3: 5-Yr Total | H3: Notes
A4: INCOME SOURCES
A5: Total Revenue | B5: 1239914 | C5: 3663052 | D5: 7233870 | E5: 11238233 | F5: 16077571 | G5: 22608085
A6: Direct Book Revenue (Aaron's Production) | B6: 704357 | C6: 1527393 | D6: 2581022 | E6: 3824762 | F6: 5470087 | G6: 7751562.3 | H6: Primary growth engine
A7: JV Network Revenue (Aaron's 80%) | B7: 241920 | C7: 1252087 | D7: 2936656 | E7: 4776314 | F7: 6940180 | G7: 9230400 | H7: Accelerates growth without additional direct effort
A8: Contingent Income | B8: 293637 | C8: 883572 | D8: 1716192 | E8: 2637157 | F8: 3667303 | G8: 5626122.4
A9: AARON'S COMPENSATION (EXPENSED IN P&L)
A10: Aaron's Base Salary | B10: 0 | C10: 185000 | D10: 185000 | E10: 185000 | F10: 185000 | G10: 740000 | H10: $0 Y1 — reinvesting; $185K Y2+
A11: Admin Burden (23%) | B11: 0 | C11: 42550 | D11: 42550 | E11: 42550 | F11: 42550 | G11: 170200
A12: TOTAL OWNER COMPENSATION (LOADED) | B12: 0 | C12: 227550 | D12: 227550 | E12: 227550 | F12: 227550 | G12: 910200 | H12: Already deducted in EBITDA — shown here for clarity
A13: BUSINESS PROFITABILITY & RETAINED CASH
A14: EBITDA | B14: 463526 | C14: 1514184 | D14: 3104354 | E14: 4916305 | F14: 7059342 | G14: 7788206.1
A15: EBITDA Margin % | B15: 0.3738 | C15: 0.4134 | D15: 0.4291 | E15: 0.4375 | F15: 0.4391 | G15: 0.344571
A16: Tax Provision (25%) | B16: 115882 | C16: 378546 | D16: 776089 | E16: 1229076 | F16: 1764836 | G16: 1947051.5
A17: NET INCOME (Annual) | B17: 347645 | C17: 1135638 | D17: 2328266 | E17: 3687229 | F17: 5294506 | G17: 5841154.6
A18: CUMULATIVE RETAINED CASH (Year-End Balance) | B18: 347645 | C18: 1483283 | D18: 3811548 | E18: 7498777 | F18: 12793283 | G18: 5841154.6 | H18: War chest for hiring, growth, and operations
A19: COLD CALLER INVESTMENT (FUNDED FROM RETAINED CASH)
A20: Cold Caller Heads Hired | B20: 2 | C20: 2 | D20: 2 | E20: 2 | F20: 2 | G20: 2 | H20: Trigger: 2 callers when cumulative cash >= $80K
A21: Cold Caller Annual Cost | B21: 40000 | C21: 40000 | D21: 40000 | E21: 40000 | F21: 40000 | G21: =SUM(B21:F21) -> 200000 | H21: $40K/head — funded from retained cash
A22: Cumulative Cold Caller Investment | B22: =B20*B21 -> 80000 | C22: =C20*C21 -> 80000 | D22: =D20*D21 -> 80000 | E22: =E20*E21 -> 80000 | F22: =F20*F21 -> 80000 | G22: =SUM(B22:F22) -> 400000
A23: JV REVENUE AS GROWTH ACCELERATOR
A24: JV Network Revenue (Aaron's 80%) | B24: 241920 | C24: 1252087 | D24: 2936656 | E24: 4776314 | F24: 6940180 | G24: 9230400
A25: JV Revenue as % of Total Revenue | B25: 0.1951 | C25: 0.3418 | D25: 0.406 | E25: 0.425 | F25: 0.4317 | G25: 0.35777198 | H25: JV channel grows faster than direct book over time
A26: Cumulative JV Revenue Earned | B26: 241920 | C26: 1494007 | D26: 4430663 | E26: 9206977 | F26: 16147157 | G26: 18043200 | H26: JV income funds expansion without dilution
A27: PLAIN ENGLISH CASH SUMMARY
A28: Y1 2026: Aaron earns $0 salary. Business nets $347,644 after tax. Cumulative cash in business: $347,644. Cold callers on payroll: 2.
A29: Y2 2027: Aaron earns $185,000 salary. Business nets $1,135,638 after tax. Cumulative cash in business: $1,483,282. Cold callers on payroll: 2.
A30: Y3 2028: Aaron earns $185,000 salary. Business nets $2,328,266 after tax. Cumulative cash in business: $3,811,548. Cold callers on payroll: 2.
A31: Y4 2029: Aaron earns $185,000 salary. Business nets $3,687,229 after tax. Cumulative cash in business: $7,498,777. Cold callers on payroll: 2.
A32: Y5 2030: Aaron earns $185,000 salary. Business nets $5,294,507 after tax. Cumulative cash in business: $12,793,283. Cold callers on payroll: 2.

Sheet Key Metrics (PE Dashboard)
A1: KEY METRICS — INVESTOR DASHBOARD
A2: CAC | LTV | LTV:CAC | Payback Period | Net Revenue Retention | EBITDA Margin | Exit Multiple
A3: Line Item | B3: Y1 2026 | C3: Y2 2027 | D3: Y3 2028 | E3: Y4 2029 | F3: Y5 2030 | G3: 5-Yr Total | H3: Notes
A4: UNIT ECONOMICS
A5: Avg Annual Commission per Client | B5: 30240 | C5: 30870 | D5: 32130 | E5: 32760 | F5: 34020 | G5: 90000 | H5: Blended across all P&C lines at 12% commission rate
A6: Avg Client Tenure (Years) | B6: 7 | C6: 7 | D6: 7 | E6: 7 | F6: 7 | G6: 35 | H6: Industry avg for commercial P&C brokerage
A7: Client Lifetime Value (LTV) | B7: 211680 | C7: 216090 | D7: 224910 | E7: 229320 | F7: 238140 | G7: 630000 | H7: Avg commission x avg tenure = $126K per client
A8: CUSTOMER ACQUISITION COST (CAC)
A9: Cold Caller Cost (Direct Book) | B9: 80000 | C9: 80000 | D9: 80000 | E9: 80000 | F9: 80000 | G9: 400000 | H9: Milestone-triggered; $40K/head
A10: New Direct Clients Added | B10: 22 | C10: 26 | D10: 29 | E10: 34 | F10: 39 | G10: 150
A11: CAC — Direct Book (Cost / New Client) | B11: 3636.36 | C11: 3076.92 | D11: 2758.62 | E11: 2352.94 | F11: 2051.28 | G11: 14875.931 | H11: $0 in Y1 (no callers yet); improves as callers scale
A12: LTV:CAC & PAYBACK PERIOD
A13: LTV:CAC Ratio | B13: 58.2 | C13: 70.2 | D13: 81.5 | E13: 97.5 | F13: 116.1 | G13: 47.25 | H13: PE benchmark: >3x is good; >5x is excellent
A14: Payback Period (Months) | B14: 1.4 | C14: 1.2 | D14: 1 | E14: 0.9 | F14: 0.7 | G14: 1.8501508 | H14: Months to recoup CAC from monthly commission; <18 months is strong
A15: REVENUE RETENTION & GROWTH
A16: Net Revenue Retention — Direct Book | B16: 1 | C16: 2.954 | D16: 1.975 | E16: 1.554 | F16: 1.431 | G16: 1.5156763 | H16: >100% = book growing organically even without new clients
A17: Direct Book Churn Rate | B17: 0 | C17: 0 | D17: 0 | E17: 0 | F17: 0 | G17: 0.042 | H17: Conservative vs. industry avg of 8-12%
A18: Total Active Clients (Direct + JV) | B18: 31 | C18: 96 | D18: 192 | E18: 300 | F18: 414 | G18: 1033
A19: Year-over-Year Revenue Growth | B19: 0 | C19: 1.954 | D19: 0.975 | E19: 0.554 | F19: 0.431 | G19: 0.75699453
A20: PROFITABILITY METRICS
A21: EBITDA | B21: 463526 | C21: 1514184 | D21: 3104354 | E21: 4916305 | F21: 7059342 | G21: 7108206.1
A22: EBITDA Margin % | B22: 0.3738 | C22: 0.4134 | D22: 0.4291 | E22: 0.4375 | F22: 0.4391 | G22: 0.2591177
A23: Net Income | B23: 347644.5 | C23: 1135638 | D23: 2328265.5 | E23: 3687228.8 | F23: 5294506.5 | G23: 5331154.6
A24: Net Margin % | B24: 0.2804 | C24: 0.31 | D24: 0.3219 | E24: 0.3281 | F24: 0.3294 | G24: 0.19433828
A25: Cumulative Retained Cash | B25: 347644.5 | C25: 1483282.5 | D25: 3811548 | E25: 7498776.8 | F25: 12793283 | G25: 9967184.1
A26: EXIT METRICS
A27: Exit Multiple Applied (Base) | B27: 5 | C27: 9 | D27: 11.5 | E27: 11.5 | F27: 15 | G27: 39.5 | H27: Tiered by EBITDA size — industry best practice
A28: Exit Tier | B28: 0 | C28: 0 | D28: 0 | E28: 0 | F28: 0 | G28: 0 | H28: Y1 2026: Sub-Scale (<$500K EBITDA) | Y2 2027: Sub-Scale (<$500K EBITDA) | Y3 2028: Mid-Market ($1M-$3M EBITDA) | Y4 2029: Mid-Market ($1M-$3M EBITDA) | Y5 2030: Strong Mid-Market ($3M-$7M EBITDA)
A29: Exit Value — Low | B29: 1854105 | C29: 12113471 | D29: 31043540 | E29: 49163049 | F29: 91771440 | G29: 61333437
A30: EXIT VALUE — BASE | B30: 2317631 | C30: 13627655 | D30: 35700071 | E30: 56537506 | F30: 105890123 | G30: 70037623
A31: Exit Value — High | B31: 2781157 | C31: 15141839 | D31: 40356602 | E31: 63911963 | F31: 120008806 | G31: 78741810

Sheet Revenue Detail
A1: REVENUE DETAIL — CLIENT COUNTS, PREMIUM & CHANNEL BREAKDOWN
A3: Line Item | B3: Y1 2026 | C3: Y2 2027 | D3: Y3 2028 | E3: Y4 2029 | F3: Y5 2030 | G3: 5-Yr Total | H3: Notes
A4: DIRECT BOOK — AARON'S PRODUCTION
A5: New Commission Revenue (Production) | B5: 672000 | C5: 788900 | D5: 944265 | E5: 1107197 | F5: 1322249 | G5: 2696952.5 | H5: $400K Y1; 15% growth Y2+
A6: New Clients Added | B6: 22 | C6: 26 | D6: 29 | E6: 34 | F6: 39 | G6: 150
A7: Organic Growth Revenue (7% on existing book) | B7: 2117 | C7: 19462 | D7: 47021 | E7: 85934 | F7: 175971 | G7: 179273.54 | H7: Existing clients renewing at higher premiums
A8: Active Clients (End of Year) | B8: 23 | C8: 48 | D8: 75 | E8: 106 | F8: 142 | G8: 394
A9: Direct Book Total Revenue | B9: 704357 | C9: 1527393 | D9: 2581022 | E9: 3824762 | F9: 5470087 | G9: 7751562.3
A10: Implied Net Written Premium (Direct) | B10: 5869640 | C10: 12468515 | D10: 20243311 | E10: 29421243 | F10: 40519165 | G10: 64596353
A11: JV PARTNER NETWORK (Aaron 80% / Partner 20%)
A12: Full-Year JV Partners Active | B12: 1 | C12: 4 | D12: 6 | E12: 6 | F12: 6 | G12: 23 | H12: Y1: 1 full + 1 late Q4 partial
A13: Total JV Active Clients | B13: 8 | C13: 48 | D13: 117 | E13: 194 | F13: 272 | G13: 639
A14: JV Network Gross Revenue (100%) | B14: 302400 | C14: 1565109 | D14: 3670820 | E14: 5970393 | F14: 8675225 | G14: 11538000
A15: JV Partner Commissions Paid (20%) | B15: 60480 | C15: 313022 | D15: 734164 | E15: 1194079 | F15: 1735045 | G15: 2307600
A16: Aaron's JV Revenue (80%) | B16: 241920 | C16: 1252087 | D16: 2936656 | E16: 4776314 | F16: 6940180 | G16: 9230400
A17: CONTINGENT INCOME
A18: Total Net Written Premium | B18: 8389640 | C18: 25244915 | D18: 49034059 | E18: 75347343 | F18: 104780092 | G18: 1.6074635e+08 | H18: Threshold: $500K to qualify
A19: Contingent Income Earned | B19: 293637 | C19: 883572 | D19: 1716192 | E19: 2637157 | F19: 3667303 | G19: 5626122.4 | H19: 3.5% of NWP when threshold met
A20: TOTAL REVENUE SUMMARY
A21: Direct Book Revenue | B21: 704357 | C21: 1527393 | D21: 2581022 | E21: 3824762 | F21: 5470087 | G21: 7751562.3
A22: JV Network Revenue (Aaron 80%) | B22: 241920 | C22: 1252087 | D22: 2936656 | E22: 4776314 | F22: 6940180 | G22: 9230400
A23: Contingent Income | B23: 293637 | C23: 883572 | D23: 1716192 | E23: 2637157 | F23: 3667303 | G23: 5626122.4
A24: TOTAL REVENUE | B24: 1239914 | C24: 3663052 | D24: 7233870 | E24: 11238233 | F24: 16077571 | G24: 22608085

Sheet JV Partner Illustration
A1: JV PARTNER ILLUSTRATION — REVENUE SHARE OVERVIEW
A2: Aaron earns 80% | Partner earns 20% producer commission | Y1: 1 JV full year + 1 late Q4 join
A3: Line Item | B3: Y1 2026 | C3: Y2 2027 | D3: Y3 2028 | E3: Y4 2029 | F3: Y5 2030 | G3: 5-Yr Total | H3: Notes
A4: AVERAGE PER-PARTNER ECONOMICS
A5: Active JV Partners (Full Year) | B5: 1 | C5: 4 | D5: 6 | E5: 6 | F5: 6 | G5: 23
A6: Avg Active Clients per Partner | B6: 8 | C6: 12 | D6: 20 | E6: 32 | F6: 45 | G6: 117
A7: Avg Gross Revenue per Partner (100%) | B7: 302400 | C7: 391277 | D7: 611803 | E7: 995066 | F7: 1445871 | G7: 2109000
A8: Avg Partner Commission (20%) | B8: 60480 | C8: 78255 | D8: 122361 | E8: 199013 | F8: 289174 | G8: 421800 | H8: Paid as 1099 producer commission
A9: Avg Aaron's Earnings per Partner (80%) | B9: 241920 | C9: 313022 | D9: 489443 | E9: 796052 | F9: 1156697 | G9: 1687200
A10: FULL JV NETWORK — COMBINED VIEW
A11: Total JV Active Clients | B11: 8 | C11: 48 | D11: 117 | E11: 194 | F11: 272 | G11: 639
A12: JV Network Gross Revenue (100%) | B12: 302400 | C12: 1565109 | D12: 3670820 | E12: 5970393 | F12: 8675225 | G12: 11538000
A13: Total Partner Commissions Paid (20%) | B13: 60480 | C13: 313022 | D13: 734164 | E13: 1194079 | F13: 1735045 | G13: 2307600
A14: Aaron's Total JV Revenue (80%) | B14: 241920 | C14: 1252087 | D14: 2936656 | E14: 4776314 | F14: 6940180 | G14: 9230400
A15: CUMULATIVE EARNINGS
A16: JV Partner Cumulative Commissions (20%) | B16: 60480 | C16: 373502 | D16: 1107666 | E16: 2301744 | F16: 4036790 | G16: 923400
A17: Aaron's Cumulative JV Earnings (80%) | B17: 241920 | C17: 1494007 | D17: 4430663 | E17: 9206978 | F17: 16147158 | G17: 18043200

Sheet JV Compensation & Exit
A1: JV PARTNER COMPENSATION & EXIT ILLUSTRATION
A2: No investment required. Refer your book. Earn 20% commission every year. Get paid on the exit.
A3: Line Item | B3: Y1 2026 | C3: Y2 2027 | D3: Y3 2028 | E3: Y4 2029 | F3: Y5 2030 | G3: 5-Yr Total | H3: Notes
A4: HOW IT WORKS — JV PARTNER ECONOMICS
A5: Active JV Partners (Full Year) | B5: 1 | C5: 4 | D5: 6 | E5: 6 | F5: 6 | G5: 23 | H5: Your book = 1 equal share of the JV network
A6: Avg Active Clients per Partner | B6: 8 | C6: 12 | D6: 20 | E6: 32 | F6: 45 | G6: 117
A7: Avg Gross Revenue — Your Book (100%) | B7: 302400 | C7: 391277 | D7: 611803 | E7: 995066 | F7: 1445871 | G7: 2145000 | H7: Total commission value of your referred clients
A8: ANNUAL COMMISSION INCOME (20% PRODUCER RATE — 1099)
A9: Annual Commission — Pre-Tax (20%) | B9: 60480 | C9: 78255 | D9: 122361 | E9: 199013 | F9: 289174 | G9: 429000 | H9: Straight producer commission — paid as 1099
A10: Est. After-Tax (~32% effective rate) | B10: 41126 | C10: 53214 | D10: 83205 | E10: 135329 | F10: 196638 | G10: 291720 | H10: Estimate only — consult your tax advisor
A11: Cumulative Commissions Earned — Pre-Tax | B11: 60480 | C11: 138735 | D11: 261096 | E11: 460109 | F11: 749283 | G11: 959400 | H11: Running total of income pocketed to date
A12: Cumulative Commissions — Est. After-Tax | B12: 41126 | C12: 94340 | D12: 177545 | E12: 312874 | F12: 509513 | G12: 652392
A13: EXIT PAYOUT — YOUR SLICE OF THE BOOK SALE (POINT-IN-TIME)
A14: Your Book as % of Total Brokerage Revenue | B14: 0.243888 | C14: 0.106817 | D14: 0.084575 | E14: 0.088543 | F14: 0.089931 | G14: 0.12206201 | H14: Proportional ownership — based on your book's share of total revenue
A15: Total Brokerage Exit Value — Low | B15: 1854105 | C15: 12113471 | D15: 31043540 | E15: 49163049 | F15: 91771440 | G15: 67381015
A16: Total Brokerage Exit Value — Base | B16: 2317631 | C16: 13627655 | D16: 35700071 | E16: 56537506 | F16: 105890123 | G16: 76845201
A17: Total Brokerage Exit Value — High | B17: 2781157 | C17: 15141839 | D17: 40356602 | E17: 63911963 | F17: 120008806 | G17: 86309387
A18: YOUR EXIT PAYOUT — Low (if sold this year) | B18: 452194 | C18: 1293928 | D18: 2625502 | E18: 4353038 | F18: 8253091 | G18: 6106048.6 | H18: Point-in-time — what you receive if Aaron sells in that year
A19: YOUR EXIT PAYOUT — Base (if sold this year) | B19: 565242 | C19: 1455669 | D19: 3019328 | E19: 5005994 | F19: 9522797 | G19: 6975105 | H19: Pre-tax. Your % of book x exit value. One-time event.
A20: YOUR EXIT PAYOUT — High (if sold this year) | B20: 678290 | C20: 1617410 | D20: 3413153 | E20: 5658949 | F20: 10792503 | G20: 7844161.4
A21: Est. After-Tax Exit Payout (Base, ~32%) | B21: 384365 | C21: 989855 | D21: 2053143 | E21: 3404076 | F21: 6475502 | G21: 4743471.4 | H21: Estimate only — consult your tax advisor
A22: TOTAL WEALTH CREATED — IF AARON SELLS IN THAT YEAR
A23: Cumulative Commissions Earned to Date (Pre-Tax) | B23: 60480 | C23: 138735 | D23: 261096 | E23: 460109 | F23: 749283 | G23: 959400 | H23: All commissions earned from Y1 through that year
A24: Exit Payout in That Year — Low | B24: 452194 | C24: 1293928 | D24: 2625502 | E24: 4353038 | F24: 8253091 | G24: 6106048.6
A25: TOTAL WEALTH — Low (Commissions + Exit) | B25: 512674 | C25: 1432663 | D25: 2886598 | E25: 4813147 | F25: 9002374 | G25: 7065448.6
A26: TOTAL WEALTH — Base (Commissions + Exit) | B26: 625722 | C26: 1594404 | D26: 3280424 | E26: 5466103 | F26: 10272081 | G26: 7275966.9 | H26: Cumulative commissions + one-time exit check
A27: TOTAL WEALTH — High (Commissions + Exit) | B27: 738770 | C27: 1756145 | D27: 3674249 | E27: 6119058 | F27: 11541787 | G27: 8069453.3
A28: WHAT THIS MEANS IN PLAIN ENGLISH
A29: Y1 2026: You have earned $60,480 in commissions (pre-tax). If Aaron sells this year, your exit check is ~$565,242 (base case). Total in your pocket: ~$625,722 pre-tax.
A30: Y5 2030: You have earned $749,283 in cumulative commissions (pre-tax). If Aaron sells in Year 5, your exit check is ~$9,522,797 (base case). Total wealth created: ~$10,272,081 pre-tax.
A31: Y3 2028: You have earned $149,400 in commissions (pre-tax). If Aaron sells this year, your exit check is ~$918,736 (base case). Total in your pocket: ~$1,068,136 pre-tax.
A32: Y4 2029: You have earned $265,800 in commissions (pre-tax). If Aaron sells this year, your exit check is ~$1,786,029 (base case). Total in your pocket: ~$2,051,829 pre-tax.
A33: Y5 2030: You have earned $429,000 in commissions (pre-tax). If Aaron sells this year, your exit check is ~$3,297,675 (base case). Total in your pocket: ~$3,726,675 pre-tax.

Sheet Exit Valuation (Tiered)
A1: EXIT VALUATION — TIERED EBITDA MULTIPLES (INDUSTRY BEST PRACTICE)
A2: Multiple scales with EBITDA size | Sub-scale 4-6x | Mid-Market 8-10x | Platform $7M+ = 13-17x
A3: Line Item | B3: Y1 2026 | C3: Y2 2027 | D3: Y3 2028 | E3: Y4 2029 | F3: Y5 2030 | G3: 5-Yr Total | H3: Notes
A4: EBITDA & TIERED EXIT VALUE BY YEAR
A5: Total Revenue | B5: 1239914 | C5: 3663052 | D5: 7233870 | E5: 11238233 | F5: 16077571 | G5: 22608085
A6: Total All-In Costs | B6: 776388 | C6: 2148868 | D6: 4129516 | E6: 6321928 | F6: 9018229 | G6: 14819879
A7: EBITDA | B7: 463526 | C7: 1514184 | D7: 3104354 | E7: 4916305 | F7: 7059342 | G7: 7788206.1
A8: EBITDA Margin % | B8: 0.3738 | C8: 0.4134 | D8: 0.4291 | E8: 0.4375 | F8: 0.4391 | G8: 0.344571
A9: Exit Tier Applied | B9: 4 | C9: 8 | D9: 10 | E9: 10 | F9: 13 | G9: 0 | H9: Y1 2026: Sub-Scale (<$500K EBITDA) | Y2 2027: Sub-Scale (<$500K EBITDA) | Y3 2028: Mid-Market ($1M-$3M EBITDA) | Y4 2029: Mid-Market ($1M-$3M EBITDA) | Y5 2030: Strong Mid-Market ($3M-$7M EBITDA)
A10: Exit Multiple — Low | B10: 5 | C10: 9 | D10: 11.5 | E10: 11.5 | F10: 15 | G10: 34
A11: Exit Multiple — Mid (Base Case) | B11: 6 | C11: 10 | D11: 13 | E11: 13 | F11: 17 | G11: 39.5
A12: Exit Multiple — High | B12: 1854105 | C12: 12113471 | D12: 31043540 | E12: 49163049 | F12: 91771440 | G12: 45
A13: Exit Value — Low | B13: 2317631 | C13: 13627655 | D13: 35700071 | E13: 56537506 | F13: 105890123 | G13: 67381015
A14: EXIT VALUE — BASE (MIDPOINT) | B14: 2781157 | C14: 15141839 | D14: 40356602 | E14: 63911963 | F14: 120008806 | G14: 76845201 | H14: Pre-tax gross proceeds — point-in-time if sold in that year
A15: Exit Value — High | B15: 347645 | C15: 1483283 | D15: 3811548 | E15: 7498777 | F15: 12793283 | G15: 86309387
A16: Cumulative Net Income to Date | B16: 2665276 | C16: 15110938 | D16: 39511619 | E16: 64036283 | F16: 118683406 | G16: 5841154.6
A17: TOTAL WEALTH CREATED — Base (Exit + Retained Cash) | B17: 777653.96 | C17: 4726973.5 | D17: 13397221 | E17: 22606535 | F17: 40128377 | G17: 82686356
A18: EXIT TIER REFERENCE TABLE
A19: Sub-Scale (<$500K EBITDA) | B19: 4 | C19: 6 | D19: 6 | E19: 0 | F19: 0 | G19: 15 | H19: EBITDA <$0.5M → 4x / 5x / 6x (Low / Mid / High)
A20: Emerging ($500K-$1M EBITDA) | B20: 6 | C20: 7 | D20: 8 | E20: 0 | F20: 0 | G20: 21 | H20: EBITDA <$1.0M → 6x / 7x / 8x (Low / Mid / High)
A21: Mid-Market ($1M-$3M EBITDA) | B21: 8 | C21: 8 | D21: 10 | E21: 0 | F21: 0 | G21: 27 | H21: EBITDA <$3.0M → 8x / 9x / 10x (Low / Mid / High)
A22: Strong Mid-Market ($3M-$7M EBITDA) | B22: 10 | C22: 9 | D22: 13 | E22: 0 | F22: 0 | G22: 34.5 | H22: EBITDA <$7.0M → 10x / 11.5x / 13x (Low / Mid / High)
A23: Platform-Level ($7M+ EBITDA) | B23: 13 | C23: 11.5 | D23: 17 | E23: 0 | F23: 0 | G23: 45 | H23: EBITDA $7M+ → 13x / 15x / 17x (Low / Mid / High)

Sheet Scenario Analysis
A1: SCENARIO ANALYSIS — CONSERVATIVE / BASE / UPSIDE
A2: Revenue and EBITDA stress-tested at 70% (Conservative), 100% (Base), 130% (Upside)
A3: Line Item | B3: Y1 2026 | C3: Y2 2027 | D3: Y3 2028 | E3: Y4 2029 | F3: Y5 2030 | G3: 5-Yr Total | H3: Notes
A4: SCENARIO: CONSERVATIVE (70%)
A5: Total Revenue | B5: 867940 | C5: 2564137 | D5: 5063709 | E5: 7866763 | F5: 11254299 | G5: 6124438.3
A6: EBITDA | B6: 324468 | C6: 1059929 | D6: 2173048 | E6: 3441413 | F6: 4941539 | G6: 2108787.9
A7: EBITDA Margin % | B7: 0.3738 | C7: 0.4134 | D7: 0.4291 | E7: 0.4375 | F7: 0.4391 | G7: 0.344944
A8: Net Income (est.) | B8: 243351 | C8: 794947 | D8: 1629786 | E8: 2581060 | F8: 3706155 | G8: 1581590.9
A9: Exit Value — Low | B9: 1297870 | C9: 8479433 | D9: 21730480 | E9: 34414133 | F9: 64240012 | G9: 8
A10: Exit Value — Base | B10: 1622338 | C10: 9539236 | D10: 24990052 | E10: 39576252 | F10: 74123089 | G10: 10
A11: Exit Value — High | B11: 1946805 | C11: 10599290 | D11: 28249624 | E11: 44738371 | F11: 84006166 | G11: 13
A13: SCENARIO: BASE CASE (100%)
A14: Total Revenue | B14: 1239914 | C14: 3663052 | D14: 7233870 | E14: 11238233 | F14: 16077571 | G14: 8749197.6
A15: EBITDA | B15: 463526 | C15: 1514184 | D15: 3104354 | E15: 4916305 | F15: 7059342 | G15: 3017982.7
A16: EBITDA Margin % | B16: 0.3738 | C16: 0.4134 | D16: 0.4291 | E16: 0.4375 | F16: 0.4391 | G16: 0.344944
A17: Net Income (est.) | B17: 347645 | C17: 1135638 | D17: 2328266 | E17: 3687229 | F17: 5294506 | G17: 2263487
A18: Exit Value — Low | B18: 1854105 | C18: 12113471 | D18: 31043540 | E18: 49163049 | F18: 91771440 | G18: 10
A19: Exit Value — Base | B19: 2317631 | C19: 13627655 | D19: 35700071 | E19: 56537506 | F19: 105890123 | G19: 11.5
A20: Exit Value — High | B20: 2781157 | C20: 15141839 | D20: 40356602 | E20: 63911963 | F20: 120008806 | G20: 13
A22: SCENARIO: UPSIDE (130%)
A23: Total Revenue | B23: 1611888 | C23: 4761968 | D23: 9404032 | E23: 14609703 | F23: 20900842 | G23: 11373957
A24: EBITDA | B24: 602584 | C24: 1968439 | D24: 4035660 | E24: 6391196 | F24: 9177144 | G24: 3927177.5
A25: EBITDA Margin % | B25: 0.3738 | C25: 0.4134 | D25: 0.4291 | E25: 0.4375 | F25: 0.4391 | G25: 0.344944
A26: Net Income (est.) | B26: 451938 | C26: 1476329 | D26: 3026745 | E26: 4793397 | F26: 6882858 | G26: 2945383.1
A27: Exit Value — Low | B27: 2410338 | C27: 15747515 | D27: 40356602 | E27: 63911963 | F27: 119302878 | G27: 87595310
A28: Exit Value — Base | B28: 3012922 | C28: 17717952 | D28: 46410093 | E28: 73498758 | F28: 137657160 | G28: 1.0089876e+08
A29: Exit Value — High | B29: 3615507 | C29: 19688390 | D29: 52463583 | E29: 83085553 | F29: 156011447 | G29: 1.1420221e+08
A31: SCENARIO COMPARISON — Y5 SUMMARY
A32: Metric | B32: Conservative | C32: Base Case | D32: Upside | E32: Notes
A33: Y5 Revenue | B33: 11254300 | C33: 16077571 | D33: 20900842
A34: Y5 EBITDA | B34: 4941539 | C34: 7059342 | D34: 9177145
A35: Y5 EBITDA Margin | B35: 0.4391 | C35: 0.4391 | D35: 0.4391
A36: Y5 Exit Value (Base Multiple) | B36: 56827703 | C36: 105890131 | D36: 137657169
G37: 8749197.6
G38: 3017982.7
G39: 0.344944
G40: 34706801
G41: 11373957
G42: 3927177.5
G43: 0.344944
...

Sheet Headcount & Cost Detail
A1: HEADCOUNT & COST DETAIL — ALL CATEGORIES
A3: Line Item | B3: Y1 2026 | C3: Y2 2027 | D3: Y3 2028 | E3: Y4 2029 | F3: Y5 2030 | G3: 5-Yr Total | H3: Notes
A4: AARON'S COMPENSATION
A5: Base Salary | B5: 0 | C5: 185000 | D5: 185000 | E5: 185000 | F5: 185000 | G5: 740000 | H5: $0 Y1; $185K Y2+
A6: Admin Burden (23%) | B6: 0 | C6: 42550 | D6: 42550 | E6: 42550 | F6: 42550 | G6: 170200
A7: TOTAL OWNER COMP (LOADED) | B7: 0 | C7: 227550 | D7: 227550 | E7: 227550 | F7: 227550 | G7: 910200
A8: COLD CALLERS — DIRECT BOOK (MILESTONE-TRIGGERED)
A9: Heads | B9: 2 | C9: 2 | D9: 2 | E9: 2 | F9: 2 | G9: 10 | H9: 2 callers at $80K cumulative cash; +1 per additional $80K
A10: TOTAL COLD CALLER COST | B10: 80000 | C10: 80000 | D10: 80000 | E10: 80000 | F10: 80000 | G10: 400000 | H10: $40K/head — 1099
A11: RESOURCEPRO (OUTSOURCED)
A12: Heads | B12: 3 | C12: 7 | D12: 14 | E12: 22 | F12: 30 | G12: 76 | H12: 0 until 10 clients
A13: TOTAL RESOURCEPRO COST | B13: 120000 | C13: 280000 | D13: 560000 | E13: 880000 | F13: 1200000 | G13: 3040000
A14: ACCOUNT MANAGERS (W-2, 3% ANNUAL ESCALATION)
A15: Heads | B15: 2 | C15: 5 | D15: 10 | E15: 15 | F15: 21 | G15: 53 | H15: 0 until 20 clients
A16: Salary Rate per AM | B16: 140000 | C16: 144200 | D16: 148526 | E16: 152981.78 | F16: 157571.23 | G16: 743279.01 | H16: $140K Y1; 3% annual increase
A17: AM Base Salary (Total) | B17: 280000 | C17: 721000 | D17: 1485260 | E17: 2294726.7 | F17: 3308995.9 | G17: 8089982.6
A18: Admin Burden (23%) | B18: 64400 | C18: 165830 | D18: 341609.8 | E18: 527787.14 | F18: 761069.06 | G18: 1860696
A19: TOTAL AM LOADED COST | B19: 344400 | C19: 886830 | D19: 1826869.8 | E19: 2822513.8 | F19: 4070065 | G19: 9950678.6
A20: FIXED OPERATING EXPENSES
A21: E&O Insurance | B21: 13000 | C21: 39000 | D21: 78000 | E21: 117000 | F21: 162500 | G21: 247000 | H21: $6,500 per $650K revenue band
A22: Agency Management System | B22: 35000 | C22: 35000 | D22: 35000 | E22: 35000 | F22: 35000 | G22: 175000 | H22: $35K/yr at 10 clients
A23: Marketing | B23: 5000 | C23: 8000 | D23: 12000 | E23: 15000 | F23: 18000 | G23: 58000
A24: Professional Services | B24: 3000 | C24: 4000 | D24: 5000 | E24: 6000 | F24: 6000 | G24: 24000
A25: Misc / Admin | B25: 2400 | C25: 2400 | D25: 3000 | E25: 3600 | F25: 3600 | G25: 15000
A26: TOTAL FIXED OPEX | B26: 58400 | C26: 88400 | D26: 133000 | E26: 176600 | F26: 225100 | G26: 519000
A27: TOTAL ALL-IN COST SUMMARY
A28: Owner Compensation (Loaded) | B28: 0 | C28: 227550 | D28: 227550 | E28: 227550 | F28: 227550 | G28: 910200
A29: Cold Caller Costs | B29: 80000 | C29: 80000 | D29: 80000 | E29: 80000 | F29: 80000 | G29: 400000
A30: ResourcePro Costs | B30: 120000 | C30: 280000 | D30: 560000 | E30: 880000 | F30: 1200000 | G30: 3040000
A31: Account Manager Costs (Loaded) | B31: 344400 | C31: 886830 | D31: 1826869.8 | E31: 2822513.8 | F31: 4070065 | G31: 9950678.6
A32: Fixed OpEx | B32: 58400 | C32: 88400 | D32: 133000 | E32: 176600 | F32: 225100 | G32: 519000
A33: TOTAL ALL-IN COSTS | B33: 776388 | C33: 2148868 | D33: 4129516 | E33: 6321928 | F33: 9018229 | G33: 14819879
A34: Total Costs as % of Revenue | B34: 0.6262 | C34: 0.5866 | D34: 0.5709 | E34: 0.5625 | F34: 0.5609 | G34: 0.655495

Sheet Client Mix Assumptions
A1: CLIENT MIX ASSUMPTIONS
A3: CLIENT TIER MIX
A4: Tier | B4: Mix % | C4: Avg Premium | D4: Commission (12%)
A5: Small Commercial | B5: 0.4 | C5: 100000 | D5: =C5*0.12 -> 12000
A6: Mid-Market | B6: 0.4 | C6: 280000 | D6: =C6*0.12 -> 33600
A7: Large / Complex | B7: 0.2 | C7: 500000 | D7: =C7*0.12 -> 60000
A8: Blended Average | B8: =SUM(B5:B7) -> 1 | C8: =SUMPRODUCT(B5:B7,C5:C7) -> 252000 | D8: =SUMPRODUCT(B5:B7,D5:D7) -> 30240
A10: GRADUATING COMMISSION RATES
B11: Year 1 | C11: Year 2 | D11: Year 3 | E11: Year 4 | F11: Year 5
A12: Commission Rate | B12: 0.12 | C12: 0.1225 | D12: 0.1275 | E12: 0.13 | F12: 0.135
A13: Blended Comm / Client | B13: =C8*B12 -> 30240 | C13: =C8*C12 -> 30870 | D13: =C8*D12 -> 32130 | E13: =C8*E12 -> 32760 | F13: =C8*F12 -> 34020
A14: Scale vs Old ($18K) | B14: =B13/18000 -> 1.68 | C14: =C13/18000 -> 1.715 | D14: =D13/18000 -> 1.785 | E14: =E13/18000 -> 1.82 | F14: =F13/18000 -> 1.89
A16: PREMIUM SERVICE COST
A17: Service Cost % of Revenue | B17: 0.14 | C17: 0.16 | D17: 0.18 | E17: 0.19 | F17: 0.2
A18: Rationale | B18: Onboarding | C18: Growing complexity | D18: Full service | E18: Deepening service | F18: Mature book
A20: Notes:
A21: • Blue values are adjustable inputs
A22: • Commission rate graduates as book matures and service offerings expand
A23: • Service cost covers: stewardship reports, claims advocacy, dedicated AMs for large accounts
A24: • Target EBITDA margin range: 35-45% (industry benchmark for upmarket P&C brokerage)
